Workbook
Name \: #REF!
Name \0: #REF!
Name \A: #REF!
Name \B: #REF!
Name \E: #REF!
Name \G: #REF!
Name \L: #REF!
Name \q: #REF!
Name \S: #REF!
Name \T: #REF!
Name \U: #REF!
Name ________DAT7: #REF!
Name ________DAT8: #REF!
Name ________DAT9: #REF!
Name _______DAT13: #REF!
Name _______DAT2: #REF!
Name _______DAT3: #REF!
Name _______DAT4: #REF!
Name _______DAT5: #REF!
Name _______DAT6: #REF!
Name _______DAT7: #REF!
Name _______DAT8: #REF!
Name _______DAT9: #REF!
Name _______New1: #REF!
Name ______DAT13: #REF!
Name ______DAT2: #REF!
Name ______DAT3: #REF!
Name ______DAT4: #REF!
Name ______DAT5: #REF!
Name ______DAT6: #REF!
Name ______DAT7: #REF!
Name ______DAT8: #REF!
Name ______DAT9: #REF!
Name ______New1: #REF!
Name _____DAT1: #REF!
Name _____DAT13: #REF!
Name _____DAT2: #REF!
Name _____DAT3: #REF!
Name _____DAT4: #REF!
Name _____DAT5: #REF!
Name _____DAT6: #REF!
Name _____DAT7: #REF!
Name _____DAT8: #REF!
Name _____DAT9: #REF!
Name _____New1: #REF!
Name ____DAT1: #REF!
Name ____DAT13: #REF!
Name ____DAT2: #REF!
Name ____DAT3: #REF!
Name ____DAT4: #REF!
Name ____DAT5: #REF!
Name ____DAT6: #REF!
Name ____DAT7: #REF!
Name ____DAT8: #REF!
Name ____DAT9: #REF!
Name ____New1: #REF!
Name ___col1: #REF!
Name ___col10: #REF!
Name ___col11: #REF!
Name ___col12: #REF!

Sheet Sheet1
H2: Total Days | I2: 23 | J2: 21 | K2: 21 | L2: 22 | M2: 23 | N2: 20 | O2: 23 | P2: 22 | Q2: 21 | R2: 23 | S2: 21 | T2: 22
H3: Holidays | I3: 3 | J3: 0 | K3: 0 | L3: 0 | M3: 2 | N3: 1 | O3: 4 | P3: 1 | Q3: 1 | R3: 2 | S3: 2 | T3: 1
H4: Working Days | I4: =I2-I3 -> 20 | J4: =J2-J3 -> 21 | K4: =K2-K3 -> 21 | L4: =L2-L3 -> 22 | M4: =M2-M3 -> 21 | N4: =N2-N3 -> 19 | O4: =O2-O3 -> 19 | P4: =P2-P3 -> 21 | ... T4: =T2-T3 -> 21
A5: Project | B5: Active/Inactive | C5: Scope | D5: EHR system | E5: Norms | F5: Billing Type | G5: Pricing | H5: Daily volume | I5: Jan | J5: Feb | K5: Mar | L5: Apr | M5: May | N5: Jun | O5: Jul | P5: Aug | Q5: Sep | R5: Oct | S5: Nov | T5: Dec
A6: D'Souza | B6: Active | C6: Demographics - Established patient | D6: Intergy | E6: 300 | F6: Transcation | G6: 0.27 | H6: 355 | I6: 7100 | J6: 7455 | K6: 7455 | L6: 7810 | M6: 7455 | N6: 6745 | O6: 6745 | P6: 7455 | Q6: 7100 | R6: 7455 | S6: 6745 | T6: 7455
B7: Active | C7: Demographics - New Patient | D7: Intergy | E7: 300 | F7: Transcation | G7: 0.55 | H7: 55 | I7: 1100 | J7: 1155 | K7: 1155 | L7: 1210 | M7: 1155 | N7: 1045 | O7: 1045 | P7: 1155 | Q7: 1100 | R7: 1155 | S7: 1045 | T7: 1155
B8: Active | C8: Insurance Update - Established Patient | D8: Intergy | E8: 150 | F8: Transcation | G8: 0.54 | H8: =7300/20 -> 365 | I8: =H8*I4 -> 7300 | J8: =H8*J4 -> 7665 | K8: =H8*K4 -> 7665 | L8: =H8*L4 -> 8030 | M8: =H8*M4 -> 7665 | N8: =H8*N4 -> 6935 | O8: =H8*O4 -> 6935 | P8: =H8*P4 -> 7665 | Q8: =H8*Q4 -> 7300 | R8: =H8*R4 -> 7665 | S8: =H8*S4 -> 6935 | T8: =H8*T4 -> 7665
B9: Active | C9: Insurance Update - New Patient | D9: Intergy | E9: 150 | F9: Transcation | G9: 0.25 | H9: =1200/20 -> 60 | I9: =H9*I4 -> 1200 | J9: =H9*J4 -> 1260 | K9: =H9*K4 -> 1260 | L9: =H9*L4 -> 1320 | M9: =H9*M4 -> 1260 | N9: =H9*N4 -> 1140 | O9: =H9*O4 -> 1140 | P9: =H9*P4 -> 1260 | Q9: =H9*Q4 -> 1200 | R9: =H9*R4 -> 1260 | S9: =H9*S4 -> 1140 | T9: =H9*T4 -> 1260
B10: Active | C10: Charge entry | D10: Intergy | E10: 380 | F10: Transcation | G10: 0.14 | H10: =23000/20 -> 1150 | I10: =H10*I4 -> 23000 | J10: =H10*J4 -> 24150 | K10: =H10*K4 -> 24150 | L10: =H10*L4 -> 25300 | M10: =H10*M4 -> 24150 | N10: =H10*N4 -> 21850 | O10: =H10*O4 -> 21850 | P10: =H10*P4 -> 24150 | Q10: =H10*Q4 -> 23000 | R10: =H10*R4 -> 24150 | S10: =H10*S4 -> 21850 | T10: =H10*T4 -> 24150
B11: Active | C11: Payment posting - Manual | D11: Intergy | E11: 450 | F11: Transcation | G11: 0.16 | H11: =11000/20 -> 550 | I11: =H11*I4 -> 11000 | J11: =H11*J4 -> 11550 | K11: =H11*K4 -> 11550 | L11: =H11*L4 -> 12100 | M11: =H11*M4 -> 11550 | N11: =H11*N4 -> 10450 | O11: =H11*O4 -> 10450 | P11: =H11*P4 -> 11550 | Q11: =H11*Q4 -> 11000 | R11: =H11*R4 -> 11550 | S11: =H11*S4 -> 10450 | T11: =H11*T4 -> 11550
B12: Active | C12: Payment posting ERA | D12: Intergy | E12: 2000 | F12: Transcation | G12: 0.026 | H12: =34538/20 -> 1726.9 | I12: =H12*I4 -> 34538 | J12: =H12*J4 -> 36264.9 | K12: =H12*K4 -> 36264.9 | L12: =H12*L4 -> 37991.8 | M12: =H12*M4 -> 36264.9 | N12: =H12*N4 -> 32811.1 | O12: =H12*O4 -> 32811.1 | P12: =H12*P4 -> 36264.9 | Q12: =H12*Q4 -> 34538 | R12: =H12*R4 -> 36264.9 | S12: =H12*S4 -> 32811.1 | T12: =H12*T4 -> 36264.9
B13: Active | C13: Medicare Calling | D13: Intergy | E13: 200 | F13: Transcation | G13: 0.3 | H13: =369/20 -> 18.45 | I13: =H13*I4 -> 369 | J13: =H13*J4 -> 387.45 | K13: =H13*K4 -> 387.45 | L13: =H13*L4 -> 405.9 | M13: =H13*M4 -> 387.45 | N13: =H13*N4 -> 350.55 | O13: =H13*O4 -> 350.55 | P13: =H13*P4 -> 387.45 | Q13: =H13*Q4 -> 369 | R13: =H13*R4 -> 387.45 | S13: =H13*S4 -> 350.55 | T13: =H13*T4 -> 387.45
B14: Active | C14: AR Non - Calling | D14: Intergy | E14: 64 | F14: Transcation | G14: 1.35 | H14: =11500/20 -> 575 | I14: =H14*I4 -> 11500 | J14: =H14*J4 -> 12075 | K14: =H14*K4 -> 12075 | L14: =H14*L4 -> 12650 | M14: =H14*M4 -> 12075 | N14: =H14*N4 -> 10925 | O14: =H14*O4 -> 10925 | P14: =H14*P4 -> 12075 | Q14: =H14*Q4 -> 11500 | R14: =H14*R4 -> 12075 | S14: =H14*S4 -> 10925 | T14: =H14*T4 -> 12075
B15: Active | C15: AR Calling | D15: Intergy | E15: 40 | F15: Transcation | G15: 1.35 | H15: =1500/20 -> 75 | I15: =H15*I4 -> 1500 | J15: =H15*J4 -> 1575 | K15: =H15*K4 -> 1575 | L15: =H15*L4 -> 1650 | M15: =H15*M4 -> 1575 | N15: =H15*N4 -> 1425 | O15: =H15*O4 -> 1425 | P15: =H15*P4 -> 1575 | Q15: =H15*Q4 -> 1500 | R15: =H15*R4 -> 1575 | S15: =H15*S4 -> 1425 | T15: =H15*T4 -> 1575
A16: Biotek | B16: In-Active | C16: AR | D16: CPR + | E16: 20 | F16: Collection | G16: 0.015
A17: Biotek | B17: In-Active | C17: Eligibility Verification | D17: CPR + | F17: FTE | G17: 1400
A18: Biotek | B18: In-Active | C18: Payment Posting | D18: CPR + | F18: FTE | G18: 1300
A19: UGBZ | B19: Active | C19: AR | D19: Next Gen | E19: 40 | F19: Collection | G19: 0.03 | H19: =250000/20 -> 12500 | I19: =H19*I4 -> 250000 | J19: =H19*J4 -> 262500 | K19: =H19*K4 -> 262500 | L19: =H19*L4 -> 275000 | M19: =H19*M4 -> 262500 | N19: =H19*N4 -> 237500 | O19: =H19*O4 -> 237500 | P19: =H19*P4 -> 262500 | Q19: =H19*Q4 -> 250000 | R19: =H19*R4 -> 262500 | S19: =H19*S4 -> 237500 | T19: =H19*T4 -> 262500
B20: In-Active | C20: Auth | D20: Next Gen | E20: 20 | F20: Collection | K20: =H20*K9 -> 0 | L20: =I20*L9 -> 0 | M20: =J20*M9 -> 0 | N20: =K20*N9 -> 0 | O20: =L20*O9 -> 0 | P20: =M20*P9 -> 0 | Q20: =N20*Q9 -> 0 | R20: =O20*R9 -> 0 | ... T20: =Q20*T9 -> 0
B21: Active | C21: Payment posting Manual | D21: Next Gen | E21: 350 | F21: Collection | K21: =H21*K10 -> 0 | L21: =I21*L10 -> 0 | M21: =J21*M10 -> 0 | N21: =K21*N10 -> 0 | O21: =L21*O10 -> 0 | P21: =M21*P10 -> 0 | Q21: =N21*Q10 -> 0 | R21: =O21*R10 -> 0 | ... T21: =Q21*T10 -> 0
B22: Active | C22: Payment posting ERA | D22: Next Gen | E22: 2000 | F22: Collection | K22: =H22*K11 -> 0 | L22: =I22*L11 -> 0 | M22: =J22*M11 -> 0 | N22: =K22*N11 -> 0 | O22: =L22*O11 -> 0 | P22: =M22*P11 -> 0 | Q22: =N22*Q11 -> 0 | R22: =O22*R11 -> 0 | ... T22: =Q22*T11 -> 0
B23: Active | C23: Eligibility Benefits and Auth verification | D23: Next Gen | F23: FTE | G23: 1400
A24: HCA | B24: In-Active | C24: Adjustment | D24: Primesuite | E24: 250 | F24: FTE | G24: 1200
B25: Active | C25: AR Follow up | D25: Primesuite | E25: 40 | F25: FTE | G25: 1300 | H25: 4 | I25: 5200 | J25: 5200 | K25: 5200 | L25: 5200 | M25: 5200 | N25: 5200 | O25: 5200 | P25: 5200 | Q25: 5200 | R25: 5200 | S25: 5200 | T25: 5200
A26: BMMSA | B26: In-Active | C26: AR | D26: Intergy | E26: 20 | F26: FTE | G26: 1200
A27: Nova GI | B27: In-Active | C27: Charge entry | D27: Gastro Med | E27: 150 | F27: Collection | G27: 0.025 | M27: Price change from 3% to 2.5% effective from. July 2023
B28: In-Active | C28: Payment posting - Manual | D28: Gastro Med | E28: 180 | F28: Collection
B29: In-Active | C29: Payment posting ERA | D29: Gastro Med | E29: 300 | F29: Collection
B30: In-Active | C30: AR calling | D30: Gastro Med | E30: 40 | F30: Collection
B31: In-Active | C31: Patient Collection | D31: Gastro Med | E31: 64 | G31: 0.005
A32: CMS | B32: Active | C32: AR | D32: Intergy / Advanced MD / eCw | E32: 40 | F32: Transaction | G32: 2.1 | H32: =1500/20 -> 75 | I32: =H32*I4 -> 1500 | J32: =H32*J4 -> 1575 | K32: =H32*K4 -> 1575 | L32: =H32*L4 -> 1650 | M32: =H32*M4 -> 1575 | N32: =H32*N4 -> 1425 | O32: =H32*O4 -> 1425 | P32: =H32*P4 -> 1575 | Q32: =H32*Q4 -> 1500 | R32: =H32*R4 -> 1575 | S32: =H32*S4 -> 1425 | T32: =H32*T4 -> 1575
B33: Active | C33: Demographics | D33: Intergy / Advanced MD / eCw | E33: 100 | F33: Transaction | G33: 0.55 | H33: =150/20 -> 7.5 | I33: =H33*I4 -> 150 | J33: =H33*J4 -> 157.5 | K33: =H33*K4 -> 157.5 | L33: =H33*L4 -> 165 | M33: =H33*M4 -> 157.5 | N33: =H33*N4 -> 142.5 | O33: =H33*O4 -> 142.5 | P33: =H33*P4 -> 157.5 | Q33: =H33*Q4 -> 150 | R33: =H33*R4 -> 157.5 | S33: =H33*S4 -> 142.5 | T33: =H33*T4 -> 157.5
B34: Active | C34: Charge entry | D34: Intergy / Advanced MD / eCw | E34: 150 | F34: Transaction | G34: 0.3 | H34: =150/20 -> 7.5 | I34: =H34*I4 -> 150 | J34: =H34*J4 -> 157.5 | K34: =H34*K4 -> 157.5 | L34: =H34*L4 -> 165 | M34: =H34*M4 -> 157.5 | N34: =H34*N4 -> 142.5 | O34: =H34*O4 -> 142.5 | P34: =H34*P4 -> 157.5 | Q34: =H34*Q4 -> 150 | R34: =H34*R4 -> 157.5 | S34: =H34*S4 -> 142.5 | T34: =H34*T4 -> 157.5
B35: Active | C35: Payment posting - Manual | D35: Intergy / Advanced MD / eCw | E35: 450 | F35: Transaction | G35: 0.27 | H35: =700/20 -> 35 | I35: =H35*I4 -> 700 | J35: =H35*J4 -> 735 | K35: =H35*K4 -> 735 | L35: =H35*L4 -> 770 | M35: =H35*M4 -> 735 | N35: =H35*N4 -> 665 | O35: =H35*O4 -> 665 | P35: =H35*P4 -> 735 | Q35: =H35*Q4 -> 700 | R35: =H35*R4 -> 735 | S35: =H35*S4 -> 665 | T35: =H35*T4 -> 735
B36: Active | C36: Payment posting ERA | D36: Intergy / Advanced MD / eCw | E36: 450 | F36: Transaction | G36: 0.03 | H36: =4000/20 -> 200 | I36: =H36*I4 -> 4000 | J36: =H36*J4 -> 4200 | K36: =H36*K4 -> 4200 | L36: =H36*L4 -> 4400 | M36: =H36*M4 -> 4200 | N36: =H36*N4 -> 3800 | O36: =H36*O4 -> 3800 | P36: =H36*P4 -> 4200 | Q36: =H36*Q4 -> 4000 | R36: =H36*R4 -> 4200 | S36: =H36*S4 -> 3800 | T36: =H36*T4 -> 4200
A37: Open dental | B37: Active | C37: Payment posting | D37: Open Dental | E37: 80 | F37: FTE | G37: 1280 | I37: =1280+1280 -> 2560 | J37: =1280+1280 -> 2560 | K37: =1280+1280 -> 2560 | L37: =1280+1280 -> 2560 | M37: =1280+1280 -> 2560 | N37: =1280+1280 -> 2560 | O37: =1280+1280 -> 2560 | P37: =1280+1280 -> 2560 | ... T37: =1280+1280 -> 2560
A38: DDR | B38: Active | C38: Payment posting - Manual | D38: Gastro Med | E38: 180 | F38: FTE | G38: 1250 | I38: 5000 | J38: 5000 | K38: 5000 | L38: 5000 | M38: 5000 | N38: 5000 | O38: 5000 | P38: 5000 | Q38: 5000 | R38: 5000 | S38: 5000 | T38: 5000
B39: Active | C39: Payment posting ERA | D39: Gastro Med | E39: 300 | F39: FTE
B40: In-Active | C40: Eligibility Benefits and Auth verification | D40: Gastro Med | E40: 30 | F40: FTE | G40: 1350
A41: Encore | B41: In-Active | C41: Charge entry | D41: Raintree | E41: 800 | F41: Collection | G41: 0.065 | U41: Price change from 4% to 6.5% effective from. October 2023
...

Sheet Sheet 3
D1: AR | H1: 2024 Expected Volume | AX1: Base | AY1: =SUM(AJ6:AJ15) -> 20.263613 | BA1: Deployment
D2: Date Entry | I2: Total Days | J2: 23 | K2: 21 | L2: 21 | M2: 22 | N2: 23 | O2: 20 | P2: 23 | Q2: 22 | R2: 21 | S2: 23 | T2: 21 | U2: 22 | AX2: Absenteeism | AY2: 0.1 | AZ2: =100%-AY2-AY3 -> 0.85 | BA2: =AY1/AZ2 -> 23.839545 | BB2: =BA2*AZ2 -> 20.263613
D3: Coding | I3: Holidays | J3: 3 | K3: 0 | L3: 0 | M3: 0 | N3: 2 | O3: 1 | P3: 4 | Q3: 1 | R3: 1 | S3: 2 | T3: 2 | U3: 1 | AJ3: Base FTEs | AX3: Attrition | AY3: 0.05
I4: Working Days | J4: =J2-J3 -> 20 | K4: =K2-K3 -> 21 | L4: =L2-L3 -> 21 | M4: =M2-M3 -> 22 | N4: =N2-N3 -> 21 | O4: =O2-O3 -> 19 | P4: =P2-P3 -> 19 | Q4: =Q2-Q3 -> 21 | ... U4: =U2-U3 -> 21 | W4: Revenue in $
A5: Project | B5: Active/Inactive | C5: Scope | D5: Manpower Type | E5: EHR system | F5: Norms | G5: Billing Type | H5: Pricing | I5: Daily volume | J5: Jan | K5: Feb | L5: Mar | M5: Apr | N5: May | O5: Jun | P5: Jul | Q5: Aug | R5: Sep | S5: Oct | T5: Nov | U5: Dec | W5: Jan | X5: Feb | Y5: Mar | Z5: Apr | AA5: May | AB5: Jun | AC5: Jul | AD5: Aug | AE5: Sep | AF5: Oct | AG5: Nov | AH5: Dec | AJ5: Jan | AK5: Feb | AL5: Mar | AM5: Apr | AN5: May | AO5: Jun | AP5: Jul | AQ5: Aug | AR5: Sep | AS5: Oct | AT5: Nov | AU5: Dec
A6: D'Souza | B6: Active | C6: Demographics - Established patient | D6: Date Entry | E6: Intergy | F6: 300 | G6: Transcation | H6: 0.27 | I6: 355 | J6: 7100 | K6: 7455 | L6: 7455 | M6: 7810 | N6: 7455 | O6: 6745 | P6: 6745 | Q6: 7455 | R6: 7100 | S6: 7455 | T6: 6745 | U6: 7455 | W6: =$H6*J6 -> 1917 | X6: =$H6*K6 -> 2012.85 | Y6: =$H6*L6 -> 2012.85 | Z6: =$H6*M6 -> 2108.7 | AA6: =$H6*N6 -> 2012.85 | AB6: =$H6*O6 -> 1821.15 | AC6: =$H6*P6 -> 1821.15 | AD6: =$H6*Q6 -> 2012.85 | ... AH6: =$H6*U6 -> 2012.85 | AJ6: =(J6/J$4)/$F6 -> 1.1833333 | AK6: =(K6/K$4)/$F6 -> 1.1833333 | AL6: =(L6/L$4)/$F6 -> 1.1833333 | AM6: =(M6/M$4)/$F6 -> 1.1833333 | AN6: =(N6/N$4)/$F6 -> 1.1833333 | AO6: =(O6/O$4)/$F6 -> 1.1833333 | AP6: =(P6/P$4)/$F6 -> 1.1833333 | AQ6: =(Q6/Q$4)/$F6 -> 1.1833333 | ... AU6: =(U6/U$4)/$F6 -> 1.1833333 | AY6: Client Name
A7: =A6 -> D'Souza | B7: Active | C7: Demographics - New Patient | D7: Date Entry | E7: Intergy | F7: 300 | G7: Transcation | H7: 0.55 | I7: 55 | J7: 1100 | K7: 1155 | L7: 1155 | M7: 1210 | N7: 1155 | O7: 1045 | P7: 1045 | Q7: 1155 | R7: 1100 | S7: 1155 | T7: 1045 | U7: 1155 | W7: =$H7*J7 -> 605 | X7: =$H7*K7 -> 635.25 | Y7: =$H7*L7 -> 635.25 | Z7: =$H7*M7 -> 665.5 | AA7: =$H7*N7 -> 635.25 | AB7: =$H7*O7 -> 574.75 | AC7: =$H7*P7 -> 574.75 | AD7: =$H7*Q7 -> 635.25 | ... AH7: =$H7*U7 -> 635.25 | AJ7: =(J7/J$4)/$F7 -> 0.18333333 | AK7: =(K7/K$4)/$F7 -> 0.18333333 | AL7: =(L7/L$4)/$F7 -> 0.18333333 | AM7: =(M7/M$4)/$F7 -> 0.18333333 | AN7: =(N7/N$4)/$F7 -> 0.18333333 | AO7: =(O7/O$4)/$F7 -> 0.18333333 | AP7: =(P7/P$4)/$F7 -> 0.18333333 | AQ7: =(Q7/Q$4)/$F7 -> 0.18333333 | ... AU7: =(U7/U$4)/$F7 -> 0.18333333 | AY7: Type of Manpower
A8: =A7 -> D'Souza | B8: Active | C8: Insurance Update - Established Patient | D8: Date Entry | E8: Intergy | F8: 150 | G8: Transcation | H8: 0.54 | I8: =7300/20 -> 365 | J8: =I8*J4 -> 7300 | K8: =I8*K4 -> 7665 | L8: =I8*L4 -> 7665 | M8: =I8*M4 -> 8030 | N8: =I8*N4 -> 7665 | O8: =I8*O4 -> 6935 | P8: =I8*P4 -> 6935 | Q8: =I8*Q4 -> 7665 | R8: =I8*R4 -> 7300 | S8: =I8*S4 -> 7665 | T8: =I8*T4 -> 6935 | U8: =I8*U4 -> 7665 | W8: =$H8*J8 -> 3942 | X8: =$H8*K8 -> 4139.1 | Y8: =$H8*L8 -> 4139.1 | Z8: =$H8*M8 -> 4336.2 | AA8: =$H8*N8 -> 4139.1 | AB8: =$H8*O8 -> 3744.9 | AC8: =$H8*P8 -> 3744.9 | AD8: =$H8*Q8 -> 4139.1 | ... AH8: =$H8*U8 -> 4139.1 | AJ8: =(J8/J$4)/$F8 -> 2.4333333 | AK8: =(K8/K$4)/$F8 -> 2.4333333 | AL8: =(L8/L$4)/$F8 -> 2.4333333 | AM8: =(M8/M$4)/$F8 -> 2.4333333 | AN8: =(N8/N$4)/$F8 -> 2.4333333 | AO8: =(O8/O$4)/$F8 -> 2.4333333 | AP8: =(P8/P$4)/$F8 -> 2.4333333 | AQ8: =(Q8/Q$4)/$F8 -> 2.4333333 | ... AU8: =(U8/U$4)/$F8 -> 2.4333333 | AY8: Required Headcount
A9: =A8 -> D'Souza | B9: Active | C9: Insurance Update - New Patient | D9: Date Entry | E9: Intergy | F9: 150 | G9: Transcation | H9: 0.25 | I9: =1200/20 -> 60 | J9: =I9*J4 -> 1200 | K9: =I9*K4 -> 1260 | L9: =I9*L4 -> 1260 | M9: =I9*M4 -> 1320 | N9: =I9*N4 -> 1260 | O9: =I9*O4 -> 1140 | P9: =I9*P4 -> 1140 | Q9: =I9*Q4 -> 1260 | R9: =I9*R4 -> 1200 | S9: =I9*S4 -> 1260 | T9: =I9*T4 -> 1140 | U9: =I9*U4 -> 1260 | W9: =$H9*J9 -> 300 | X9: =$H9*K9 -> 315 | Y9: =$H9*L9 -> 315 | Z9: =$H9*M9 -> 330 | AA9: =$H9*N9 -> 315 | AB9: =$H9*O9 -> 285 | AC9: =$H9*P9 -> 285 | AD9: =$H9*Q9 -> 315 | ... AH9: =$H9*U9 -> 315 | AJ9: =(J9/J$4)/$F9 -> 0.4 | AK9: =(K9/K$4)/$F9 -> 0.4 | AL9: =(L9/L$4)/$F9 -> 0.4 | AM9: =(M9/M$4)/$F9 -> 0.4 | AN9: =(N9/N$4)/$F9 -> 0.4 | AO9: =(O9/O$4)/$F9 -> 0.4 | AP9: =(P9/P$4)/$F9 -> 0.4 | AQ9: =(Q9/Q$4)/$F9 -> 0.4 | ... AU9: =(U9/U$4)/$F9 -> 0.4
A10: =A9 -> D'Souza | B10: Active | C10: Charge entry | D10: Date Entry | E10: Intergy | F10: 380 | G10: Transcation | H10: 0.14 | I10: =23000/20 -> 1150 | J10: =I10*J4 -> 23000 | K10: =I10*K4 -> 24150 | L10: =I10*L4 -> 24150 | M10: =I10*M4 -> 25300 | N10: =I10*N4 -> 24150 | O10: =I10*O4 -> 21850 | P10: =I10*P4 -> 21850 | Q10: =I10*Q4 -> 24150 | R10: =I10*R4 -> 23000 | S10: =I10*S4 -> 24150 | T10: =I10*T4 -> 21850 | U10: =I10*U4 -> 24150 | W10: =$H10*J10 -> 3220 | X10: =$H10*K10 -> 3381 | Y10: =$H10*L10 -> 3381 | Z10: =$H10*M10 -> 3542 | AA10: =$H10*N10 -> 3381 | AB10: =$H10*O10 -> 3059 | AC10: =$H10*P10 -> 3059 | AD10: =$H10*Q10 -> 3381 | ... AH10: =$H10*U10 -> 3381 | AJ10: =(J10/J$4)/$F10 -> 3.0263158 | AK10: =(K10/K$4)/$F10 -> 3.0263158 | AL10: =(L10/L$4)/$F10 -> 3.0263158 | AM10: =(M10/M$4)/$F10 -> 3.0263158 | AN10: =(N10/N$4)/$F10 -> 3.0263158 | AO10: =(O10/O$4)/$F10 -> 3.0263158 | AP10: =(P10/P$4)/$F10 -> 3.0263158 | AQ10: =(Q10/Q$4)/$F10 -> 3.0263158 | ... AU10: =(U10/U$4)/$F10 -> 3.0263158
A11: =A10 -> D'Souza | B11: Active | C11: Payment posting - Manual | D11: Date Entry | E11: Intergy | F11: 450 | G11: Transcation | H11: 0.16 | I11: =11000/20 -> 550 | J11: =I11*J4 -> 11000 | K11: =I11*K4 -> 11550 | L11: =I11*L4 -> 11550 | M11: =I11*M4 -> 12100 | N11: =I11*N4 -> 11550 | O11: =I11*O4 -> 10450 | P11: =I11*P4 -> 10450 | Q11: =I11*Q4 -> 11550 | R11: =I11*R4 -> 11000 | S11: =I11*S4 -> 11550 | T11: =I11*T4 -> 10450 | U11: =I11*U4 -> 11550 | W11: =$H11*J11 -> 1760 | X11: =$H11*K11 -> 1848 | Y11: =$H11*L11 -> 1848 | Z11: =$H11*M11 -> 1936 | AA11: =$H11*N11 -> 1848 | AB11: =$H11*O11 -> 1672 | AC11: =$H11*P11 -> 1672 | AD11: =$H11*Q11 -> 1848 | ... AH11: =$H11*U11 -> 1848 | AJ11: =(J11/J$4)/$F11 -> 1.2222222 | AK11: =(K11/K$4)/$F11 -> 1.2222222 | AL11: =(L11/L$4)/$F11 -> 1.2222222 | AM11: =(M11/M$4)/$F11 -> 1.2222222 | AN11: =(N11/N$4)/$F11 -> 1.2222222 | AO11: =(O11/O$4)/$F11 -> 1.2222222 | AP11: =(P11/P$4)/$F11 -> 1.2222222 | AQ11: =(Q11/Q$4)/$F11 -> 1.2222222 | ... AU11: =(U11/U$4)/$F11 -> 1.2222222
A12: =A11 -> D'Souza | B12: Active | C12: Payment posting ERA | D12: Date Entry | E12: Intergy | F12: 2000 | G12: Transcation | H12: 0.026 | I12: =34538/20 -> 1726.9 | J12: =I12*J4 -> 34538 | K12: =I12*K4 -> 36264.9 | L12: =I12*L4 -> 36264.9 | M12: =I12*M4 -> 37991.8 | N12: =I12*N4 -> 36264.9 | O12: =I12*O4 -> 32811.1 | P12: =I12*P4 -> 32811.1 | Q12: =I12*Q4 -> 36264.9 | R12: =I12*R4 -> 34538 | S12: =I12*S4 -> 36264.9 | T12: =I12*T4 -> 32811.1 | U12: =I12*U4 -> 36264.9 | W12: =$H12*J12 -> 897.988 | X12: =$H12*K12 -> 942.8874 | Y12: =$H12*L12 -> 942.8874 | Z12: =$H12*M12 -> 987.7868 | AA12: =$H12*N12 -> 942.8874 | AB12: =$H12*O12 -> 853.0886 | AC12: =$H12*P12 -> 853.0886 | AD12: =$H12*Q12 -> 942.8874 | ... AH12: =$H12*U12 -> 942.8874 | AJ12: =(J12/J$4)/$F12 -> 0.86345 | AK12: =(K12/K$4)/$F12 -> 0.86345 | AL12: =(L12/L$4)/$F12 -> 0.86345 | AM12: =(M12/M$4)/$F12 -> 0.86345 | AN12: =(N12/N$4)/$F12 -> 0.86345 | AO12: =(O12/O$4)/$F12 -> 0.86345 | AP12: =(P12/P$4)/$F12 -> 0.86345 | AQ12: =(Q12/Q$4)/$F12 -> 0.86345 | ... AU12: =(U12/U$4)/$F12 -> 0.86345
A13: =A12 -> D'Souza | B13: Active | C13: Medicare Calling | D13: AR | E13: Intergy | F13: 200 | G13: Transcation | H13: 0.3 | I13: =369/20 -> 18.45 | J13: =I13*J4 -> 369 | K13: =I13*K4 -> 387.45 | L13: =I13*L4 -> 387.45 | M13: =I13*M4 -> 405.9 | N13: =I13*N4 -> 387.45 | O13: =I13*O4 -> 350.55 | P13: =I13*P4 -> 350.55 | Q13: =I13*Q4 -> 387.45 | R13: =I13*R4 -> 369 | S13: =I13*S4 -> 387.45 | T13: =I13*T4 -> 350.55 | U13: =I13*U4 -> 387.45 | W13: =$H13*J13 -> 110.7 | X13: =$H13*K13 -> 116.235 | Y13: =$H13*L13 -> 116.235 | Z13: =$H13*M13 -> 121.77 | AA13: =$H13*N13 -> 116.235 | AB13: =$H13*O13 -> 105.165 | AC13: =$H13*P13 -> 105.165 | AD13: =$H13*Q13 -> 116.235 | ... AH13: =$H13*U13 -> 116.235 | AJ13: =(J13/J$4)/$F13 -> 0.09225 | AK13: =(K13/K$4)/$F13 -> 0.09225 | AL13: =(L13/L$4)/$F13 -> 0.09225 | AM13: =(M13/M$4)/$F13 -> 0.09225 | AN13: =(N13/N$4)/$F13 -> 0.09225 | AO13: =(O13/O$4)/$F13 -> 0.09225 | AP13: =(P13/P$4)/$F13 -> 0.09225 | AQ13: =(Q13/Q$4)/$F13 -> 0.09225 | ... AU13: =(U13/U$4)/$F13 -> 0.09225
A14: =A13 -> D'Souza | B14: Active | C14: AR Non - Calling | D14: AR | E14: Intergy | F14: 64 | G14: Transcation | H14: 1.35 | I14: =11500/20 -> 575 | J14: =I14*J4 -> 11500 | K14: =I14*K4 -> 12075 | L14: =I14*L4 -> 12075 | M14: =I14*M4 -> 12650 | N14: =I14*N4 -> 12075 | O14: =I14*O4 -> 10925 | P14: =I14*P4 -> 10925 | Q14: =I14*Q4 -> 12075 | R14: =I14*R4 -> 11500 | S14: =I14*S4 -> 12075 | T14: =I14*T4 -> 10925 | U14: =I14*U4 -> 12075 | W14: =$H14*J14 -> 15525 | X14: =$H14*K14 -> 16301.25 | Y14: =$H14*L14 -> 16301.25 | Z14: =$H14*M14 -> 17077.5 | AA14: =$H14*N14 -> 16301.25 | AB14: =$H14*O14 -> 14748.75 | AC14: =$H14*P14 -> 14748.75 | AD14: =$H14*Q14 -> 16301.25 | ... AH14: =$H14*U14 -> 16301.25 | AJ14: =(J14/J$4)/$F14 -> 8.984375 | AK14: =(K14/K$4)/$F14 -> 8.984375 | AL14: =(L14/L$4)/$F14 -> 8.984375 | AM14: =(M14/M$4)/$F14 -> 8.984375 | AN14: =(N14/N$4)/$F14 -> 8.984375 | AO14: =(O14/O$4)/$F14 -> 8.984375 | AP14: =(P14/P$4)/$F14 -> 8.984375 | AQ14: =(Q14/Q$4)/$F14 -> 8.984375 | ... AU14: =(U14/U$4)/$F14 -> 8.984375
A15: =A14 -> D'Souza | B15: Active | C15: AR Calling | D15: AR | E15: Intergy | F15: 40 | G15: Transcation | H15: 1.35 | I15: =1500/20 -> 75 | J15: =I15*J4 -> 1500 | K15: =I15*K4 -> 1575 | L15: =I15*L4 -> 1575 | M15: =I15*M4 -> 1650 | N15: =I15*N4 -> 1575 | O15: =I15*O4 -> 1425 | P15: =I15*P4 -> 1425 | Q15: =I15*Q4 -> 1575 | R15: =I15*R4 -> 1500 | S15: =I15*S4 -> 1575 | T15: =I15*T4 -> 1425 | U15: =I15*U4 -> 1575 | W15: =$H15*J15 -> 2025 | X15: =$H15*K15 -> 2126.25 | Y15: =$H15*L15 -> 2126.25 | Z15: =$H15*M15 -> 2227.5 | AA15: =$H15*N15 -> 2126.25 | AB15: =$H15*O15 -> 1923.75 | AC15: =$H15*P15 -> 1923.75 | AD15: =$H15*Q15 -> 2126.25 | ... AH15: =$H15*U15 -> 2126.25 | AJ15: =(J15/J$4)/$F15 -> 1.875 | AK15: =(K15/K$4)/$F15 -> 1.875 | AL15: =(L15/L$4)/$F15 -> 1.875 | AM15: =(M15/M$4)/$F15 -> 1.875 | AN15: =(N15/N$4)/$F15 -> 1.875 | AO15: =(O15/O$4)/$F15 -> 1.875 | AP15: =(P15/P$4)/$F15 -> 1.875 | AQ15: =(Q15/Q$4)/$F15 -> 1.875 | ... AU15: =(U15/U$4)/$F15 -> 1.875
A16: UGBZ | B16: Active | C16: AR | D16: AR | E16: Next Gen | F16: 40 | G16: Collection | H16: 0.03 | I16: =250000/20 -> 12500 | J16: =I16*J4 -> 250000 | K16: =I16*K4 -> 262500 | L16: =I16*L4 -> 262500 | M16: =I16*M4 -> 275000 | N16: =I16*N4 -> 262500 | O16: =I16*O4 -> 237500 | P16: =I16*P4 -> 237500 | Q16: =I16*Q4 -> 262500 | R16: =I16*R4 -> 250000 | S16: =I16*S4 -> 262500 | T16: =I16*T4 -> 237500 | U16: =I16*U4 -> 262500 | W16: =$H16*J16 -> 7500 | X16: =$H16*K16 -> 7875 | Y16: =$H16*L16 -> 7875 | Z16: =$H16*M16 -> 8250 | AA16: =$H16*N16 -> 7875 | AB16: =$H16*O16 -> 7125 | AC16: =$H16*P16 -> 7125 | AD16: =$H16*Q16 -> 7875 | ... AH16: =$H16*U16 -> 7875 | AJ16: =AI16*AY1 -> 0
A17: =A16 -> UGBZ | B17: In-Active | C17: Auth | D17: Date Entry | E17: Next Gen | F17: 20 | G17: Collection | L17: =I17*L9 -> 0 | M17: =J17*M9 -> 0 | N17: =K17*N9 -> 0 | O17: =L17*O9 -> 0 | P17: =M17*P9 -> 0 | Q17: =N17*Q9 -> 0 | R17: =O17*R9 -> 0 | S17: =P17*S9 -> 0 | ... U17: =R17*U9 -> 0 | W17: =$H17*J17 -> 0 | X17: =$H17*K17 -> 0 | Y17: =$H17*L17 -> 0 | Z17: =$H17*M17 -> 0 | AA17: =$H17*N17 -> 0 | AB17: =$H17*O17 -> 0 | AC17: =$H17*P17 -> 0 | AD17: =$H17*Q17 -> 0 | ... AH17: =$H17*U17 -> 0
A18: =A17 -> UGBZ | B18: Active | C18: Payment posting Manual | D18: Date Entry | E18: Next Gen | F18: 350 | G18: Collection | L18: =I18*L10 -> 0 | M18: =J18*M10 -> 0 | N18: =K18*N10 -> 0 | O18: =L18*O10 -> 0 | P18: =M18*P10 -> 0 | Q18: =N18*Q10 -> 0 | R18: =O18*R10 -> 0 | S18: =P18*S10 -> 0 | ... U18: =R18*U10 -> 0 | W18: =$H18*J18 -> 0 | X18: =$H18*K18 -> 0 | Y18: =$H18*L18 -> 0 | Z18: =$H18*M18 -> 0 | AA18: =$H18*N18 -> 0 | AB18: =$H18*O18 -> 0 | AC18: =$H18*P18 -> 0 | AD18: =$H18*Q18 -> 0 | ... AH18: =$H18*U18 -> 0
A19: =A18 -> UGBZ | B19: Active | C19: Payment posting ERA | D19: Date Entry | E19: Next Gen | F19: 2000 | G19: Collection | L19: =I19*L11 -> 0 | M19: =J19*M11 -> 0 | N19: =K19*N11 -> 0 | O19: =L19*O11 -> 0 | P19: =M19*P11 -> 0 | Q19: =N19*Q11 -> 0 | R19: =O19*R11 -> 0 | S19: =P19*S11 -> 0 | ... U19: =R19*U11 -> 0 | W19: =$H19*J19 -> 0 | X19: =$H19*K19 -> 0 | Y19: =$H19*L19 -> 0 | Z19: =$H19*M19 -> 0 | AA19: =$H19*N19 -> 0 | AB19: =$H19*O19 -> 0 | AC19: =$H19*P19 -> 0 | AD19: =$H19*Q19 -> 0 | ... AH19: =$H19*U19 -> 0
A20: =A19 -> UGBZ | B20: Active | C20: Eligibility Benefits and Auth verification | D20: Date Entry | E20: Next Gen | G20: FTE | H20: 1400
A21: HCA | B21: In-Active | C21: Adjustment | D21: Date Entry | E21: Primesuite | F21: 250 | G21: FTE | H21: 1200
A22: =A21 -> HCA | B22: Active | C22: AR Follow up | D22: AR | E22: Primesuite | F22: 40 | G22: FTE | H22: 1300 | I22: 4 | J22: 4 | K22: 4 | L22: 4 | M22: 4 | N22: 4 | O22: 4 | P22: 4 | Q22: 4 | R22: 4 | S22: 4 | T22: 4 | U22: 4 | W22: =$H22*J22 -> 5200 | X22: =$H22*K22 -> 5200 | Y22: =$H22*L22 -> 5200 | Z22: =$H22*M22 -> 5200 | AA22: =$H22*N22 -> 5200 | AB22: =$H22*O22 -> 5200 | AC22: =$H22*P22 -> 5200 | AD22: =$H22*Q22 -> 5200 | ... AH22: =$H22*U22 -> 5200 | AJ22: =J22 -> 4 | AK22: =K22 -> 4 | AL22: =L22 -> 4 | AM22: =M22 -> 4 | AN22: =N22 -> 4 | AO22: =O22 -> 4 | AP22: =P22 -> 4 | AQ22: =Q22 -> 4 | ... AU22: =U22 -> 4
A23: BMMSA | B23: In-Active | C23: AR | D23: AR | E23: Intergy | F23: 20 | G23: FTE | H23: 1200
A24: CMS | B24: Active | C24: AR | D24: AR | E24: Intergy / Advanced MD / eCw | F24: 40 | G24: Transaction | H24: 2.1 | I24: =1500/20 -> 75 | J24: =I24*J4 -> 1500 | K24: =I24*K4 -> 1575 | L24: =I24*L4 -> 1575 | M24: =I24*M4 -> 1650 | N24: =I24*N4 -> 1575 | O24: =I24*O4 -> 1425 | P24: =I24*P4 -> 1425 | Q24: =I24*Q4 -> 1575 | R24: =I24*R4 -> 1500 | S24: =I24*S4 -> 1575 | T24: =I24*T4 -> 1425 | U24: =I24*U4 -> 1575 | W24: =$H24*J24 -> 3150 | X24: =$H24*K24 -> 3307.5 | Y24: =$H24*L24 -> 3307.5 | Z24: =$H24*M24 -> 3465 | AA24: =$H24*N24 -> 3307.5 | AB24: =$H24*O24 -> 2992.5 | AC24: =$H24*P24 -> 2992.5 | AD24: =$H24*Q24 -> 3307.5 | ... AH24: =$H24*U24 -> 3307.5 | AJ24: =(J24/J$4)/$F24 -> 1.875 | AK24: =(K24/K$4)/$F24 -> 1.875 | AL24: =(L24/L$4)/$F24 -> 1.875 | AM24: =(M24/M$4)/$F24 -> 1.875 | AN24: =(N24/N$4)/$F24 -> 1.875 | AO24: =(O24/O$4)/$F24 -> 1.875 | AP24: =(P24/P$4)/$F24 -> 1.875 | AQ24: =(Q24/Q$4)/$F24 -> 1.875 | ... AU24: =(U24/U$4)/$F24 -> 1.875
A25: =A24 -> CMS | B25: Active | C25: Demographics | D25: Date Entry | E25: Intergy / Advanced MD / eCw | F25: 100 | G25: Transaction | H25: 0.55 | I25: =150/20 -> 7.5 | J25: =I25*J4 -> 150 | K25: =I25*K4 -> 157.5 | L25: =I25*L4 -> 157.5 | M25: =I25*M4 -> 165 | N25: =I25*N4 -> 157.5 | O25: =I25*O4 -> 142.5 | P25: =I25*P4 -> 142.5 | Q25: =I25*Q4 -> 157.5 | R25: =I25*R4 -> 150 | S25: =I25*S4 -> 157.5 | T25: =I25*T4 -> 142.5 | U25: =I25*U4 -> 157.5 | W25: =$H25*J25 -> 82.5 | X25: =$H25*K25 -> 86.625 | Y25: =$H25*L25 -> 86.625 | Z25: =$H25*M25 -> 90.75 | AA25: =$H25*N25 -> 86.625 | AB25: =$H25*O25 -> 78.375 | AC25: =$H25*P25 -> 78.375 | AD25: =$H25*Q25 -> 86.625 | ... AH25: =$H25*U25 -> 86.625 | AJ25: =(J25/J$4)/$F25 -> 0.075 | AK25: =(K25/K$4)/$F25 -> 0.075 | AL25: =(L25/L$4)/$F25 -> 0.075 | AM25: =(M25/M$4)/$F25 -> 0.075 | AN25: =(N25/N$4)/$F25 -> 0.075 | AO25: =(O25/O$4)/$F25 -> 0.075 | AP25: =(P25/P$4)/$F25 -> 0.075 | AQ25: =(Q25/Q$4)/$F25 -> 0.075 | ... AU25: =(U25/U$4)/$F25 -> 0.075
A26: =A25 -> CMS | B26: Active | C26: Charge entry | D26: Date Entry | E26: Intergy / Advanced MD / eCw | F26: 150 | G26: Transaction | H26: 0.3 | I26: =150/20 -> 7.5 | J26: =I26*J4 -> 150 | K26: =I26*K4 -> 157.5 | L26: =I26*L4 -> 157.5 | M26: =I26*M4 -> 165 | N26: =I26*N4 -> 157.5 | O26: =I26*O4 -> 142.5 | P26: =I26*P4 -> 142.5 | Q26: =I26*Q4 -> 157.5 | R26: =I26*R4 -> 150 | S26: =I26*S4 -> 157.5 | T26: =I26*T4 -> 142.5 | U26: =I26*U4 -> 157.5 | W26: =$H26*J26 -> 45 | X26: =$H26*K26 -> 47.25 | Y26: =$H26*L26 -> 47.25 | Z26: =$H26*M26 -> 49.5 | AA26: =$H26*N26 -> 47.25 | AB26: =$H26*O26 -> 42.75 | AC26: =$H26*P26 -> 42.75 | AD26: =$H26*Q26 -> 47.25 | ... AH26: =$H26*U26 -> 47.25 | AJ26: =(J26/J$4)/$F26 -> 0.05 | AK26: =(K26/K$4)/$F26 -> 0.05 | AL26: =(L26/L$4)/$F26 -> 0.05 | AM26: =(M26/M$4)/$F26 -> 0.05 | AN26: =(N26/N$4)/$F26 -> 0.05 | AO26: =(O26/O$4)/$F26 -> 0.05 | AP26: =(P26/P$4)/$F26 -> 0.05 | AQ26: =(Q26/Q$4)/$F26 -> 0.05 | ... AU26: =(U26/U$4)/$F26 -> 0.05
A27: =A26 -> CMS | B27: Active | C27: Payment posting - Manual | D27: Date Entry | E27: Intergy / Advanced MD / eCw | F27: 450 | G27: Transaction | H27: 0.27 | I27: =700/20 -> 35 | J27: =I27*J4 -> 700 | K27: =I27*K4 -> 735 | L27: =I27*L4 -> 735 | M27: =I27*M4 -> 770 | N27: =I27*N4 -> 735 | O27: =I27*O4 -> 665 | P27: =I27*P4 -> 665 | Q27: =I27*Q4 -> 735 | R27: =I27*R4 -> 700 | S27: =I27*S4 -> 735 | T27: =I27*T4 -> 665 | U27: =I27*U4 -> 735 | W27: =$H27*J27 -> 189 | X27: =$H27*K27 -> 198.45 | Y27: =$H27*L27 -> 198.45 | Z27: =$H27*M27 -> 207.9 | AA27: =$H27*N27 -> 198.45 | AB27: =$H27*O27 -> 179.55 | AC27: =$H27*P27 -> 179.55 | AD27: =$H27*Q27 -> 198.45 | ... AH27: =$H27*U27 -> 198.45 | AJ27: =(J27/J$4)/$F27 -> 0.077777778 | AK27: =(K27/K$4)/$F27 -> 0.077777778 | AL27: =(L27/L$4)/$F27 -> 0.077777778 | AM27: =(M27/M$4)/$F27 -> 0.077777778 | AN27: =(N27/N$4)/$F27 -> 0.077777778 | AO27: =(O27/O$4)/$F27 -> 0.077777778 | AP27: =(P27/P$4)/$F27 -> 0.077777778 | AQ27: =(Q27/Q$4)/$F27 -> 0.077777778 | ... AU27: =(U27/U$4)/$F27 -> 0.077777778
A28: =A27 -> CMS | B28: Active | C28: Payment posting ERA | D28: Date Entry | E28: Intergy / Advanced MD / eCw | F28: 450 | G28: Transaction | H28: 0.03 | I28: =4000/20 -> 200 | J28: =I28*J4 -> 4000 | K28: =I28*K4 -> 4200 | L28: =I28*L4 -> 4200 | M28: =I28*M4 -> 4400 | N28: =I28*N4 -> 4200 | O28: =I28*O4 -> 3800 | P28: =I28*P4 -> 3800 | Q28: =I28*Q4 -> 4200 | R28: =I28*R4 -> 4000 | S28: =I28*S4 -> 4200 | T28: =I28*T4 -> 3800 | U28: =I28*U4 -> 4200 | W28: =$H28*J28 -> 120 | X28: =$H28*K28 -> 126 | Y28: =$H28*L28 -> 126 | Z28: =$H28*M28 -> 132 | AA28: =$H28*N28 -> 126 | AB28: =$H28*O28 -> 114 | AC28: =$H28*P28 -> 114 | AD28: =$H28*Q28 -> 126 | ... AH28: =$H28*U28 -> 126 | AJ28: =(J28/J$4)/$F28 -> 0.44444444 | AK28: =(K28/K$4)/$F28 -> 0.44444444 | AL28: =(L28/L$4)/$F28 -> 0.44444444 | AM28: =(M28/M$4)/$F28 -> 0.44444444 | AN28: =(N28/N$4)/$F28 -> 0.44444444 | AO28: =(O28/O$4)/$F28 -> 0.44444444 | AP28: =(P28/P$4)/$F28 -> 0.44444444 | AQ28: =(Q28/Q$4)/$F28 -> 0.44444444 | ... AU28: =(U28/U$4)/$F28 -> 0.44444444
A29: Open dental | B29: Active | C29: Payment posting | D29: Date Entry | E29: Open Dental | F29: 80 | G29: FTE | H29: 1280 | J29: 2 | K29: 2 | L29: 2 | M29: 2 | N29: 2 | O29: 2 | P29: 2 | Q29: 2 | R29: 2 | S29: 2 | T29: 2 | U29: 2 | W29: =$H29*J29 -> 2560 | X29: =$H29*K29 -> 2560 | Y29: =$H29*L29 -> 2560 | Z29: =$H29*M29 -> 2560 | AA29: =$H29*N29 -> 2560 | AB29: =$H29*O29 -> 2560 | AC29: =$H29*P29 -> 2560 | AD29: =$H29*Q29 -> 2560 | ... AH29: =$H29*U29 -> 2560 | AJ29: =J29 -> 2 | AK29: =K29 -> 2 | AL29: =L29 -> 2 | AM29: =M29 -> 2 | AN29: =N29 -> 2 | AO29: =O29 -> 2 | AP29: =P29 -> 2 | AQ29: =Q29 -> 2 | ... AU29: =U29 -> 2
A30: DDR | B30: Active | C30: Payment posting - Manual | D30: Date Entry | E30: Gastro Med | F30: 180 | G30: FTE | H30: 1250 | J30: 4 | K30: 4 | L30: 4 | M30: 4 | N30: 4 | O30: 4 | P30: 4 | Q30: 4 | R30: 4 | S30: 4 | T30: 4 | U30: 4 | W30: =$H30*J30 -> 5000 | X30: =$H30*K30 -> 5000 | Y30: =$H30*L30 -> 5000 | Z30: =$H30*M30 -> 5000 | AA30: =$H30*N30 -> 5000 | AB30: =$H30*O30 -> 5000 | AC30: =$H30*P30 -> 5000 | AD30: =$H30*Q30 -> 5000 | ... AH30: =$H30*U30 -> 5000 | AJ30: =J30 -> 4 | AK30: =K30 -> 4 | AL30: =L30 -> 4 | AM30: =M30 -> 4 | AN30: =N30 -> 4 | AO30: =O30 -> 4 | AP30: =P30 -> 4 | AQ30: =Q30 -> 4 | ... AU30: =U30 -> 4
A31: =A30 -> DDR | B31: Active | C31: Payment posting ERA | D31: Date Entry | E31: Gastro Med | F31: 300 | G31: FTE | W31: =$H31*J31 -> 0 | X31: =$H31*K31 -> 0 | Y31: =$H31*L31 -> 0 | Z31: =$H31*M31 -> 0 | AA31: =$H31*N31 -> 0 | AB31: =$H31*O31 -> 0 | AC31: =$H31*P31 -> 0 | AD31: =$H31*Q31 -> 0 | ... AH31: =$H31*U31 -> 0 | AJ31: =J31 -> 0 | AK31: =K31 -> 0 | AL31: =L31 -> 0 | AM31: =M31 -> 0 | AN31: =N31 -> 0 | AO31: =O31 -> 0 | AP31: =P31 -> 0 | AQ31: =Q31 -> 0 | ... AU31: =U31 -> 0
A32: =A31 -> DDR | B32: In-Active | C32: Eligibility Benefits and Auth verification | D32: Date Entry | E32: Gastro Med | F32: 30 | G32: FTE | H32: 1350
A33: Encore | B33: In-Active | C33: Charge entry | E33: Raintree | F33: 800 | G33: Collection | H33: 0.065 | V33: Price change from 4% to 6.5% effective from. October 2023
A34: =A33 -> Encore | B34: In-Active | C34: Payment posting - Manual | E34: Raintree | F34: 300 | G34: Collection
A35: =A34 -> Encore | B35: In-Active | C35: Payment posting ERA | E35: Raintree | F35: 800 | G35: Collection
A36: =A35 -> Encore | B36: Active | C36: AR | D36: AR | E36: Raintree | F36: 40 | G36: Collection
A37: =A36 -> Encore | B37: In-Active | C37: EV | E37: Raintree | F37: 20 | G37: Collection
A38: =A37 -> Encore | B38: Active | C38: Credentialling | E38: CredSimplify | F38: 50 | G38: FTE | H38: 1300
A39: =A38 -> Encore | B39: In-Active | C39: Eligibility & Benefit Verification | E39: Raintree | F39: 30 | G39: FTE | H39: 1500
A40: Hillmed | B40: In-Active | C40: AR | E40: Intergy | F40: 35 | G40: FTE | H40: 1280
...

Sheet 1. Revenue Buildup 2026
A1: Imagnum India Private Limited
A2: Revenue Buildup
B4: Revenue Summary - 2026 (Budgeted)
B5: Particulars | C5: Total | D5: 46023 | E5: 46054 | F5: 46082 | G5: 46113 | H5: 46143 | I5: 46174 | J5: 46204 | K5: 46235 | L5: 46266 | M5: 46296 | N5: 46327 | O5: 46357
A6: 1 | B6: Base Revenue + New confirmed | C6: =SUM(D6:O6) -> 2490257.2 | D6: ='Base Revenue Details'!J59 -> 225414.12 | E6: ='Base Revenue Details'!L59 -> 238765.5 | F6: ='Base Revenue Details'!N59 -> 239597.86 | G6: ='Base Revenue Details'!P59 -> 203603.86 | H6: ='Base Revenue Details'!S59 -> 199015.5 | I6: ='Base Revenue Details'!U59 -> 198603.86 | J6: ='Base Revenue Details'!W59 -> 198603.86 | K6: ='Base Revenue Details'!Y59 -> 196937.7 | L6: ='Base Revenue Details'!AA59 -> 196937.7 | M6: ='Base Revenue Details'!AC59 -> 198603.86 | N6: ='Base Revenue Details'!AE59 -> 195569.5 | O6: ='Base Revenue Details'!AG59 -> 198603.86
B7: Price per FTE | D7: =D6/'Base Revenue'!X61 -> 1751.4515 | E7: =E6/'Base Revenue'!Y61 -> 1806.075 | F7: =F6/'Base Revenue'!Z61 -> 1960.2002 | G7: =G6/'Base Revenue'!AA61 -> 1665.7258 | H7: =H6/'Base Revenue'!AB61 -> 1628.1875 | I7: =I6/'Base Revenue'!AC61 -> 1624.8198 | J7: =J6/'Base Revenue'!AD61 -> 1624.8198 | K7: =K6/'Base Revenue'!AE61 -> 1611.1885 | ... O7: =O6/'Base Revenue'!AI61 -> 1624.8198
B8: Base FTE | D8: ='Base Revenue'!X61 -> 128.70132 | E8: ='Base Revenue'!Y61 -> 132.20132 | F8: ='Base Revenue'!Z61 -> 122.23132 | G8: ='Base Revenue'!AA61 -> 122.23132 | H8: ='Base Revenue'!AB61 -> 122.23132 | I8: ='Base Revenue'!AC61 -> 122.23132 | J8: ='Base Revenue'!AD61 -> 122.23132 | K8: ='Base Revenue'!AE61 -> 122.23132 | ... O8: ='Base Revenue'!AI61 -> 122.23132
A9: 2 | B9: New Revenue | C9: =SUM(D9:O9) -> 319500 | H9: =H55 -> 13800 | I9: =I55 -> 16800 | J9: =J55 -> 17150 | K9: =K55 -> 49550 | L9: =L55 -> 53550 | M9: =M55 -> 53550 | N9: =N55 -> 57550 | O9: =O55 -> 57550
B10: Price per FTE | D10: 1400 | E10: 1400 | F10: 1400 | G10: 1400 | H10: 1400 | I10: 1400 | J10: 1400 | K10: 1400 | L10: 1400 | M10: 1400 | N10: 1400 | O10: 1400
B11: Additional FTE | D11: =IFERROR(D9/D10,0) -> 0 | E11: =IFERROR(E9/E10,0) -> 0 | F11: =IFERROR(F9/F10,0) -> 0 | G11: =IFERROR(G9/G10,0) -> 0 | H11: =H66 -> 7 | I11: =I66 -> 7 | J11: =J66 -> 12 | K11: =K66 -> 40 | L11: =L66 -> 45 | M11: =M66 -> 50 | N11: =N66 -> 55 | O11: =O66 -> 60
B13: Total Revenue | D13: =D9+D6 -> 225414.12 | E13: =E9+E6 -> 238765.5 | F13: =F9+F6 -> 239597.86 | G13: =G9+G6 -> 203603.86 | H13: =H9+H6 -> 212815.5 | I13: =I9+I6 -> 215403.86 | J13: =J9+J6 -> 215753.86 | K13: =K9+K6 -> 246487.7 | ... O13: =O9+O6 -> 256153.86
B14: Utilisation | D14: 0.85 | E14: 0.85 | F14: 0.85 | G14: 0.85 | H14: 0.85 | I14: 0.85 | J14: 0.85 | K14: 0.85 | L14: 0.85 | M14: 0.85 | N14: 0.85 | O14: 0.85
B15: Deployed FTEs for Total Revenue | D15: =D8+D11 -> 128.70132 | E15: =E8+E11 -> 132.20132 | F15: =F8+F11 -> 122.23132 | G15: =G8+G11 -> 122.23132 | H15: =H8+H11 -> 129.23132 | I15: =I8+I11 -> 129.23132 | J15: =J8+J11 -> 134.23132 | K15: =K8+K11 -> 162.23132 | ... O15: =O8+O11 -> 182.23132 | P15: =SUM(D15:O15) -> 1759.2158
B16: Deployed FTEs @ 85% Utilization | D16: =D15/D14 -> 151.41332 | E16: =E15/E14 -> 155.53096 | F16: =F15/F14 -> 143.80155 | G16: =G15/G14 -> 143.80155 | H16: =H15/H14 -> 152.03684 | I16: =I15/I14 -> 152.03684 | J16: =J15/J14 -> 157.9192 | K16: =K15/K14 -> 190.86037 | ... O16: =O15/O14 -> 214.38979 | P16: =SUM(D16:O16) -> 2069.6657
B17: Current Deployed FTEs | D17: ='India Expenses - Detailed'!E13+19 -> 185 | E17: ='India Expenses - Detailed'!F13+19 -> 185 | F17: ='India Expenses - Detailed'!G13+19 -> 176 | G17: ='India Expenses - Detailed'!H13 -> 157 | H17: ='India Expenses - Detailed'!I13 -> 164 | I17: ='India Expenses - Detailed'!J13 -> 164 | J17: ='India Expenses - Detailed'!K13 -> 169 | K17: ='India Expenses - Detailed'!L13 -> 197 | L17: ='India Expenses - Detailed'!M13 -> 202 | M17: ='India Expenses - Detailed'!N13 -> 207 | N17: ='India Expenses - Detailed'!O13 -> 212 | O17: ='India Expenses - Detailed'!P13 -> 217 | P17: =SUM(D17:O17) -> 2235
B19: Rev/FTE | D19: =D13/D15 -> 1751.4515 | E19: =E13/E15 -> 1806.075 | F19: =F13/F15 -> 1960.2002 | G19: =G13/G15 -> 1665.7258 | H19: =H13/H15 -> 1646.7796 | I19: =I13/I15 -> 1666.8085 | J19: =J13/J15 -> 1607.3288 | K19: =K13/K15 -> 1519.3595 | ... O19: =O13/O15 -> 1405.6522
B20: Rev/FTE @ 85% Utilization | D20: =D13/D16 -> 1488.7338 | E20: =E13/E16 -> 1535.1638 | F20: =F13/F16 -> 1666.1702 | G20: =G13/G16 -> 1415.8669 | H20: =H13/H16 -> 1399.7627 | I20: =I13/I16 -> 1416.7872 | J20: =J13/J16 -> 1366.2295 | K20: =K13/K16 -> 1291.4556 | ... O20: =O13/O16 -> 1194.8044
B21: Rev/FTE @ Current headcount | D21: =D13/D17 -> 1218.4547 | E21: =E13/E17 -> 1290.6243 | F21: =F13/F17 -> 1361.3515 | G21: =G13/G17 -> 1296.8399 | H21: =H13/H17 -> 1297.6555 | I21: =I13/I17 -> 1313.4382 | J21: =J13/J17 -> 1276.6501 | K21: =K13/K17 -> 1251.2066 | ... O21: =O13/O17 -> 1180.4325
B23: % growth | E23: =(E13-D13)/D13 -> 0.059230451 | F23: =(F13-E13)/E13 -> 0.0034860983 | G23: =(G13-F13)/F13 -> -0.15022672 | H23: =(H13-G13)/G13 -> 0.045242954 | I23: =(I13-H13)/H13 -> 0.01216246 | J23: =(J13-I13)/I13 -> 0.0016248548 | K23: =(K13-J13)/J13 -> 0.14244862 | L23: =(L13-K13)/K13 -> 0.01622799 | ... O23: =(O13-N13)/N13 -> 0.011987856
B25: Actual Scenario for CY 2025 for comparison
B26: Particulars | C26: Total | D26: 45658 | E26: 45689 | F26: 45717 | G26: 45748 | H26: 45778 | I26: 45809 | J26: 45839 | K26: 45870 | L26: 45901 | M26: 45931 | N26: 45962 | O26: 45992
B27: Base Revenue | C27: =SUM(D27:O27) -> 2793856.9 | D27: 190587.61 | E27: 238264.71 | F27: 206236 | G27: 220307.54 | H27: 241763 | I27: 255826 | J27: 269055.27 | K27: 245075.07 | L27: 241343.74 | M27: 236462 | N27: 224468 | O27: 224468
B28: Price per FTE
B29: Base FTE
B31: Directs | C31: =SUM(D31:O31) -> 2181 | D31: 148 | E31: 154 | F31: 163 | G31: 170 | H31: 170 | I31: 173 | J31: 187 | K31: 205 | L31: 200 | M31: 205 | N31: 203 | O31: =N31 -> 203
B32: FTE generated | C32: =SUM(D32:O32) -> 1399.2135 | D32: 118 | E32: 87 | F32: 95 | G32: 102 | H32: 103 | I32: 110 | J32: 116 | K32: 139.75092 | L32: 137.62317 | M32: 134.83942 | N32: 128 | O32: 128
B33: Actual Utilisation | C33: =C32/C31 -> 0.64154677 | D33: =D32/D31 -> 0.7972973 | E33: =E32/E31 -> 0.56493506 | F33: =F32/F31 -> 0.58282209 | G33: =G32/G31 -> 0.6 | H33: =H32/H31 -> 0.60588235 | I33: =I32/I31 -> 0.63583815 | J33: =J32/J31 -> 0.62032086 | ... O33: =O32/O31 -> 0.63054187
B35: Utilisation | D35: 0.85 | E35: 0.85 | F35: 0.85 | G35: 0.85 | H35: 0.85 | I35: 0.85 | J35: 0.85 | K35: 0.85 | L35: 0.85 | M35: 0.85 | N35: 0.85 | O35: 0.85
B36: Rev/ FTE (Operational HC) | C36: =C27/C31 -> 1280.9981 | D36: =D27/D31 -> 1287.7541 | E36: =E27/E31 -> 1547.1734 | F36: =F27/F31 -> 1265.2515 | G36: =G27/G31 -> 1295.9267 | H36: =H27/H31 -> 1422.1353 | I36: =I27/I31 -> 1478.763 | J36: =J27/J31 -> 1438.7982 | ... O36: =O27/O31 -> 1105.7537
B37: Price/ FTE (based on budgeted utilisation for FTE generated) | D37: =D27/(D32/85%) -> 1372.8769 | E37: =E27/(E32/85%) -> 2327.8736 | F37: =F27/(F32/85%) -> 1845.2695 | G37: =G27/(G32/85%) -> 1835.8962 | H37: =H27/(H32/85%) -> 1995.1316 | I37: =I27/(I32/85%) -> 1976.8373 | J37: =J27/(J32/85%) -> 1971.5257 | K37: =K27/(K32/85%) -> 1490.6078 | ... O37: =O27/(O32/85%) -> 1490.6078
B38: Cost/FTE | D38: 739.17474 | E38: 682.37081 | F38: 810 | G38: 719 | H38: 744 | I38: 746 | J38: 777 | K38: 860 | L38: 793 | M38: 840 | N38: 842 | O38: 842
B48: New Revenue Calculations Breakdown
B49: New Revenue Workings( 7FTE * 1450) starting in May | H49: =7*1450 -> 10150 | I49: =7*1450 -> 10150 | J49: =7*1450 -> 10150 | K49: =7*1450 -> 10150 | L49: =7*1450 -> 10150 | M49: =7*1450 -> 10150 | N49: =7*1450 -> 10150 | O49: =7*1450 -> 10150
B50: 2650 Rev for 2months only - No headcount increase | H50: 2650 | I50: 2650
B51: 1000 Rev for 2months only - No headcount increase | H51: 1000 | I51: 1000
B52: 32400 Rev per month from August | K52: 32400 | L52: 32400 | M52: 32400 | N52: 32400 | O52: 32400
B53: 200000 collections @ 2% from July till Dec and increase in Sep and Nov | J53: =200000*2% -> 4000 | K53: =200000*2% -> 4000 | L53: =200000*2%+200000*2% -> 8000 | M53: =200000*2%+200000*2% -> 8000 | N53: =200000*2%+200000*2%+200000*2% -> 12000 | O53: =200000*2%+200000*2%+200000*2% -> 12000
B54: 3000 Rev from June till Dec | I54: 3000 | J54: 3000 | K54: 3000 | L54: 3000 | M54: 3000 | N54: 3000 | O54: 3000
H55: =SUM(H49:H54) -> 13800 | I55: =SUM(I49:I54) -> 16800 | J55: =SUM(J49:J54) -> 17150 | K55: =SUM(K49:K54) -> 49550 | L55: =SUM(L49:L54) -> 53550 | M55: =SUM(M49:M54) -> 53550 | N55: =SUM(N49:N54) -> 57550 | O55: =SUM(O49:O54) -> 57550
B57: FTE Required for the increased Rev
...

Sheet Base Revenue
A1: I Magnum | BK1: Base | BL1: =SUM(AJ6:AJ60) -> 1483.2158 | BN1: Deployment
A2: Base Revenue | BK2: Absenteeism | BL2: 0.1 | BM2: =100%-BL2-BL3 -> 0.85 | BN2: =BL1/BM2 -> 1744.9598 | BO2: =BN2*BM2 -> 1483.2158
X3: Base FTEs | AL3: Base FTEs @85% Utlization | BK3: Attrition | BL3: 0.05
AL4: 0.8
A5: Client Code | B5: Status2 | C5: Client | D5: Active/Inactive | E5: Scope | F5: Billing Type | G5: Norm | H5: Pricing | I5: Total Volume | J5: Jan | K5: Feb | L5: Mar | M5: Apr | N5: May | O5: Jun | P5: Jul | Q5: Aug | R5: Sep | S5: Oct | T5: Nov | U5: Dec | V5: Total | X5: Jan | Y5: Feb | Z5: Mar | AA5: Apr | AB5: May | AC5: Jun | AD5: Jul | AE5: Aug | AF5: Sep | AG5: Oct | AH5: Nov | AI5: Dec | AJ5: Total | AL5: Jan | AM5: Feb | AN5: Mar | AO5: Apr | AP5: May | AQ5: Jun | AR5: Jul | AS5: Aug | AT5: Sep | AU5: Oct | AV5: Nov | AW5: Dec | AX5: Total | AY5: Monthly Avg | BA5: AM & MT | BB5: DM | BC5: Manager | BD5: Training | BE5: SWAT | BF5: MIS | BG5: Development | BH5: Ops Support | BK5: Overall | BL5: Rev | BM5: Base FTE | BN5: Rev/FTE
B6: Base | C6: eC3 LLC | E6: IVF Collection | F6: Collection | G6: 150 | H6: 0.0043 | J6: 2365 | K6: 2365 | L6: 2451 | M6: 2580 | N6: 2365 | O6: 2580 | P6: 2580 | Q6: 2580 | R6: 2580 | S6: 2580 | T6: 2580 | U6: 2580 | V6: =SUM(J6:U6) -> 30186 | X6: ='Base FTE'!$I36 -> 2.2857143 | Y6: ='Base FTE'!$I36 -> 2.2857143 | Z6: ='Base FTE'!$I36 -> 2.2857143 | AA6: ='Base FTE'!$I36 -> 2.2857143 | AB6: ='Base FTE'!$I36 -> 2.2857143 | AC6: ='Base FTE'!$I36 -> 2.2857143 | AD6: ='Base FTE'!$I36 -> 2.2857143 | AE6: ='Base FTE'!$I36 -> 2.2857143 | ... AI6: ='Base FTE'!$I36 -> 2.2857143 | AJ6: =SUM(X6:AI6) -> 27.428571 | AL6: =X6/$AL$4 -> 2.8571429 | AM6: =Y6/$AL$4 -> 2.8571429 | AN6: =Z6/$AL$4 -> 2.8571429 | AO6: =AA6/$AL$4 -> 2.8571429 | AP6: =AB6/$AL$4 -> 2.8571429 | AQ6: =AC6/$AL$4 -> 2.8571429 | AR6: =AD6/$AL$4 -> 2.8571429 | AS6: =AE6/$AL$4 -> 2.8571429 | ... AW6: =AI6/$AL$4 -> 2.8571429 | AX6: =SUM(AL6:AW6) -> 34.285714 | AY6: =AX6/12 -> 2.8571429 | BA6: =AY6/'2. Headcount Buildup'!$D$36 -> 0.19047619 | BB6: =AY6/'2. Headcount Buildup'!$D$37 -> 0.057142857 | BC6: =AY6/'2. Headcount Buildup'!$D$38 -> 0.028571429 | BD6: =AY6/'2. Headcount Buildup'!$D$43 -> 0.028571429 | BE6: =(SUM('2. Headcount Buildup'!$F$44:$Q$44)/12)*('Base Revenue'!$AY6/'Base Revenue'!$AY$61) -> 0.05547791 | BF6: =(SUM('2. Headcount Buildup'!$F$45:$Q$45)/12)*('Base Revenue'!$AY6/'Base Revenue'!$AY$61) -> 0.092463184 | BG6: =(SUM('2. Headcount Buildup'!$F$46:$Q$46)/12)*('Base Revenue'!$AY6/'Base Revenue'!$AY$61) -> 0.14794109 | BH6: =SUM(BA6:BG6) -> 0.60064409 | BK6: eC3 LLC | BL6: =IFERROR(SUMIF($C$6:$C$60,BK6,$V$6:$V$60),0) -> 136567 | BM6: =IFERROR(SUMIF($C$5:$C$60,BK6,$AJ$5:$AJ$60),0) -> 27.428571 | BN6: =IFERROR(BL6/BM6,0) -> 4979.0052
B7: Base | C7: eC3 LLC | E7: Non-IVF Collection | F7: Collection | G7: 150 | H7: 0.0255 | J7: 7650 | K7: 7650 | L7: 8415 | M7: 8925 | N7: 7650 | O7: 8925 | P7: 8925 | Q7: 8925 | R7: 8925 | S7: 8925 | T7: 8925 | U7: 8925 | V7: =SUM(J7:U7) -> 102765 | AJ7: =SUM(X7:AI7) -> 0 | AX7: =SUM(AL7:AW7) -> 0 | AY7: =AX7/12 -> 0 | BA7: =AY7/'2. Headcount Buildup'!$D$36 -> 0 | BB7: =AY7/'2. Headcount Buildup'!$D$37 -> 0 | BC7: =AY7/'2. Headcount Buildup'!$D$38 -> 0 | BD7: =AY7/'2. Headcount Buildup'!$D$43 -> 0 | BE7: =(SUM('2. Headcount Buildup'!$F$44:$Q$44)/12)*('Base Revenue'!$AY7/'Base Revenue'!$AY$61) -> 0 | BF7: =(SUM('2. Headcount Buildup'!$F$45:$Q$45)/12)*('Base Revenue'!$AY7/'Base Revenue'!$AY$61) -> 0 | BG7: =(SUM('2. Headcount Buildup'!$F$46:$Q$46)/12)*('Base Revenue'!$AY7/'Base Revenue'!$AY$61) -> 0 | BH7: =SUM(BA7:BG7) -> 0 | BK7: D'Souza & Associates, Inc | BL7: =IFERROR(SUMIF($C$6:$C$60,BK7,$V$6:$V$60),0) -> 365662.68 | BM7: =IFERROR(SUMIF($C$5:$C$60,BK7,$AJ$5:$AJ$60),0) -> 341.41311 | BN7: =IFERROR(BL7/BM7,0) -> 1071.0271
B8: Base | C8: eC3 LLC | E8: Patient Collection | F8: Collection | G8: 150 | H8: 0.0064 | J8: 256 | K8: 256 | L8: 288 | M8: 320 | N8: 256 | O8: 320 | P8: 320 | Q8: 320 | R8: 320 | S8: 320 | T8: 320 | U8: 320 | V8: =SUM(J8:U8) -> 3616 | AJ8: =SUM(X8:AI8) -> 0 | AX8: =SUM(AL8:AW8) -> 0 | AY8: =AX8/12 -> 0 | BA8: =AY8/'2. Headcount Buildup'!$D$36 -> 0 | BB8: =AY8/'2. Headcount Buildup'!$D$37 -> 0 | BC8: =AY8/'2. Headcount Buildup'!$D$38 -> 0 | BD8: =AY8/'2. Headcount Buildup'!$D$43 -> 0 | BE8: =(SUM('2. Headcount Buildup'!$F$44:$Q$44)/12)*('Base Revenue'!$AY8/'Base Revenue'!$AY$61) -> 0 | BF8: =(SUM('2. Headcount Buildup'!$F$45:$Q$45)/12)*('Base Revenue'!$AY8/'Base Revenue'!$AY$61) -> 0 | BG8: =(SUM('2. Headcount Buildup'!$F$46:$Q$46)/12)*('Base Revenue'!$AY8/'Base Revenue'!$AY$61) -> 0 | BH8: =SUM(BA8:BG8) -> 0 | BK8: Univ. Of Delaware | BL8: =IFERROR(SUMIF($C$6:$C$60,BK8,$V$6:$V$60),0) -> 104400 | BM8: =IFERROR(SUMIF($C$5:$C$60,BK8,$AJ$5:$AJ$60),0) -> 87.770327 | BN8: =IFERROR(BL8/BM8,0) -> 1189.4681
B9: Base | C9: D'Souza & Associates, Inc | E9: Demo Entry | F9: Transaction | G9: 300 | H9: 0.55 | I9: 840 | J9: 462 | K9: 462 | L9: 462 | M9: 462 | N9: 462 | O9: 462 | P9: 462 | Q9: 462 | R9: 462 | S9: 462 | T9: 462 | U9: 462 | V9: =SUM(J9:U9) -> 5544 | X9: =$I9/$G9/21 -> 0.13333333 | Y9: =$I9/$G9/21 -> 0.13333333 | Z9: =$I9/$G9/21 -> 0.13333333 | AA9: =$I9/$G9/21 -> 0.13333333 | AB9: =$I9/$G9/21 -> 0.13333333 | AC9: =$I9/$G9/21 -> 0.13333333 | AD9: =$I9/$G9/21 -> 0.13333333 | AE9: =$I9/$G9/21 -> 0.13333333 | ... AI9: =$I9/$G9/21 -> 0.13333333 | AJ9: =SUM(X9:AI9) -> 1.6 | AL9: =X9/$AL$4 -> 0.16666667 | AM9: =Y9/$AL$4 -> 0.16666667 | AN9: =Z9/$AL$4 -> 0.16666667 | AO9: =AA9/$AL$4 -> 0.16666667 | AP9: =AB9/$AL$4 -> 0.16666667 | AQ9: =AC9/$AL$4 -> 0.16666667 | AR9: =AD9/$AL$4 -> 0.16666667 | AS9: =AE9/$AL$4 -> 0.16666667 | ... AW9: =AI9/$AL$4 -> 0.16666667 | AX9: =SUM(AL9:AW9) -> 2 | AY9: =AX9/12 -> 0.16666667 | BA9: =AY9/'2. Headcount Buildup'!$D$36 -> 0.011111111 | BB9: =AY9/'2. Headcount Buildup'!$D$37 -> 0.0033333333 | BC9: =AY9/'2. Headcount Buildup'!$D$38 -> 0.0016666667 | BD9: =AY9/'2. Headcount Buildup'!$D$43 -> 0.0016666667 | BE9: =(SUM('2. Headcount Buildup'!$F$44:$Q$44)/12)*('Base Revenue'!$AY9/'Base Revenue'!$AY$61) -> 0.0032362114 | BF9: =(SUM('2. Headcount Buildup'!$F$45:$Q$45)/12)*('Base Revenue'!$AY9/'Base Revenue'!$AY$61) -> 0.0053936857 | BG9: =(SUM('2. Headcount Buildup'!$F$46:$Q$46)/12)*('Base Revenue'!$AY9/'Base Revenue'!$AY$61) -> 0.0086298972 | BH9: =SUM(BA9:BG9) -> 0.035037572 | BK9: Staff a Dental LLC | BL9: =IFERROR(SUMIF($C$6:$C$60,BK9,$V$6:$V$60),0) -> 30720 | BM9: =IFERROR(SUMIF($C$5:$C$60,BK9,$AJ$5:$AJ$60),0) -> 24 | BN9: =IFERROR(BL9/BM9,0) -> 1280
B10: Base | C10: D'Souza & Associates, Inc | E10: Demo Verify | F10: Transaction | G10: 300 | H10: 0.27 | I10: 6143.5 | J10: 1620 | K10: 1593 | L10: 1710.99 | M10: 1710.99 | N10: 1593 | O10: 1710.99 | P10: 1710.99 | Q10: 1620 | R10: 1620 | S10: 1710.99 | T10: 1593 | U10: 1710.99 | V10: =SUM(J10:U10) -> 19904.94 | X10: =$I10/$G10/21 -> 0.97515873 | Y10: =$I10/$G10/21 -> 0.97515873 | Z10: =$I10/$G10/21 -> 0.97515873 | AA10: =$I10/$G10/21 -> 0.97515873 | AB10: =$I10/$G10/21 -> 0.97515873 | AC10: =$I10/$G10/21 -> 0.97515873 | AD10: =$I10/$G10/21 -> 0.97515873 | AE10: =$I10/$G10/21 -> 0.97515873 | ... AI10: =$I10/$G10/21 -> 0.97515873 | AJ10: =SUM(X10:AI10) -> 11.701905 | AL10: =X10/$AL$4 -> 1.2189484 | AM10: =Y10/$AL$4 -> 1.2189484 | AN10: =Z10/$AL$4 -> 1.2189484 | AO10: =AA10/$AL$4 -> 1.2189484 | AP10: =AB10/$AL$4 -> 1.2189484 | AQ10: =AC10/$AL$4 -> 1.2189484 | AR10: =AD10/$AL$4 -> 1.2189484 | AS10: =AE10/$AL$4 -> 1.2189484 | ... AW10: =AI10/$AL$4 -> 1.2189484 | AX10: =SUM(AL10:AW10) -> 14.627381 | AY10: =AX10/12 -> 1.2189484 | BA10: =AY10/'2. Headcount Buildup'!$D$36 -> 0.081263228 | BB10: =AY10/'2. Headcount Buildup'!$D$37 -> 0.024378968 | BC10: =AY10/'2. Headcount Buildup'!$D$38 -> 0.012189484 | BD10: =AY10/'2. Headcount Buildup'!$D$43 -> 0.012189484 | BE10: =(SUM('2. Headcount Buildup'!$F$44:$Q$44)/12)*('Base Revenue'!$AY10/'Base Revenue'!$AY$61) -> 0.023668649 | BF10: =(SUM('2. Headcount Buildup'!$F$45:$Q$45)/12)*('Base Revenue'!$AY10/'Base Revenue'!$AY$61) -> 0.039447748 | BG10: =(SUM('2. Headcount Buildup'!$F$46:$Q$46)/12)*('Base Revenue'!$AY10/'Base Revenue'!$AY$61) -> 0.063116397 | BH10: =SUM(BA10:BG10) -> 0.25625396 | BK10: Source It Dental | BL10: =IFERROR(SUMIF($C$6:$C$60,BK10,$V$6:$V$60),0) -> 34560 | BM10: =IFERROR(SUMIF($C$5:$C$60,BK10,$AJ$5:$AJ$60),0) -> 24 | BN10: =IFERROR(BL10/BM10,0) -> 1440
B11: Base | C11: D'Souza & Associates, Inc | E11: IV Entry | F11: Transaction | G11: 150 | H11: 0.54 | I11: 813 | J11: 447.12 | K11: 432 | L11: 447.12 | M11: 447.12 | N11: 432 | O11: 447.12 | P11: 447.12 | Q11: 421.2 | R11: 421.2 | S11: 447.12 | T11: 432 | U11: 447.12 | V11: =SUM(J11:U11) -> 5268.24 | X11: =$I11/$G11/21 -> 0.25809524 | Y11: =$I11/$G11/21 -> 0.25809524 | Z11: =$I11/$G11/21 -> 0.25809524 | AA11: =$I11/$G11/21 -> 0.25809524 | AB11: =$I11/$G11/21 -> 0.25809524 | AC11: =$I11/$G11/21 -> 0.25809524 | AD11: =$I11/$G11/21 -> 0.25809524 | AE11: =$I11/$G11/21 -> 0.25809524 | ... AI11: =$I11/$G11/21 -> 0.25809524 | AJ11: =SUM(X11:AI11) -> 3.0971429 | AL11: =X11/$AL$4 -> 0.32261905 | AM11: =Y11/$AL$4 -> 0.32261905 | AN11: =Z11/$AL$4 -> 0.32261905 | AO11: =AA11/$AL$4 -> 0.32261905 | AP11: =AB11/$AL$4 -> 0.32261905 | AQ11: =AC11/$AL$4 -> 0.32261905 | AR11: =AD11/$AL$4 -> 0.32261905 | AS11: =AE11/$AL$4 -> 0.32261905 | ... AW11: =AI11/$AL$4 -> 0.32261905 | AX11: =SUM(AL11:AW11) -> 3.8714286 | AY11: =AX11/12 -> 0.32261905 | BA11: =AY11/'2. Headcount Buildup'!$D$36 -> 0.021507937 | BB11: =AY11/'2. Headcount Buildup'!$D$37 -> 0.006452381 | BC11: =AY11/'2. Headcount Buildup'!$D$38 -> 0.0032261905 | BD11: =AY11/'2. Headcount Buildup'!$D$43 -> 0.0032261905 | BE11: =(SUM('2. Headcount Buildup'!$F$44:$Q$44)/12)*('Base Revenue'!$AY11/'Base Revenue'!$AY$61) -> 0.0062643807 | BF11: =(SUM('2. Headcount Buildup'!$F$45:$Q$45)/12)*('Base Revenue'!$AY11/'Base Revenue'!$AY$61) -> 0.010440635 | BG11: =(SUM('2. Headcount Buildup'!$F$46:$Q$46)/12)*('Base Revenue'!$AY11/'Base Revenue'!$AY$61) -> 0.016705015 | BH11: =SUM(BA11:BG11) -> 0.067822729 | BK11: Physical Therapy & Sports Medicine Center | BL11: =IFERROR(SUMIF($C$6:$C$60,BK11,$V$6:$V$60),0) -> 0 | BM11: =IFERROR(SUMIF($C$5:$C$60,BK11,$AJ$5:$AJ$60),0) -> 0 | BN11: =IFERROR(BL11/BM11,0) -> 0
B12: Base | C12: D'Souza & Associates, Inc | E12: IV Verify | F12: Transaction | G12: 150 | H12: 0.25 | I12: 6114.5 | J12: 1500 | K12: 1500 | L12: 1557.25 | M12: 1557.25 | N12: 1500 | O12: 1557.25 | P12: 1557.25 | Q12: 1500 | R12: 1500 | S12: 1557.25 | T12: 1500 | U12: 1557.25 | V12: =SUM(J12:U12) -> 18343.5 | X12: =$I12/$G12/21 -> 1.9411111 | Y12: =$I12/$G12/21 -> 1.9411111 | Z12: =$I12/$G12/21 -> 1.9411111 | AA12: =$I12/$G12/21 -> 1.9411111 | AB12: =$I12/$G12/21 -> 1.9411111 | AC12: =$I12/$G12/21 -> 1.9411111 | AD12: =$I12/$G12/21 -> 1.9411111 | AE12: =$I12/$G12/21 -> 1.9411111 | ... AI12: =$I12/$G12/21 -> 1.9411111 | AJ12: =SUM(X12:AI12) -> 23.293333 | AL12: =X12/$AL$4 -> 2.4263889 | AM12: =Y12/$AL$4 -> 2.4263889 | AN12: =Z12/$AL$4 -> 2.4263889 | AO12: =AA12/$AL$4 -> 2.4263889 | AP12: =AB12/$AL$4 -> 2.4263889 | AQ12: =AC12/$AL$4 -> 2.4263889 | AR12: =AD12/$AL$4 -> 2.4263889 | AS12: =AE12/$AL$4 -> 2.4263889 | ... AW12: =AI12/$AL$4 -> 2.4263889 | AX12: =SUM(AL12:AW12) -> 29.116667 | AY12: =AX12/12 -> 2.4263889 | BA12: =AY12/'2. Headcount Buildup'!$D$36 -> 0.16175926 | BB12: =AY12/'2. Headcount Buildup'!$D$37 -> 0.048527778 | BC12: =AY12/'2. Headcount Buildup'!$D$38 -> 0.024263889 | BD12: =AY12/'2. Headcount Buildup'!$D$43 -> 0.024263889 | BE12: =(SUM('2. Headcount Buildup'!$F$44:$Q$44)/12)*('Base Revenue'!$AY12/'Base Revenue'!$AY$61) -> 0.047113845 | BF12: =(SUM('2. Headcount Buildup'!$F$45:$Q$45)/12)*('Base Revenue'!$AY12/'Base Revenue'!$AY$61) -> 0.078523075 | BG12: =(SUM('2. Headcount Buildup'!$F$46:$Q$46)/12)*('Base Revenue'!$AY12/'Base Revenue'!$AY$61) -> 0.12563692 | BH12: =SUM(BA12:BG12) -> 0.51008865 | BK12: Primetime Physical Therapy | BL12: =IFERROR(SUMIF($C$6:$C$60,BK12,$V$6:$V$60),0) -> 86400 | BM12: =IFERROR(SUMIF($C$5:$C$60,BK12,$AJ$5:$AJ$60),0) -> 24.212381 | BN12: =IFERROR(BL12/BM12,0) -> 3568.4223
B13: Base | C13: D'Souza & Associates, Inc | E13: AR Follow-up | F13: Transaction | G13: 40 | H13: 1 | I13: 9250 | J13: 9000 | K13: 8000 | L13: 10000 | M13: 10000 | N13: 8000 | O13: 10000 | P13: 10000 | Q13: 9000 | R13: 9000 | S13: 10000 | T13: 8000 | U13: 10000 | V13: =SUM(J13:U13) -> 111000 | X13: =$I13/$G13/21 -> 11.011905 | Y13: =$I13/$G13/21 -> 11.011905 | Z13: =$I13/$G13/21 -> 11.011905 | AA13: =$I13/$G13/21 -> 11.011905 | AB13: =$I13/$G13/21 -> 11.011905 | AC13: =$I13/$G13/21 -> 11.011905 | AD13: =$I13/$G13/21 -> 11.011905 | AE13: =$I13/$G13/21 -> 11.011905 | ... AI13: =$I13/$G13/21 -> 11.011905 | AJ13: =SUM(X13:AI13) -> 132.14286 | AL13: =X13/$AL$4 -> 13.764881 | AM13: =Y13/$AL$4 -> 13.764881 | AN13: =Z13/$AL$4 -> 13.764881 | AO13: =AA13/$AL$4 -> 13.764881 | AP13: =AB13/$AL$4 -> 13.764881 | AQ13: =AC13/$AL$4 -> 13.764881 | AR13: =AD13/$AL$4 -> 13.764881 | AS13: =AE13/$AL$4 -> 13.764881 | ... AW13: =AI13/$AL$4 -> 13.764881 | AX13: =SUM(AL13:AW13) -> 165.17857 | AY13: =AX13/12 -> 13.764881 | BA13: =AY13/'2. Headcount Buildup'!$D$36 -> 0.91765873 | BB13: =AY13/'2. Headcount Buildup'!$D$37 -> 0.27529762 | BC13: =AY13/'2. Headcount Buildup'!$D$38 -> 0.13764881 | BD13: =AY13/'2. Headcount Buildup'!$D$43 -> 0.13764881 | BE13: =(SUM('2. Headcount Buildup'!$F$44:$Q$44)/12)*('Base Revenue'!$AY13/'Base Revenue'!$AY$61) -> 0.26727639 | BF13: =(SUM('2. Headcount Buildup'!$F$45:$Q$45)/12)*('Base Revenue'!$AY13/'Base Revenue'!$AY$61) -> 0.44546065 | BG13: =(SUM('2. Headcount Buildup'!$F$46:$Q$46)/12)*('Base Revenue'!$AY13/'Base Revenue'!$AY$61) -> 0.71273704 | BH13: =SUM(BA13:BG13) -> 2.8937281 | BK13: Comprehensive Sleep Care Center | BL13: =IFERROR(SUMIF($C$6:$C$60,BK13,$V$6:$V$60),0) -> 784400 | BM13: =IFERROR(SUMIF($C$5:$C$60,BK13,$AJ$5:$AJ$60),0) -> 551 | BN13: =IFERROR(BL13/BM13,0) -> 1423.5935
B14: Base | C14: D'Souza & Associates, Inc | E14: HCA & Intergy Charge Entry | F14: Transaction | G14: 380 | H14: 0.14 | I14: 41750 | J14: 5740 | K14: 5600 | L14: 6020 | M14: 6020 | N14: 5600 | O14: 6020 | P14: 6020 | Q14: 5740 | R14: 5740 | S14: 6020 | T14: 5600 | U14: 6020 | V14: =SUM(J14:U14) -> 70140 | X14: =$I14/$G14/21 -> 5.2318296 | Y14: =$I14/$G14/21 -> 5.2318296 | Z14: =$I14/$G14/21 -> 5.2318296 | AA14: =$I14/$G14/21 -> 5.2318296 | AB14: =$I14/$G14/21 -> 5.2318296 | AC14: =$I14/$G14/21 -> 5.2318296 | AD14: =$I14/$G14/21 -> 5.2318296 | AE14: =$I14/$G14/21 -> 5.2318296 | ... AI14: =$I14/$G14/21 -> 5.2318296 | AJ14: =SUM(X14:AI14) -> 62.781955 | AL14: =X14/$AL$4 -> 6.539787 | AM14: =Y14/$AL$4 -> 6.539787 | AN14: =Z14/$AL$4 -> 6.539787 | AO14: =AA14/$AL$4 -> 6.539787 | AP14: =AB14/$AL$4 -> 6.539787 | AQ14: =AC14/$AL$4 -> 6.539787 | AR14: =AD14/$AL$4 -> 6.539787 | AS14: =AE14/$AL$4 -> 6.539787 | ... AW14: =AI14/$AL$4 -> 6.539787 | AX14: =SUM(AL14:AW14) -> 78.477444 | AY14: =AX14/12 -> 6.539787 | BA14: =AY14/'2. Headcount Buildup'!$D$36 -> 0.4359858 | BB14: =AY14/'2. Headcount Buildup'!$D$37 -> 0.13079574 | BC14: =AY14/'2. Headcount Buildup'!$D$38 -> 0.06539787 | BD14: =AY14/'2. Headcount Buildup'!$D$43 -> 0.06539787 | BE14: =(SUM('2. Headcount Buildup'!$F$44:$Q$44)/12)*('Base Revenue'!$AY14/'Base Revenue'!$AY$61) -> 0.1269848 | BF14: =(SUM('2. Headcount Buildup'!$F$45:$Q$45)/12)*('Base Revenue'!$AY14/'Base Revenue'!$AY$61) -> 0.21164133 | BG14: =(SUM('2. Headcount Buildup'!$F$46:$Q$46)/12)*('Base Revenue'!$AY14/'Base Revenue'!$AY$61) -> 0.33862613 | BH14: =SUM(BA14:BG14) -> 1.3748295 | BK14: Your Docs In | BL14: =IFERROR(SUMIF($C$6:$C$60,BK14,$V$6:$V$60),0) -> 130315 | BM14: =IFERROR(SUMIF($C$5:$C$60,BK14,$AJ$5:$AJ$60),0) -> 36.94 | BN14: =IFERROR(BL14/BM14,0) -> 3527.7477
B15: Base | C15: D'Souza & Associates, Inc | E15: Payment Posting - ERA | F15: Transaction | G15: 2000 | H15: 0.026 | I15: 38500 | J15: 988 | K15: 936 | L15: 1040 | M15: 1040 | N15: 936 | O15: 1040 | P15: 1040 | Q15: 988 | R15: 988 | S15: 1040 | T15: 936 | U15: 1040 | V15: =SUM(J15:U15) -> 12012 | X15: =$I15/$G15/21 -> 0.91666667 | Y15: =$I15/$G15/21 -> 0.91666667 | Z15: =$I15/$G15/21 -> 0.91666667 | AA15: =$I15/$G15/21 -> 0.91666667 | AB15: =$I15/$G15/21 -> 0.91666667 | AC15: =$I15/$G15/21 -> 0.91666667 | AD15: =$I15/$G15/21 -> 0.91666667 | AE15: =$I15/$G15/21 -> 0.91666667 | ... AI15: =$I15/$G15/21 -> 0.91666667 | AJ15: =SUM(X15:AI15) -> 11 | AL15: =X15/$AL$4 -> 1.1458333 | AM15: =Y15/$AL$4 -> 1.1458333 | AN15: =Z15/$AL$4 -> 1.1458333 | AO15: =AA15/$AL$4 -> 1.1458333 | AP15: =AB15/$AL$4 -> 1.1458333 | AQ15: =AC15/$AL$4 -> 1.1458333 | AR15: =AD15/$AL$4 -> 1.1458333 | AS15: =AE15/$AL$4 -> 1.1458333 | ... AW15: =AI15/$AL$4 -> 1.1458333 | AX15: =SUM(AL15:AW15) -> 13.75 | AY15: =AX15/12 -> 1.1458333 | BA15: =AY15/'2. Headcount Buildup'!$D$36 -> 0.076388889 | BB15: =AY15/'2. Headcount Buildup'!$D$37 -> 0.022916667 | BC15: =AY15/'2. Headcount Buildup'!$D$38 -> 0.011458333 | BD15: =AY15/'2. Headcount Buildup'!$D$43 -> 0.011458333 | BE15: =(SUM('2. Headcount Buildup'!$F$44:$Q$44)/12)*('Base Revenue'!$AY15/'Base Revenue'!$AY$61) -> 0.022248954 | BF15: =(SUM('2. Headcount Buildup'!$F$45:$Q$45)/12)*('Base Revenue'!$AY15/'Base Revenue'!$AY$61) -> 0.037081589 | BG15: =(SUM('2. Headcount Buildup'!$F$46:$Q$46)/12)*('Base Revenue'!$AY15/'Base Revenue'!$AY$61) -> 0.059330543 | BH15: =SUM(BA15:BG15) -> 0.24088331 | BK15: The Physical Therapy Institute | BL15: =IFERROR(SUMIF($C$6:$C$60,BK15,$V$6:$V$60),0) -> 31875 | BM15: =IFERROR(SUMIF($C$5:$C$60,BK15,$AJ$5:$AJ$60),0) -> 31.857143 | BN15: =IFERROR(BL15/BM15,0) -> 1000.5605
