Workbook
Name \: #REF!
Name \: #REF!
Name \: #REF!
Name \: #REF!
Name \0: #REF!
Name \0: #REF!
Name \0: #REF!
Name \0: #REF!
Name \A: #REF!
Name \A: #REF!
Name \A: #REF!
Name \A: #REF!
Name \B: #REF!
Name \B: #REF!
Name \B: #REF!
Name \B: #REF!
Name \E: #REF!
Name \E: #REF!
Name \E: #REF!
Name \E: #REF!
Name \G: #REF!
Name \G: #REF!
Name \G: #REF!
Name \G: #REF!
Name \L: #REF!
Name \L: #REF!
Name \L: #REF!
Name \L: #REF!
Name \q: #REF!
Name \q: #REF!
Name \q: #REF!
Name \q: #REF!
Name \S: #REF!
Name \S: #REF!
Name \S: #REF!
Name \S: #REF!
Name \T: #REF!
Name \T: #REF!
Name \T: #REF!
Name \T: #REF!
Name \U: #REF!
Name \U: #REF!
Name \U: #REF!
Name \U: #REF!
Name ________DAT7: #REF!
Name ________DAT7: #REF!
Name ________DAT7: #REF!
Name ________DAT7: #REF!
Name ________DAT8: #REF!
Name ________DAT8: #REF!
Name ________DAT8: #REF!
Name ________DAT8: #REF!
Name ________DAT9: #REF!
Name ________DAT9: #REF!
Name ________DAT9: #REF!
Name ________DAT9: #REF!
Name _______DAT13: #REF!
Name _______DAT13: #REF!
Name _______DAT13: #REF!
Name _______DAT13: #REF!

Sheet MIS-Actuals
B5: MIS Actuals
B7: >>>>

Sheet MIS Actuals Jan-Jun
A1: I-Magnum Healthcare Solution Inc.
A2: MIS Actuals - Consolidated P&L, Jan to June 2026 (USD, post-elimination Total)
A6: Particulars | B6: 46023 | C6: 46054 | D6: 46082 | E6: 46113 | F6: 46143 | G6: 46174 | H6: 46204 | I6: Total
A7: =IF('Jun''26'!B7="","",'Jun''26'!B7) -> Service Income | B7: =IFERROR(IF(INDEX(Jan!$E:$E,MATCH(TRIM($A7),Jan!$B:$B,0))="","",INDEX(Jan!$E:$E,MATCH(TRIM($A7),Jan!$B:$B,0))),"") | C7: =IFERROR(IF(INDEX('March-Feb'!$I:$I,MATCH($A7,'March-Feb'!$B:$B,0))="","",INDEX('March-Feb'!$I:$I,MATCH($A7,'March-Feb'!$B:$B,0))),"") | D7: =IFERROR(IF(INDEX('March-Feb'!$E:$E,MATCH($A7,'March-Feb'!$B:$B,0))="","",INDEX('March-Feb'!$E:$E,MATCH($A7,'March-Feb'!$B:$B,0))),"") | E7: =IFERROR(IF(INDEX('April-March'!$F:$F,MATCH($A7,'April-March'!$B:$B,0))="","",INDEX('April-March'!$F:$F,MATCH($A7,'April-March'!$B:$B,0))),"") | F7: =IFERROR(IF(INDEX('May-April'!$F:$F,MATCH($A7,'May-April'!$B:$B,0))="","",INDEX('May-April'!$F:$F,MATCH($A7,'May-April'!$B:$B,0))),"") | G7: =IF('Jun''26'!F7="","",'Jun''26'!F7) | H7: =IFERROR(IF(INDEX('Jul''26'!$F:$F,MATCH($A7,'Jul''26'!$B:$B,0))="","",INDEX('Jul''26'!$F:$F,MATCH($A7,'Jul''26'!$B:$B,0))),"") | I7: =IF(COUNT(B7:G7)=0,"",SUM(B7:G7))
A8: =IF('Jun''26'!B8="","",'Jun''26'!B8) -> Sales | B8: =IFERROR(IF(INDEX(Jan!$E:$E,MATCH(TRIM($A8),Jan!$B:$B,0))="","",INDEX(Jan!$E:$E,MATCH(TRIM($A8),Jan!$B:$B,0))),"") -> 226814 | C8: =IFERROR(IF(INDEX('March-Feb'!$I:$I,MATCH($A8,'March-Feb'!$B:$B,0))="","",INDEX('March-Feb'!$I:$I,MATCH($A8,'March-Feb'!$B:$B,0))),"") -> 227771 | D8: =IFERROR(IF(INDEX('March-Feb'!$E:$E,MATCH($A8,'March-Feb'!$B:$B,0))="","",INDEX('March-Feb'!$E:$E,MATCH($A8,'March-Feb'!$B:$B,0))),"") -> 221215 | E8: =IFERROR(IF(INDEX('April-March'!$F:$F,MATCH($A8,'April-March'!$B:$B,0))="","",INDEX('April-March'!$F:$F,MATCH($A8,'April-March'!$B:$B,0))),"") -> 195207 | F8: =IFERROR(IF(INDEX('May-April'!$F:$F,MATCH($A8,'May-April'!$B:$B,0))="","",INDEX('May-April'!$F:$F,MATCH($A8,'May-April'!$B:$B,0))),"") -> 209918 | G8: =IF('Jun''26'!F8="","",'Jun''26'!F8) -> 232311 | H8: =IFERROR(IF(INDEX('Jul''26'!$F:$F,MATCH($A8,'Jul''26'!$B:$B,0))="","",INDEX('Jul''26'!$F:$F,MATCH($A8,'Jul''26'!$B:$B,0))),"") -> 250672 | I8: =SUM(B8:H8) -> 1563908
A9: =IF('Jun''26'!B9="","",'Jun''26'!B9) -> Sales | B9: =IFERROR(IF(INDEX(Jan!$E:$E,MATCH(TRIM($A9),Jan!$B:$B,0))="","",INDEX(Jan!$E:$E,MATCH(TRIM($A9),Jan!$B:$B,0))),"") -> 226814 | C9: =IFERROR(IF(INDEX('March-Feb'!$I:$I,MATCH($A9,'March-Feb'!$B:$B,0))="","",INDEX('March-Feb'!$I:$I,MATCH($A9,'March-Feb'!$B:$B,0))),"") -> 227770 | D9: =IFERROR(IF(INDEX('March-Feb'!$E:$E,MATCH($A9,'March-Feb'!$B:$B,0))="","",INDEX('March-Feb'!$E:$E,MATCH($A9,'March-Feb'!$B:$B,0))),"") -> 221215 | E9: =IFERROR(IF(INDEX('April-March'!$F:$F,MATCH($A9,'April-March'!$B:$B,0))="","",INDEX('April-March'!$F:$F,MATCH($A9,'April-March'!$B:$B,0))),"") -> 194902 | F9: =IFERROR(IF(INDEX('May-April'!$F:$F,MATCH($A9,'May-April'!$B:$B,0))="","",INDEX('May-April'!$F:$F,MATCH($A9,'May-April'!$B:$B,0))),"") -> 209920 | G9: =IF('Jun''26'!F9="","",'Jun''26'!F9) -> 225714 | H9: =IFERROR(IF(INDEX('Jul''26'!$F:$F,MATCH($A9,'Jul''26'!$B:$B,0))="","",INDEX('Jul''26'!$F:$F,MATCH($A9,'Jul''26'!$B:$B,0))),"") -> 250400 | I9: =SUM(B9:H9) -> 1556735
A10: =IF('Jun''26'!B10="","",'Jun''26'!B10) -> Other Charges | B10: =IFERROR(IF(INDEX(Jan!$E:$E,MATCH(TRIM($A10),Jan!$B:$B,0))="","",INDEX(Jan!$E:$E,MATCH(TRIM($A10),Jan!$B:$B,0))),"") -> 0 | C10: =IFERROR(IF(INDEX('March-Feb'!$I:$I,MATCH($A10,'March-Feb'!$B:$B,0))="","",INDEX('March-Feb'!$I:$I,MATCH($A10,'March-Feb'!$B:$B,0))),"") -> 1 | D10: =IFERROR(IF(INDEX('March-Feb'!$E:$E,MATCH($A10,'March-Feb'!$B:$B,0))="","",INDEX('March-Feb'!$E:$E,MATCH($A10,'March-Feb'!$B:$B,0))),"") -> 0 | E10: =IFERROR(IF(INDEX('April-March'!$F:$F,MATCH($A10,'April-March'!$B:$B,0))="","",INDEX('April-March'!$F:$F,MATCH($A10,'April-March'!$B:$B,0))),"") -> 0 | F10: =IFERROR(IF(INDEX('May-April'!$F:$F,MATCH($A10,'May-April'!$B:$B,0))="","",INDEX('May-April'!$F:$F,MATCH($A10,'May-April'!$B:$B,0))),"") -> 0 | G10: =IF('Jun''26'!F10="","",'Jun''26'!F10) -> 0 | H10: =IFERROR(IF(INDEX('Jul''26'!$F:$F,MATCH($A10,'Jul''26'!$B:$B,0))="","",INDEX('Jul''26'!$F:$F,MATCH($A10,'Jul''26'!$B:$B,0))),"") -> 0 | I10: =SUM(B10:H10) -> 1
A11: =IF('Jun''26'!B11="","",'Jun''26'!B11) -> Buyout | B11: =IFERROR(IF(INDEX(Jan!$E:$E,MATCH(TRIM($A11),Jan!$B:$B,0))="","",INDEX(Jan!$E:$E,MATCH(TRIM($A11),Jan!$B:$B,0))),"") -> 0 | C11: =IFERROR(IF(INDEX('March-Feb'!$I:$I,MATCH($A11,'March-Feb'!$B:$B,0))="","",INDEX('March-Feb'!$I:$I,MATCH($A11,'March-Feb'!$B:$B,0))),"") | D11: =IFERROR(IF(INDEX('March-Feb'!$E:$E,MATCH($A11,'March-Feb'!$B:$B,0))="","",INDEX('March-Feb'!$E:$E,MATCH($A11,'March-Feb'!$B:$B,0))),"") | E11: =IFERROR(IF(INDEX('April-March'!$F:$F,MATCH($A11,'April-March'!$B:$B,0))="","",INDEX('April-March'!$F:$F,MATCH($A11,'April-March'!$B:$B,0))),"") | F11: =IFERROR(IF(INDEX('May-April'!$F:$F,MATCH($A11,'May-April'!$B:$B,0))="","",INDEX('May-April'!$F:$F,MATCH($A11,'May-April'!$B:$B,0))),"") | G11: =IF('Jun''26'!F11="","",'Jun''26'!F11) | H11: =IFERROR(IF(INDEX('Jul''26'!$F:$F,MATCH($A11,'Jul''26'!$B:$B,0))="","",INDEX('Jul''26'!$F:$F,MATCH($A11,'Jul''26'!$B:$B,0))),"") -> 224 | I11: =SUM(B11:H11) -> 224
A12: =IF('Jun''26'!B12="","",'Jun''26'!B12) -> General Income | B12: =IFERROR(IF(INDEX(Jan!$E:$E,MATCH(TRIM($A12),Jan!$B:$B,0))="","",INDEX(Jan!$E:$E,MATCH(TRIM($A12),Jan!$B:$B,0))),"") -> 287 | C12: =IFERROR(IF(INDEX('March-Feb'!$I:$I,MATCH($A12,'March-Feb'!$B:$B,0))="","",INDEX('March-Feb'!$I:$I,MATCH($A12,'March-Feb'!$B:$B,0))),"") -> 0 | D12: =IFERROR(IF(INDEX('March-Feb'!$E:$E,MATCH($A12,'March-Feb'!$B:$B,0))="","",INDEX('March-Feb'!$E:$E,MATCH($A12,'March-Feb'!$B:$B,0))),"") -> 0 | E12: =IFERROR(IF(INDEX('April-March'!$F:$F,MATCH($A12,'April-March'!$B:$B,0))="","",INDEX('April-March'!$F:$F,MATCH($A12,'April-March'!$B:$B,0))),"") -> 16 | F12: =IFERROR(IF(INDEX('May-April'!$F:$F,MATCH($A12,'May-April'!$B:$B,0))="","",INDEX('May-April'!$F:$F,MATCH($A12,'May-April'!$B:$B,0))),"") -> 0 | G12: =IF('Jun''26'!F12="","",'Jun''26'!F12) -> 294 | H12: =IFERROR(IF(INDEX('Jul''26'!$F:$F,MATCH($A12,'Jul''26'!$B:$B,0))="","",INDEX('Jul''26'!$F:$F,MATCH($A12,'Jul''26'!$B:$B,0))),"") -> 16 | I12: =SUM(B12:H12) -> 613
A13: =IF('Jun''26'!B13="","",'Jun''26'!B13) -> Interest Income | B13: =IFERROR(IF(INDEX(Jan!$E:$E,MATCH(TRIM($A13),Jan!$B:$B,0))="","",INDEX(Jan!$E:$E,MATCH(TRIM($A13),Jan!$B:$B,0))),"") -> 0 | C13: =IFERROR(IF(INDEX('March-Feb'!$I:$I,MATCH($A13,'March-Feb'!$B:$B,0))="","",INDEX('March-Feb'!$I:$I,MATCH($A13,'March-Feb'!$B:$B,0))),"") | D13: =IFERROR(IF(INDEX('March-Feb'!$E:$E,MATCH($A13,'March-Feb'!$B:$B,0))="","",INDEX('March-Feb'!$E:$E,MATCH($A13,'March-Feb'!$B:$B,0))),"") | E13: =IFERROR(IF(INDEX('April-March'!$F:$F,MATCH($A13,'April-March'!$B:$B,0))="","",INDEX('April-March'!$F:$F,MATCH($A13,'April-March'!$B:$B,0))),"") -> 289 | F13: =IFERROR(IF(INDEX('May-April'!$F:$F,MATCH($A13,'May-April'!$B:$B,0))="","",INDEX('May-April'!$F:$F,MATCH($A13,'May-April'!$B:$B,0))),"") -> -2 | G13: =IF('Jun''26'!F13="","",'Jun''26'!F13) -> -1 | H13: =IFERROR(IF(INDEX('Jul''26'!$F:$F,MATCH($A13,'Jul''26'!$B:$B,0))="","",INDEX('Jul''26'!$F:$F,MATCH($A13,'Jul''26'!$B:$B,0))),"") -> 54 | I13: =SUM(B13:H13) -> 340
A14: =IF('Jun''26'!B14="","",'Jun''26'!B14) -> Governments Grant Income | B14: =IFERROR(IF(INDEX(Jan!$E:$E,MATCH(TRIM($A14),Jan!$B:$B,0))="","",INDEX(Jan!$E:$E,MATCH(TRIM($A14),Jan!$B:$B,0))),"") | C14: =IFERROR(IF(INDEX('March-Feb'!$I:$I,MATCH($A14,'March-Feb'!$B:$B,0))="","",INDEX('March-Feb'!$I:$I,MATCH($A14,'March-Feb'!$B:$B,0))),"") | D14: =IFERROR(IF(INDEX('March-Feb'!$E:$E,MATCH($A14,'March-Feb'!$B:$B,0))="","",INDEX('March-Feb'!$E:$E,MATCH($A14,'March-Feb'!$B:$B,0))),"") | E14: =IFERROR(IF(INDEX('April-March'!$F:$F,MATCH($A14,'April-March'!$B:$B,0))="","",INDEX('April-March'!$F:$F,MATCH($A14,'April-March'!$B:$B,0))),"") | F14: =IFERROR(IF(INDEX('May-April'!$F:$F,MATCH($A14,'May-April'!$B:$B,0))="","",INDEX('May-April'!$F:$F,MATCH($A14,'May-April'!$B:$B,0))),"") | G14: =IF('Jun''26'!F14="","",'Jun''26'!F14) -> 6304 | H14: =IFERROR(IF(INDEX('Jul''26'!$F:$F,MATCH($A14,'Jul''26'!$B:$B,0))="","",INDEX('Jul''26'!$F:$F,MATCH($A14,'Jul''26'!$B:$B,0))),"") -> -21 | I14: =SUM(B14:H14) -> 6283
A15: =IF('Jun''26'!B15="","",'Jun''26'!B15) -> Total Revenue | B15: =IFERROR(IF(INDEX(Jan!$E:$E,MATCH(TRIM($A15),Jan!$B:$B,0))="","",INDEX(Jan!$E:$E,MATCH(TRIM($A15),Jan!$B:$B,0))),"") -> 226814 | C15: =IFERROR(IF(INDEX('March-Feb'!$I:$I,MATCH($A15,'March-Feb'!$B:$B,0))="","",INDEX('March-Feb'!$I:$I,MATCH($A15,'March-Feb'!$B:$B,0))),"") -> 227771 | D15: =IFERROR(IF(INDEX('March-Feb'!$E:$E,MATCH($A15,'March-Feb'!$B:$B,0))="","",INDEX('March-Feb'!$E:$E,MATCH($A15,'March-Feb'!$B:$B,0))),"") -> 221215 | E15: =IFERROR(IF(INDEX('April-March'!$F:$F,MATCH($A15,'April-March'!$B:$B,0))="","",INDEX('April-March'!$F:$F,MATCH($A15,'April-March'!$B:$B,0))),"") -> 195207 | F15: =IFERROR(IF(INDEX('May-April'!$F:$F,MATCH($A15,'May-April'!$B:$B,0))="","",INDEX('May-April'!$F:$F,MATCH($A15,'May-April'!$B:$B,0))),"") -> 209918 | G15: =IF('Jun''26'!F15="","",'Jun''26'!F15) -> 232311 | H15: =IFERROR(IF(INDEX('Jul''26'!$F:$F,MATCH($A15,'Jul''26'!$B:$B,0))="","",INDEX('Jul''26'!$F:$F,MATCH($A15,'Jul''26'!$B:$B,0))),"") -> 250672 | I15: =SUM(B15:H15) -> 1563908
A16: =IF('Jun''26'!B16="","",'Jun''26'!B16) -> Overall Operational cost | B16: =IFERROR(IF(INDEX(Jan!$E:$E,MATCH(TRIM($A16),Jan!$B:$B,0))="","",INDEX(Jan!$E:$E,MATCH(TRIM($A16),Jan!$B:$B,0))),"") | C16: =IFERROR(IF(INDEX('March-Feb'!$I:$I,MATCH($A16,'March-Feb'!$B:$B,0))="","",INDEX('March-Feb'!$I:$I,MATCH($A16,'March-Feb'!$B:$B,0))),"") | D16: =IFERROR(IF(INDEX('March-Feb'!$E:$E,MATCH($A16,'March-Feb'!$B:$B,0))="","",INDEX('March-Feb'!$E:$E,MATCH($A16,'March-Feb'!$B:$B,0))),"") | E16: =IFERROR(IF(INDEX('April-March'!$F:$F,MATCH($A16,'April-March'!$B:$B,0))="","",INDEX('April-March'!$F:$F,MATCH($A16,'April-March'!$B:$B,0))),"") | F16: =IFERROR(IF(INDEX('May-April'!$F:$F,MATCH($A16,'May-April'!$B:$B,0))="","",INDEX('May-April'!$F:$F,MATCH($A16,'May-April'!$B:$B,0))),"") | G16: =IF('Jun''26'!F16="","",'Jun''26'!F16) | H16: =IFERROR(IF(INDEX('Jul''26'!$F:$F,MATCH($A16,'Jul''26'!$B:$B,0))="","",INDEX('Jul''26'!$F:$F,MATCH($A16,'Jul''26'!$B:$B,0))),"") | I16: =SUM(B16:H16) -> 0
A17: =IF('Jun''26'!B17="","",'Jun''26'!B17) -> Manpower | B17: =IFERROR(IF(INDEX(Jan!$E:$E,MATCH(TRIM($A17),Jan!$B:$B,0))="","",INDEX(Jan!$E:$E,MATCH(TRIM($A17),Jan!$B:$B,0))),"") -> 114851.43 | C17: =IFERROR(IF(INDEX('March-Feb'!$I:$I,MATCH($A17,'March-Feb'!$B:$B,0))="","",INDEX('March-Feb'!$I:$I,MATCH($A17,'March-Feb'!$B:$B,0))),"") -> 108834 | D17: =IFERROR(IF(INDEX('March-Feb'!$E:$E,MATCH($A17,'March-Feb'!$B:$B,0))="","",INDEX('March-Feb'!$E:$E,MATCH($A17,'March-Feb'!$B:$B,0))),"") -> 120509 | E17: =IFERROR(IF(INDEX('April-March'!$F:$F,MATCH($A17,'April-March'!$B:$B,0))="","",INDEX('April-March'!$F:$F,MATCH($A17,'April-March'!$B:$B,0))),"") -> 100793 | F17: =IFERROR(IF(INDEX('May-April'!$F:$F,MATCH($A17,'May-April'!$B:$B,0))="","",INDEX('May-April'!$F:$F,MATCH($A17,'May-April'!$B:$B,0))),"") -> 92483 | G17: =IF('Jun''26'!F17="","",'Jun''26'!F17) -> 94790 | H17: =IFERROR(IF(INDEX('Jul''26'!$F:$F,MATCH($A17,'Jul''26'!$B:$B,0))="","",INDEX('Jul''26'!$F:$F,MATCH($A17,'Jul''26'!$B:$B,0))),"") -> 100703 | I17: =SUM(B17:H17) -> 732963.43
A18: =IF('Jun''26'!B18="","",'Jun''26'!B18) -> India Cost | B18: =IFERROR(IF(INDEX(Jan!$E:$E,MATCH(TRIM($A18),Jan!$B:$B,0))="","",INDEX(Jan!$E:$E,MATCH(TRIM($A18),Jan!$B:$B,0))),"") | C18: =IFERROR(IF(INDEX('March-Feb'!$I:$I,MATCH($A18,'March-Feb'!$B:$B,0))="","",INDEX('March-Feb'!$I:$I,MATCH($A18,'March-Feb'!$B:$B,0))),"") | D18: =IFERROR(IF(INDEX('March-Feb'!$E:$E,MATCH($A18,'March-Feb'!$B:$B,0))="","",INDEX('March-Feb'!$E:$E,MATCH($A18,'March-Feb'!$B:$B,0))),"") | E18: =IFERROR(IF(INDEX('April-March'!$F:$F,MATCH($A18,'April-March'!$B:$B,0))="","",INDEX('April-March'!$F:$F,MATCH($A18,'April-March'!$B:$B,0))),"") | F18: =IFERROR(IF(INDEX('May-April'!$F:$F,MATCH($A18,'May-April'!$B:$B,0))="","",INDEX('May-April'!$F:$F,MATCH($A18,'May-April'!$B:$B,0))),"") | G18: =IF('Jun''26'!F18="","",'Jun''26'!F18) | H18: =IFERROR(IF(INDEX('Jul''26'!$F:$F,MATCH($A18,'Jul''26'!$B:$B,0))="","",INDEX('Jul''26'!$F:$F,MATCH($A18,'Jul''26'!$B:$B,0))),"") -> 0 | I18: =SUM(B18:H18) -> 0
A19: =IF('Jun''26'!B19="","",'Jun''26'!B19) -> Consultancy fee | B19: =IFERROR(IF(INDEX(Jan!$E:$E,MATCH(TRIM($A19),Jan!$B:$B,0))="","",INDEX(Jan!$E:$E,MATCH(TRIM($A19),Jan!$B:$B,0))),"") -> 0 | C19: =IFERROR(IF(INDEX('March-Feb'!$I:$I,MATCH($A19,'March-Feb'!$B:$B,0))="","",INDEX('March-Feb'!$I:$I,MATCH($A19,'March-Feb'!$B:$B,0))),"") -> 5914 | D19: =IFERROR(IF(INDEX('March-Feb'!$E:$E,MATCH($A19,'March-Feb'!$B:$B,0))="","",INDEX('March-Feb'!$E:$E,MATCH($A19,'March-Feb'!$B:$B,0))),"") -> 7575 | E19: =IFERROR(IF(INDEX('April-March'!$F:$F,MATCH($A19,'April-March'!$B:$B,0))="","",INDEX('April-March'!$F:$F,MATCH($A19,'April-March'!$B:$B,0))),"") -> 0 | F19: =IFERROR(IF(INDEX('May-April'!$F:$F,MATCH($A19,'May-April'!$B:$B,0))="","",INDEX('May-April'!$F:$F,MATCH($A19,'May-April'!$B:$B,0))),"") -> 0 | G19: =IF('Jun''26'!F19="","",'Jun''26'!F19) -> 0 | H19: =IFERROR(IF(INDEX('Jul''26'!$F:$F,MATCH($A19,'Jul''26'!$B:$B,0))="","",INDEX('Jul''26'!$F:$F,MATCH($A19,'Jul''26'!$B:$B,0))),"") -> 0 | I19: =SUM(B19:H19) -> 13489
... A66: =IF('Jun''26'!B66="","",'Jun''26'!B66) -> Total COGS | B66: =IFERROR(IF(INDEX(Jan!$E:$E,MATCH(TRIM($A66),Jan!$B:$B,0))="","",INDEX(Jan!$E:$E,MATCH(TRIM($A66),Jan!$B:$B,0))),"") -> 160435.18 | C66: =IFERROR(IF(INDEX('March-Feb'!$I:$I,MATCH($A66,'March-Feb'!$B:$B,0))="","",INDEX('March-Feb'!$I:$I,MATCH($A66,'March-Feb'!$B:$B,0))),"") -> 166233 | D66: =IFERROR(IF(INDEX('March-Feb'!$E:$E,MATCH($A66,'March-Feb'!$B:$B,0))="","",INDEX('March-Feb'!$E:$E,MATCH($A66,'March-Feb'!$B:$B,0))),"") -> 189430 | E66: =IFERROR(IF(INDEX('April-March'!$F:$F,MATCH($A66,'April-March'!$B:$B,0))="","",INDEX('April-March'!$F:$F,MATCH($A66,'April-March'!$B:$B,0))),"") -> 154650 | F66: =IFERROR(IF(INDEX('May-April'!$F:$F,MATCH($A66,'May-April'!$B:$B,0))="","",INDEX('May-April'!$F:$F,MATCH($A66,'May-April'!$B:$B,0))),"") -> 144550 | G66: =IF('Jun''26'!F66="","",'Jun''26'!F66) -> 148327 | H66: =IFERROR(IF(INDEX('Jul''26'!$F:$F,MATCH($A66,'Jul''26'!$B:$B,0))="","",INDEX('Jul''26'!$F:$F,MATCH($A66,'Jul''26'!$B:$B,0))),"") -> 152984 | I66: =SUM(B66:H66) -> 1116609.2
A67: =IF('Jun''26'!B67="","",'Jun''26'!B67) -> GM | B67: =Jan!E16 -> 66378.82 | C67: =IFERROR(IF(INDEX('March-Feb'!$I:$I,MATCH($A67,'March-Feb'!$B:$B,0))="","",INDEX('March-Feb'!$I:$I,MATCH($A67,'March-Feb'!$B:$B,0))),"") -> 61538 | D67: =IFERROR(IF(INDEX('March-Feb'!$E:$E,MATCH($A67,'March-Feb'!$B:$B,0))="","",INDEX('March-Feb'!$E:$E,MATCH($A67,'March-Feb'!$B:$B,0))),"") -> 31785 | E67: =IFERROR(IF(INDEX('April-March'!$F:$F,MATCH($A67,'April-March'!$B:$B,0))="","",INDEX('April-March'!$F:$F,MATCH($A67,'April-March'!$B:$B,0))),"") -> 40557 | F67: =IFERROR(IF(INDEX('May-April'!$F:$F,MATCH($A67,'May-April'!$B:$B,0))="","",INDEX('May-April'!$F:$F,MATCH($A67,'May-April'!$B:$B,0))),"") -> 65368 | G67: =IF('Jun''26'!F67="","",'Jun''26'!F67) -> 83983 | H67: =IFERROR(IF(INDEX('Jul''26'!$F:$F,MATCH($A67,'Jul''26'!$B:$B,0))="","",INDEX('Jul''26'!$F:$F,MATCH($A67,'Jul''26'!$B:$B,0))),"") -> 97689 | I67: =SUM(B67:H67) -> 447298.82
A68: =IF('Jun''26'!B68="","",'Jun''26'!B68) -> GM% | B68: =IFERROR(B$67/B$15,"") -> 0.29265751 | C68: =IFERROR(C$67/C$15,"") -> 0.27017487 | D68: =IFERROR(D$67/D$15,"") -> 0.14368375 | E68: =IFERROR(E$67/E$15,"") -> 0.20776407 | F68: =IFERROR(F$67/F$15,"") -> 0.31139778 | G68: =IFERROR(G$67/G$15,"") -> 0.36151108 | H68: =IFERROR(H$67/H$15,"") -> 0.38970846 | I68: =SUM(B68:H68) -> 1.9768975
A69: =IF('Jun''26'!B69="","",'Jun''26'!B69) -> SG&A | B69: =IFERROR(IF(INDEX(Jan!$E:$E,MATCH(TRIM($A69),Jan!$B:$B,0))="","",INDEX(Jan!$E:$E,MATCH(TRIM($A69),Jan!$B:$B,0))),"") | C69: =IFERROR(IF(INDEX('March-Feb'!$I:$I,MATCH($A69,'March-Feb'!$B:$B,0))="","",INDEX('March-Feb'!$I:$I,MATCH($A69,'March-Feb'!$B:$B,0))),"") | D69: =IFERROR(IF(INDEX('March-Feb'!$E:$E,MATCH($A69,'March-Feb'!$B:$B,0))="","",INDEX('March-Feb'!$E:$E,MATCH($A69,'March-Feb'!$B:$B,0))),"") | E69: =IFERROR(IF(INDEX('April-March'!$F:$F,MATCH($A69,'April-March'!$B:$B,0))="","",INDEX('April-March'!$F:$F,MATCH($A69,'April-March'!$B:$B,0))),"") | F69: =IFERROR(IF(INDEX('May-April'!$F:$F,MATCH($A69,'May-April'!$B:$B,0))="","",INDEX('May-April'!$F:$F,MATCH($A69,'May-April'!$B:$B,0))),"") | G69: =IF('Jun''26'!F69="","",'Jun''26'!F69) | H69: =IFERROR(IF(INDEX('Jul''26'!$F:$F,MATCH($A69,'Jul''26'!$B:$B,0))="","",INDEX('Jul''26'!$F:$F,MATCH($A69,'Jul''26'!$B:$B,0))),"") | I69: =SUM(B69:H69) -> 0
A70: =IF('Jun''26'!B70="","",'Jun''26'!B70) -> Selling Expenses | B70: =IFERROR(IF(INDEX(Jan!$E:$E,MATCH(TRIM($A70),Jan!$B:$B,0))="","",INDEX(Jan!$E:$E,MATCH(TRIM($A70),Jan!$B:$B,0))),"") -> 5200.478 | C70: =IFERROR(IF(INDEX('March-Feb'!$I:$I,MATCH($A70,'March-Feb'!$B:$B,0))="","",INDEX('March-Feb'!$I:$I,MATCH($A70,'March-Feb'!$B:$B,0))),"") -> 3273 | D70: =IFERROR(IF(INDEX('March-Feb'!$E:$E,MATCH($A70,'March-Feb'!$B:$B,0))="","",INDEX('March-Feb'!$E:$E,MATCH($A70,'March-Feb'!$B:$B,0))),"") -> 2839 | E70: =IFERROR(IF(INDEX('April-March'!$F:$F,MATCH($A70,'April-March'!$B:$B,0))="","",INDEX('April-March'!$F:$F,MATCH($A70,'April-March'!$B:$B,0))),"") -> 2109 | F70: =IFERROR(IF(INDEX('May-April'!$F:$F,MATCH($A70,'May-April'!$B:$B,0))="","",INDEX('May-April'!$F:$F,MATCH($A70,'May-April'!$B:$B,0))),"") -> 1407 | G70: =IF('Jun''26'!F70="","",'Jun''26'!F70) -> 6679 | H70: =IFERROR(IF(INDEX('Jul''26'!$F:$F,MATCH($A70,'Jul''26'!$B:$B,0))="","",INDEX('Jul''26'!$F:$F,MATCH($A70,'Jul''26'!$B:$B,0))),"") -> 3342 | I70: =SUM(B70:H70) -> 24849.478
A71: =IF('Jun''26'!B71="","",'Jun''26'!B71) -> Travel Expense | B71: =IFERROR(IF(INDEX(Jan!$E:$E,MATCH(TRIM($A71),Jan!$B:$B,0))="","",INDEX(Jan!$E:$E,MATCH(TRIM($A71),Jan!$B:$B,0))),"") -> 1498.83 | C71: =IFERROR(IF(INDEX('March-Feb'!$I:$I,MATCH($A71,'March-Feb'!$B:$B,0))="","",INDEX('March-Feb'!$I:$I,MATCH($A71,'March-Feb'!$B:$B,0))),"") | D71: =IFERROR(IF(INDEX('March-Feb'!$E:$E,MATCH($A71,'March-Feb'!$B:$B,0))="","",INDEX('March-Feb'!$E:$E,MATCH($A71,'March-Feb'!$B:$B,0))),"") | E71: =IFERROR(IF(INDEX('April-March'!$F:$F,MATCH($A71,'April-March'!$B:$B,0))="","",INDEX('April-March'!$F:$F,MATCH($A71,'April-March'!$B:$B,0))),"") | F71: =IFERROR(IF(INDEX('May-April'!$F:$F,MATCH($A71,'May-April'!$B:$B,0))="","",INDEX('May-April'!$F:$F,MATCH($A71,'May-April'!$B:$B,0))),"") | G71: =IF('Jun''26'!F71="","",'Jun''26'!F71) | H71: =IFERROR(IF(INDEX('Jul''26'!$F:$F,MATCH($A71,'Jul''26'!$B:$B,0))="","",INDEX('Jul''26'!$F:$F,MATCH($A71,'Jul''26'!$B:$B,0))),"") -> 0 | I71: =SUM(B71:H71) -> 1498.83
A72: =IF('Jun''26'!B72="","",'Jun''26'!B72) -> Cyber Security Insurance | B72: =IFERROR(IF(INDEX(Jan!$E:$E,MATCH(TRIM($A72),Jan!$B:$B,0))="","",INDEX(Jan!$E:$E,MATCH(TRIM($A72),Jan!$B:$B,0))),"") -> 0 | C72: =IFERROR(IF(INDEX('March-Feb'!$I:$I,MATCH($A72,'March-Feb'!$B:$B,0))="","",INDEX('March-Feb'!$I:$I,MATCH($A72,'March-Feb'!$B:$B,0))),"") | D72: =IFERROR(IF(INDEX('March-Feb'!$E:$E,MATCH($A72,'March-Feb'!$B:$B,0))="","",INDEX('March-Feb'!$E:$E,MATCH($A72,'March-Feb'!$B:$B,0))),"") | E72: =IFERROR(IF(INDEX('April-March'!$F:$F,MATCH($A72,'April-March'!$B:$B,0))="","",INDEX('April-March'!$F:$F,MATCH($A72,'April-March'!$B:$B,0))),"") | F72: =IFERROR(IF(INDEX('May-April'!$F:$F,MATCH($A72,'May-April'!$B:$B,0))="","",INDEX('May-April'!$F:$F,MATCH($A72,'May-April'!$B:$B,0))),"") | G72: =IF('Jun''26'!F72="","",'Jun''26'!F72) | H72: =IFERROR(IF(INDEX('Jul''26'!$F:$F,MATCH($A72,'Jul''26'!$B:$B,0))="","",INDEX('Jul''26'!$F:$F,MATCH($A72,'Jul''26'!$B:$B,0))),"") -> 0 | I72: =SUM(B72:H72) -> 0
A73: =IF('Jun''26'!B73="","",'Jun''26'!B73) -> Rewards and recognition | B73: =IFERROR(IF(INDEX(Jan!$E:$E,MATCH(TRIM($A73),Jan!$B:$B,0))="","",INDEX(Jan!$E:$E,MATCH(TRIM($A73),Jan!$B:$B,0))),"") -> 0 | C73: =IFERROR(IF(INDEX('March-Feb'!$I:$I,MATCH($A73,'March-Feb'!$B:$B,0))="","",INDEX('March-Feb'!$I:$I,MATCH($A73,'March-Feb'!$B:$B,0))),"") | D73: =IFERROR(IF(INDEX('March-Feb'!$E:$E,MATCH($A73,'March-Feb'!$B:$B,0))="","",INDEX('March-Feb'!$E:$E,MATCH($A73,'March-Feb'!$B:$B,0))),"") | E73: =IFERROR(IF(INDEX('April-March'!$F:$F,MATCH($A73,'April-March'!$B:$B,0))="","",INDEX('April-March'!$F:$F,MATCH($A73,'April-March'!$B:$B,0))),"") | F73: =IFERROR(IF(INDEX('May-April'!$F:$F,MATCH($A73,'May-April'!$B:$B,0))="","",INDEX('May-April'!$F:$F,MATCH($A73,'May-April'!$B:$B,0))),"") | G73: =IF('Jun''26'!F73="","",'Jun''26'!F73) -> 1314 | H73: =IFERROR(IF(INDEX('Jul''26'!$F:$F,MATCH($A73,'Jul''26'!$B:$B,0))="","",INDEX('Jul''26'!$F:$F,MATCH($A73,'Jul''26'!$B:$B,0))),"") -> -4 | I73: =SUM(B73:H73) -> 1310
A74: =IF('Jun''26'!B74="","",'Jun''26'!B74) -> Meals and Entertainment | B74: =IFERROR(IF(INDEX(Jan!$E:$E,MATCH(TRIM($A74),Jan!$B:$B,0))="","",INDEX(Jan!$E:$E,MATCH(TRIM($A74),Jan!$B:$B,0))),"") -> 605.17804 | C74: =IFERROR(IF(INDEX('March-Feb'!$I:$I,MATCH($A74,'March-Feb'!$B:$B,0))="","",INDEX('March-Feb'!$I:$I,MATCH($A74,'March-Feb'!$B:$B,0))),"") -> 1070 | D74: =IFERROR(IF(INDEX('March-Feb'!$E:$E,MATCH($A74,'March-Feb'!$B:$B,0))="","",INDEX('March-Feb'!$E:$E,MATCH($A74,'March-Feb'!$B:$B,0))),"") -> 152 | E74: =IFERROR(IF(INDEX('April-March'!$F:$F,MATCH($A74,'April-March'!$B:$B,0))="","",INDEX('April-March'!$F:$F,MATCH($A74,'April-March'!$B:$B,0))),"") -> 734 | F74: =IFERROR(IF(INDEX('May-April'!$F:$F,MATCH($A74,'May-April'!$B:$B,0))="","",INDEX('May-April'!$F:$F,MATCH($A74,'May-April'!$B:$B,0))),"") -> 318 | G74: =IF('Jun''26'!F74="","",'Jun''26'!F74) -> 3194 | H74: =IFERROR(IF(INDEX('Jul''26'!$F:$F,MATCH($A74,'Jul''26'!$B:$B,0))="","",INDEX('Jul''26'!$F:$F,MATCH($A74,'Jul''26'!$B:$B,0))),"") -> 1005 | I74: =SUM(B74:H74) -> 7078.178
A75: =IF('Jun''26'!B75="","",'Jun''26'!B75) -> VISA charges | B75: =IFERROR(IF(INDEX(Jan!$E:$E,MATCH(TRIM($A75),Jan!$B:$B,0))="","",INDEX(Jan!$E:$E,MATCH(TRIM($A75),Jan!$B:$B,0))),"") -> 0 | C75: =IFERROR(IF(INDEX('March-Feb'!$I:$I,MATCH($A75,'March-Feb'!$B:$B,0))="","",INDEX('March-Feb'!$I:$I,MATCH($A75,'March-Feb'!$B:$B,0))),"") | D75: =IFERROR(IF(INDEX('March-Feb'!$E:$E,MATCH($A75,'March-Feb'!$B:$B,0))="","",INDEX('March-Feb'!$E:$E,MATCH($A75,'March-Feb'!$B:$B,0))),"") | E75: =IFERROR(IF(INDEX('April-March'!$F:$F,MATCH($A75,'April-March'!$B:$B,0))="","",INDEX('April-March'!$F:$F,MATCH($A75,'April-March'!$B:$B,0))),"") | F75: =IFERROR(IF(INDEX('May-April'!$F:$F,MATCH($A75,'May-April'!$B:$B,0))="","",INDEX('May-April'!$F:$F,MATCH($A75,'May-April'!$B:$B,0))),"") | G75: =IF('Jun''26'!F75="","",'Jun''26'!F75) | H75: =IFERROR(IF(INDEX('Jul''26'!$F:$F,MATCH($A75,'Jul''26'!$B:$B,0))="","",INDEX('Jul''26'!$F:$F,MATCH($A75,'Jul''26'!$B:$B,0))),"") -> 0 | I75: =SUM(B75:H75) -> 0
A76: =IF('Jun''26'!B76="","",'Jun''26'!B76) -> Conference & Events | B76: =IFERROR(IF(INDEX(Jan!$E:$E,MATCH(TRIM($A76),Jan!$B:$B,0))="","",INDEX(Jan!$E:$E,MATCH(TRIM($A76),Jan!$B:$B,0))),"") | C76: =IFERROR(IF(INDEX('March-Feb'!$I:$I,MATCH($A76,'March-Feb'!$B:$B,0))="","",INDEX('March-Feb'!$I:$I,MATCH($A76,'March-Feb'!$B:$B,0))),"") | D76: =IFERROR(IF(INDEX('March-Feb'!$E:$E,MATCH($A76,'March-Feb'!$B:$B,0))="","",INDEX('March-Feb'!$E:$E,MATCH($A76,'March-Feb'!$B:$B,0))),"") | E76: =IFERROR(IF(INDEX('April-March'!$F:$F,MATCH($A76,'April-March'!$B:$B,0))="","",INDEX('April-March'!$F:$F,MATCH($A76,'April-March'!$B:$B,0))),"") | F76: =IFERROR(IF(INDEX('May-April'!$F:$F,MATCH($A76,'May-April'!$B:$B,0))="","",INDEX('May-April'!$F:$F,MATCH($A76,'May-April'!$B:$B,0))),"") | G76: =IF('Jun''26'!F76="","",'Jun''26'!F76) | H76: =IFERROR(IF(INDEX('Jul''26'!$F:$F,MATCH($A76,'Jul''26'!$B:$B,0))="","",INDEX('Jul''26'!$F:$F,MATCH($A76,'Jul''26'!$B:$B,0))),"") -> 0 | I76: =SUM(B76:H76) -> 0
A77: =IF('Jun''26'!B77="","",'Jun''26'!B77) -> Advertisement and marketing | B77: =IFERROR(IF(INDEX(Jan!$E:$E,MATCH(TRIM($A77),Jan!$B:$B,0))="","",INDEX(Jan!$E:$E,MATCH(TRIM($A77),Jan!$B:$B,0))),"") -> 0 | C77: =IFERROR(IF(INDEX('March-Feb'!$I:$I,MATCH($A77,'March-Feb'!$B:$B,0))="","",INDEX('March-Feb'!$I:$I,MATCH($A77,'March-Feb'!$B:$B,0))),"") | D77: =IFERROR(IF(INDEX('March-Feb'!$E:$E,MATCH($A77,'March-Feb'!$B:$B,0))="","",INDEX('March-Feb'!$E:$E,MATCH($A77,'March-Feb'!$B:$B,0))),"") | E77: =IFERROR(IF(INDEX('April-March'!$F:$F,MATCH($A77,'April-March'!$B:$B,0))="","",INDEX('April-March'!$F:$F,MATCH($A77,'April-March'!$B:$B,0))),"") | F77: =IFERROR(IF(INDEX('May-April'!$F:$F,MATCH($A77,'May-April'!$B:$B,0))="","",INDEX('May-April'!$F:$F,MATCH($A77,'May-April'!$B:$B,0))),"") | G77: =IF('Jun''26'!F77="","",'Jun''26'!F77) | H77: =IFERROR(IF(INDEX('Jul''26'!$F:$F,MATCH($A77,'Jul''26'!$B:$B,0))="","",INDEX('Jul''26'!$F:$F,MATCH($A77,'Jul''26'!$B:$B,0))),"") -> 0 | I77: =SUM(B77:H77) -> 0
A78: =IF('Jun''26'!B78="","",'Jun''26'!B78) -> Sales and marketing | B78: =IFERROR(IF(INDEX(Jan!$E:$E,MATCH(TRIM($A78),Jan!$B:$B,0))="","",INDEX(Jan!$E:$E,MATCH(TRIM($A78),Jan!$B:$B,0))),"") -> 1361.97 | C78: =IFERROR(IF(INDEX('March-Feb'!$I:$I,MATCH($A78,'March-Feb'!$B:$B,0))="","",INDEX('March-Feb'!$I:$I,MATCH($A78,'March-Feb'!$B:$B,0))),"") -> 1188 | D78: =IFERROR(IF(INDEX('March-Feb'!$E:$E,MATCH($A78,'March-Feb'!$B:$B,0))="","",INDEX('March-Feb'!$E:$E,MATCH($A78,'March-Feb'!$B:$B,0))),"") -> 1211 | E78: =IFERROR(IF(INDEX('April-March'!$F:$F,MATCH($A78,'April-March'!$B:$B,0))="","",INDEX('April-March'!$F:$F,MATCH($A78,'April-March'!$B:$B,0))),"") -> 128 | F78: =IFERROR(IF(INDEX('May-April'!$F:$F,MATCH($A78,'May-April'!$B:$B,0))="","",INDEX('May-April'!$F:$F,MATCH($A78,'May-April'!$B:$B,0))),"") -> 0 | G78: =IF('Jun''26'!F78="","",'Jun''26'!F78) -> 1083 | H78: =IFERROR(IF(INDEX('Jul''26'!$F:$F,MATCH($A78,'Jul''26'!$B:$B,0))="","",INDEX('Jul''26'!$F:$F,MATCH($A78,'Jul''26'!$B:$B,0))),"") -> 1346 | I78: =SUM(B78:H78) -> 6317.97
A79: =IF('Jun''26'!B79="","",'Jun''26'!B79) -> Business Promotion | B79: =IFERROR(IF(INDEX(Jan!$E:$E,MATCH(TRIM($A79),Jan!$B:$B,0))="","",INDEX(Jan!$E:$E,MATCH(TRIM($A79),Jan!$B:$B,0))),"") -> 0 | C79: =IFERROR(IF(INDEX('March-Feb'!$I:$I,MATCH($A79,'March-Feb'!$B:$B,0))="","",INDEX('March-Feb'!$I:$I,MATCH($A79,'March-Feb'!$B:$B,0))),"") | D79: =IFERROR(IF(INDEX('March-Feb'!$E:$E,MATCH($A79,'March-Feb'!$B:$B,0))="","",INDEX('March-Feb'!$E:$E,MATCH($A79,'March-Feb'!$B:$B,0))),"") | E79: =IFERROR(IF(INDEX('April-March'!$F:$F,MATCH($A79,'April-March'!$B:$B,0))="","",INDEX('April-March'!$F:$F,MATCH($A79,'April-March'!$B:$B,0))),"") | F79: =IFERROR(IF(INDEX('May-April'!$F:$F,MATCH($A79,'May-April'!$B:$B,0))="","",INDEX('May-April'!$F:$F,MATCH($A79,'May-April'!$B:$B,0))),"") | G79: =IF('Jun''26'!F79="","",'Jun''26'!F79) | H79: =IFERROR(IF(INDEX('Jul''26'!$F:$F,MATCH($A79,'Jul''26'!$B:$B,0))="","",INDEX('Jul''26'!$F:$F,MATCH($A79,'Jul''26'!$B:$B,0))),"") -> 0 | I79: =SUM(B79:H79) -> 0
A80: =IF('Jun''26'!B80="","",'Jun''26'!B80) -> S&M Salaries | B80: =IFERROR(IF(INDEX(Jan!$E:$E,MATCH(TRIM($A80),Jan!$B:$B,0))="","",INDEX(Jan!$E:$E,MATCH(TRIM($A80),Jan!$B:$B,0))),"") -> 1153.75 | C80: =IFERROR(IF(INDEX('March-Feb'!$I:$I,MATCH($A80,'March-Feb'!$B:$B,0))="","",INDEX('March-Feb'!$I:$I,MATCH($A80,'March-Feb'!$B:$B,0))),"") -> 1015 | D80: =IFERROR(IF(INDEX('March-Feb'!$E:$E,MATCH($A80,'March-Feb'!$B:$B,0))="","",INDEX('March-Feb'!$E:$E,MATCH($A80,'March-Feb'!$B:$B,0))),"") -> 1476 | E80: =IFERROR(IF(INDEX('April-March'!$F:$F,MATCH($A80,'April-March'!$B:$B,0))="","",INDEX('April-March'!$F:$F,MATCH($A80,'April-March'!$B:$B,0))),"") -> 1247 | F80: =IFERROR(IF(INDEX('May-April'!$F:$F,MATCH($A80,'May-April'!$B:$B,0))="","",INDEX('May-April'!$F:$F,MATCH($A80,'May-April'!$B:$B,0))),"") -> 1093 | G80: =IF('Jun''26'!F80="","",'Jun''26'!F80) -> 1090 | H80: =IFERROR(IF(INDEX('Jul''26'!$F:$F,MATCH($A80,'Jul''26'!$B:$B,0))="","",INDEX('Jul''26'!$F:$F,MATCH($A80,'Jul''26'!$B:$B,0))),"") -> 997 | I80: =SUM(B80:H80) -> 8071.75
... A98: =IF('Jun''26'!B98="","",'Jun''26'!B98) -> Coder | B98: =IFERROR(IF(INDEX(Jan!$E:$E,MATCH(TRIM($A98),Jan!$B:$B,0))="","",INDEX(Jan!$E:$E,MATCH(TRIM($A98),Jan!$B:$B,0))),"") -> 0 | C98: =IFERROR(IF(INDEX('March-Feb'!$I:$I,MATCH($A98,'March-Feb'!$B:$B,0))="","",INDEX('March-Feb'!$I:$I,MATCH($A98,'March-Feb'!$B:$B,0))),"") | D98: =IFERROR(IF(INDEX('March-Feb'!$E:$E,MATCH($A98,'March-Feb'!$B:$B,0))="","",INDEX('March-Feb'!$E:$E,MATCH($A98,'March-Feb'!$B:$B,0))),"") | E98: =IFERROR(IF(INDEX('April-March'!$F:$F,MATCH($A98,'April-March'!$B:$B,0))="","",INDEX('April-March'!$F:$F,MATCH($A98,'April-March'!$B:$B,0))),"") | F98: =IFERROR(IF(INDEX('May-April'!$F:$F,MATCH($A98,'May-April'!$B:$B,0))="","",INDEX('May-April'!$F:$F,MATCH($A98,'May-April'!$B:$B,0))),"") | G98: =IF('Jun''26'!F98="","",'Jun''26'!F98) | H98: =IFERROR(IF(INDEX('Jul''26'!$F:$F,MATCH($A98,'Jul''26'!$B:$B,0))="","",INDEX('Jul''26'!$F:$F,MATCH($A98,'Jul''26'!$B:$B,0))),"") -> 0 | I98: =SUM(B98:H98) -> 0
A99: =IF('Jun''26'!B99="","",'Jun''26'!B99) -> Gen & Admin Expenses | B99: =Jan!E26 -> 16548.773 | C99: =IFERROR(IF(INDEX('March-Feb'!$I:$I,MATCH($A99,'March-Feb'!$B:$B,0))="","",INDEX('March-Feb'!$I:$I,MATCH($A99,'March-Feb'!$B:$B,0))),"") -> 9435 | D99: =IFERROR(IF(INDEX('March-Feb'!$E:$E,MATCH($A99,'March-Feb'!$B:$B,0))="","",INDEX('March-Feb'!$E:$E,MATCH($A99,'March-Feb'!$B:$B,0))),"") -> 15990 | E99: =IFERROR(IF(INDEX('April-March'!$F:$F,MATCH($A99,'April-March'!$B:$B,0))="","",INDEX('April-March'!$F:$F,MATCH($A99,'April-March'!$B:$B,0))),"") -> 9176 | F99: =IFERROR(IF(INDEX('May-April'!$F:$F,MATCH($A99,'May-April'!$B:$B,0))="","",INDEX('May-April'!$F:$F,MATCH($A99,'May-April'!$B:$B,0))),"") -> 10040 | G99: =IF('Jun''26'!F99="","",'Jun''26'!F99) -> 13142 | H99: =IFERROR(IF(INDEX('Jul''26'!$F:$F,MATCH($A99,'Jul''26'!$B:$B,0))="","",INDEX('Jul''26'!$F:$F,MATCH($A99,'Jul''26'!$B:$B,0))),"") -> 19905 | I99: =SUM(B99:H99) -> 94236.773
A100: =IF('Jun''26'!B100="","",'Jun''26'!B100) -> Consultancy Fees | B100: =IFERROR(IF(INDEX(Jan!$E:$E,MATCH(TRIM($A100),Jan!$B:$B,0))="","",INDEX(Jan!$E:$E,MATCH(TRIM($A100),Jan!$B:$B,0))),"") -> 6383.42 | C100: =IFERROR(IF(INDEX('March-Feb'!$I:$I,MATCH($A100,'March-Feb'!$B:$B,0))="","",INDEX('March-Feb'!$I:$I,MATCH($A100,'March-Feb'!$B:$B,0))),"") | D100: =IFERROR(IF(INDEX('March-Feb'!$E:$E,MATCH($A100,'March-Feb'!$B:$B,0))="","",INDEX('March-Feb'!$E:$E,MATCH($A100,'March-Feb'!$B:$B,0))),"") | E100: =IFERROR(IF(INDEX('April-March'!$F:$F,MATCH($A100,'April-March'!$B:$B,0))="","",INDEX('April-March'!$F:$F,MATCH($A100,'April-March'!$B:$B,0))),"") | F100: =IFERROR(IF(INDEX('May-April'!$F:$F,MATCH($A100,'May-April'!$B:$B,0))="","",INDEX('May-April'!$F:$F,MATCH($A100,'May-April'!$B:$B,0))),"") | G100: =IF('Jun''26'!F100="","",'Jun''26'!F100) | H100: =IFERROR(IF(INDEX('Jul''26'!$F:$F,MATCH($A100,'Jul''26'!$B:$B,0))="","",INDEX('Jul''26'!$F:$F,MATCH($A100,'Jul''26'!$B:$B,0))),"") -> 0 | I100: =SUM(B100:H100) -> 6383.42
A101: =IF('Jun''26'!B101="","",'Jun''26'!B101) -> Comission Paid-Scinet Inc | B101: =IFERROR(IF(INDEX(Jan!$E:$E,MATCH(TRIM($A101),Jan!$B:$B,0))="","",INDEX(Jan!$E:$E,MATCH(TRIM($A101),Jan!$B:$B,0))),"") -> 0 | C101: =IFERROR(IF(INDEX('March-Feb'!$I:$I,MATCH($A101,'March-Feb'!$B:$B,0))="","",INDEX('March-Feb'!$I:$I,MATCH($A101,'March-Feb'!$B:$B,0))),"") | D101: =IFERROR(IF(INDEX('March-Feb'!$E:$E,MATCH($A101,'March-Feb'!$B:$B,0))="","",INDEX('March-Feb'!$E:$E,MATCH($A101,'March-Feb'!$B:$B,0))),"") | E101: =IFERROR(IF(INDEX('April-March'!$F:$F,MATCH($A101,'April-March'!$B:$B,0))="","",INDEX('April-March'!$F:$F,MATCH($A101,'April-March'!$B:$B,0))),"") | F101: =IFERROR(IF(INDEX('May-April'!$F:$F,MATCH($A101,'May-April'!$B:$B,0))="","",INDEX('May-April'!$F:$F,MATCH($A101,'May-April'!$B:$B,0))),"") | G101: =IF('Jun''26'!F101="","",'Jun''26'!F101) | H101: =IFERROR(IF(INDEX('Jul''26'!$F:$F,MATCH($A101,'Jul''26'!$B:$B,0))="","",INDEX('Jul''26'!$F:$F,MATCH($A101,'Jul''26'!$B:$B,0))),"") -> 0 | I101: =SUM(B101:H101) -> 0
A102: =IF('Jun''26'!B102="","",'Jun''26'!B102) -> Leadership engagemnet | B102: =IFERROR(IF(INDEX(Jan!$E:$E,MATCH(TRIM($A102),Jan!$B:$B,0))="","",INDEX(Jan!$E:$E,MATCH(TRIM($A102),Jan!$B:$B,0))),"") -> 0 | C102: =IFERROR(IF(INDEX('March-Feb'!$I:$I,MATCH($A102,'March-Feb'!$B:$B,0))="","",INDEX('March-Feb'!$I:$I,MATCH($A102,'March-Feb'!$B:$B,0))),"") | D102: =IFERROR(IF(INDEX('March-Feb'!$E:$E,MATCH($A102,'March-Feb'!$B:$B,0))="","",INDEX('March-Feb'!$E:$E,MATCH($A102,'March-Feb'!$B:$B,0))),"") | E102: =IFERROR(IF(INDEX('April-March'!$F:$F,MATCH($A102,'April-March'!$B:$B,0))="","",INDEX('April-March'!$F:$F,MATCH($A102,'April-March'!$B:$B,0))),"") | F102: =IFERROR(IF(INDEX('May-April'!$F:$F,MATCH($A102,'May-April'!$B:$B,0))="","",INDEX('May-April'!$F:$F,MATCH($A102,'May-April'!$B:$B,0))),"") | G102: =IF('Jun''26'!F102="","",'Jun''26'!F102) | H102: =IFERROR(IF(INDEX('Jul''26'!$F:$F,MATCH($A102,'Jul''26'!$B:$B,0))="","",INDEX('Jul''26'!$F:$F,MATCH($A102,'Jul''26'!$B:$B,0))),"") -> 0 | I102: =SUM(B102:H102) -> 0
A103: =IF('Jun''26'!B103="","",'Jun''26'!B103) -> Charitable Donations | B103: =IFERROR(IF(INDEX(Jan!$E:$E,MATCH(TRIM($A103),Jan!$B:$B,0))="","",INDEX(Jan!$E:$E,MATCH(TRIM($A103),Jan!$B:$B,0))),"") -> 0 | C103: =IFERROR(IF(INDEX('March-Feb'!$I:$I,MATCH($A103,'March-Feb'!$B:$B,0))="","",INDEX('March-Feb'!$I:$I,MATCH($A103,'March-Feb'!$B:$B,0))),"") | D103: =IFERROR(IF(INDEX('March-Feb'!$E:$E,MATCH($A103,'March-Feb'!$B:$B,0))="","",INDEX('March-Feb'!$E:$E,MATCH($A103,'March-Feb'!$B:$B,0))),"") | E103: =IFERROR(IF(INDEX('April-March'!$F:$F,MATCH($A103,'April-March'!$B:$B,0))="","",INDEX('April-March'!$F:$F,MATCH($A103,'April-March'!$B:$B,0))),"") | F103: =IFERROR(IF(INDEX('May-April'!$F:$F,MATCH($A103,'May-April'!$B:$B,0))="","",INDEX('May-April'!$F:$F,MATCH($A103,'May-April'!$B:$B,0))),"") | G103: =IF('Jun''26'!F103="","",'Jun''26'!F103) | H103: =IFERROR(IF(INDEX('Jul''26'!$F:$F,MATCH($A103,'Jul''26'!$B:$B,0))="","",INDEX('Jul''26'!$F:$F,MATCH($A103,'Jul''26'!$B:$B,0))),"") -> 0 | I103: =SUM(B103:H103) -> 0
A104: =IF('Jun''26'!B104="","",'Jun''26'!B104) -> Fuel/Mileage Expenses | B104: =IFERROR(IF(INDEX(Jan!$E:$E,MATCH(TRIM($A104),Jan!$B:$B,0))="","",INDEX(Jan!$E:$E,MATCH(TRIM($A104),Jan!$B:$B,0))),"") -> 132.06 | C104: =IFERROR(IF(INDEX('March-Feb'!$I:$I,MATCH($A104,'March-Feb'!$B:$B,0))="","",INDEX('March-Feb'!$I:$I,MATCH($A104,'March-Feb'!$B:$B,0))),"") -> 125 | D104: =IFERROR(IF(INDEX('March-Feb'!$E:$E,MATCH($A104,'March-Feb'!$B:$B,0))="","",INDEX('March-Feb'!$E:$E,MATCH($A104,'March-Feb'!$B:$B,0))),"") -> 97 | E104: =IFERROR(IF(INDEX('April-March'!$F:$F,MATCH($A104,'April-March'!$B:$B,0))="","",INDEX('April-March'!$F:$F,MATCH($A104,'April-March'!$B:$B,0))),"") -> 89 | F104: =IFERROR(IF(INDEX('May-April'!$F:$F,MATCH($A104,'May-April'!$B:$B,0))="","",INDEX('May-April'!$F:$F,MATCH($A104,'May-April'!$B:$B,0))),"") -> 0 | G104: =IF('Jun''26'!F104="","",'Jun''26'!F104) -> 0 | H104: =IFERROR(IF(INDEX('Jul''26'!$F:$F,MATCH($A104,'Jul''26'!$B:$B,0))="","",INDEX('Jul''26'!$F:$F,MATCH($A104,'Jul''26'!$B:$B,0))),"") -> 157 | I104: =SUM(B104:H104) -> 600.06
A105: =IF('Jun''26'!B105="","",'Jun''26'!B105) -> Payroll Processing Fees | B105: =IFERROR(IF(INDEX(Jan!$E:$E,MATCH(TRIM($A105),Jan!$B:$B,0))="","",INDEX(Jan!$E:$E,MATCH(TRIM($A105),Jan!$B:$B,0))),"") -> 962.65 | C105: =IFERROR(IF(INDEX('March-Feb'!$I:$I,MATCH($A105,'March-Feb'!$B:$B,0))="","",INDEX('March-Feb'!$I:$I,MATCH($A105,'March-Feb'!$B:$B,0))),"") -> 468 | D105: =IFERROR(IF(INDEX('March-Feb'!$E:$E,MATCH($A105,'March-Feb'!$B:$B,0))="","",INDEX('March-Feb'!$E:$E,MATCH($A105,'March-Feb'!$B:$B,0))),"") -> 608 | E105: =IFERROR(IF(INDEX('April-March'!$F:$F,MATCH($A105,'April-March'!$B:$B,0))="","",INDEX('April-March'!$F:$F,MATCH($A105,'April-March'!$B:$B,0))),"") -> 523 | F105: =IFERROR(IF(INDEX('May-April'!$F:$F,MATCH($A105,'May-April'!$B:$B,0))="","",INDEX('May-April'!$F:$F,MATCH($A105,'May-April'!$B:$B,0))),"") -> 537 | G105: =IF('Jun''26'!F105="","",'Jun''26'!F105) -> 528 | H105: =IFERROR(IF(INDEX('Jul''26'!$F:$F,MATCH($A105,'Jul''26'!$B:$B,0))="","",INDEX('Jul''26'!$F:$F,MATCH($A105,'Jul''26'!$B:$B,0))),"") -> 933 | I105: =SUM(B105:H105) -> 4559.65
A106: =IF('Jun''26'!B106="","",'Jun''26'!B106) -> Parking | B106: =IFERROR(IF(INDEX(Jan!$E:$E,MATCH(TRIM($A106),Jan!$B:$B,0))="","",INDEX(Jan!$E:$E,MATCH(TRIM($A106),Jan!$B:$B,0))),"") -> 0 | C106: =IFERROR(IF(INDEX('March-Feb'!$I:$I,MATCH($A106,'March-Feb'!$B:$B,0))="","",INDEX('March-Feb'!$I:$I,MATCH($A106,'March-Feb'!$B:$B,0))),"") | D106: =IFERROR(IF(INDEX('March-Feb'!$E:$E,MATCH($A106,'March-Feb'!$B:$B,0))="","",INDEX('March-Feb'!$E:$E,MATCH($A106,'March-Feb'!$B:$B,0))),"") | E106: =IFERROR(IF(INDEX('April-March'!$F:$F,MATCH($A106,'April-March'!$B:$B,0))="","",INDEX('April-March'!$F:$F,MATCH($A106,'April-March'!$B:$B,0))),"") | F106: =IFERROR(IF(INDEX('May-April'!$F:$F,MATCH($A106,'May-April'!$B:$B,0))="","",INDEX('May-April'!$F:$F,MATCH($A106,'May-April'!$B:$B,0))),"") | G106: =IF('Jun''26'!F106="","",'Jun''26'!F106) | H106: =IFERROR(IF(INDEX('Jul''26'!$F:$F,MATCH($A106,'Jul''26'!$B:$B,0))="","",INDEX('Jul''26'!$F:$F,MATCH($A106,'Jul''26'!$B:$B,0))),"") -> 58 | I106: =SUM(B106:H106) -> 58
...

Sheet Jul'26
B2: iMagnum US | C2: Period: July 2026 | H2: Period: June 2026
B3: FTM_CurrentYear_CV_SPL | E3: ( USD in Whole Number ) | J3: ( USD in Whole Number )
B6: particulars | C6: iMagnum India | D6: iMagnum US | E6: Elimination-iMagnum Segment | F6: Total | G6: iMagnum India | H6: iMagnum US | I6: Elimination-iMagnum Segment | J6: Total
B7: Service Income
B8: Sales | C8: 169130 | D8: 250110 | E8: -168568 | F8: 250672 | G8: 163489 | H8: 226261 | I8: -157139 | J8: 232611
B9: Sales | C9: 168858 | D9: 250110 | E9: -168568 | F9: 250400 | G9: 157186 | H9: 225967 | I9: -157139 | J9: 226014
B10: Other Charges | C10: 0 | D10: 0 | E10: 0 | F10: 0 | G10: 0 | H10: 0 | I10: 0 | J10: 0
B11: Buyout | C11: 224 | E11: 0 | F11: 224 | I11: 0 | J11: 0
B12: General Income | C12: 16 | D12: 0 | E12: 0 | F12: 16 | G12: 0 | H12: 294 | I12: 0 | J12: 294
B13: Interest Income | C13: 54 | E13: 0 | F13: 54 | G13: -1 | I13: 0 | J13: -1
B14: Governments Grant Income | C14: -21 | E14: 0 | F14: -21 | G14: 6304 | I14: 0 | J14: 6304
B15: Total Revenue | C15: 169130 | D15: 250110 | E15: -168568 | F15: 250672 | G15: 163489 | H15: 226261 | I15: -157139 | J15: 232611
B16: Overall Operational cost
B17: Manpower | C17: 100703 | D17: 168568 | E17: -168568 | F17: 100703 | G17: 94790 | H17: 157139 | I17: -157139 | J17: 94790
B18: India Cost | E18: 0 | F18: 0 | I18: 0 | J18: 0
B19: Consultancy fee | D19: 0 | E19: 0 | F19: 0 | H19: 0 | I19: 0 | J19: 0
B20: Operation salaries | C20: 64832 | E20: 0 | F20: 64832 | G20: 60587 | I20: 0 | J20: 60587
B21: Ops Support Salaries | C21: 33513 | E21: 0 | F21: 33513 | G21: 33990 | I21: 0 | J21: 33990
B22: Contract employee salaries | C22: 211 | D22: 168568 | E22: -168568 | F22: 211 | G22: 213 | H22: 157139 | I22: -157139 | J22: 213
B23: Coding charges | C23: 2147 | E23: 0 | F23: 2147 | G23: 0 | I23: 0 | J23: 0
B24: Employee statutory expenses | C24: 11693 | E24: 0 | F24: 11693 | G24: 11260 | I24: 0 | J24: 11260
B25: Employee ESI | E25: 0 | F25: 0 | I25: 0 | J25: 0
B26: EPF Admin Charges | C26: 413 | E26: 0 | F26: 413 | G26: 396 | I26: 0 | J26: 396
B27: Employee PF | C27: 10249 | E27: 0 | F27: 10249 | G27: 9833 | I27: 0 | J27: 9833
B28: Employer ESI | C28: 341 | E28: 0 | F28: 341 | G28: 381 | I28: 0 | J28: 381
B29: Employer PF | E29: 0 | F29: 0 | I29: 0 | J29: 0
B30: Professional tax | C30: 690 | E30: 0 | F30: 690 | G30: 651 | I30: 0 | J30: 651
B31: Interest on TDS | C31: 0 | E31: 0 | F31: 0 | G31: 0 | I31: 0 | J31: 0
B32: Interest on employee statutory dues | E32: 0 | F32: 0 | I32: 0 | J32: 0
B33: Interest on Advance Tax | C33: 0 | E33: 0 | F33: 0 | G33: 0 | I33: 0 | J33: 0
B34: Facility Cost | C34: 15220 | D34: 3125 | E34: 0 | F34: 18345 | G34: 15275 | H34: 0 | I34: 0 | J34: 15275
B35: Electricity | E35: 0 | F35: 0 | I35: 0 | J35: 0
B36: Electricity Expense | C36: 4842 | E36: 0 | F36: 4842 | G36: 3476 | I36: 0 | J36: 3476
B37: Computer maintenance | E37: 0 | F37: 0 | I37: 0 | J37: 0
B38: Janani Property Maintenance Charges | C38: 317 | E38: 0 | F38: 317 | G38: 727 | I38: 0 | J38: 727
B39: Janani Property Rental Charges | C39: 1834 | E39: 0 | F39: 1834 | G39: 4210 | I39: 0 | J39: 4210
B40: Laptop Rental Charges | C40: 2148 | E40: 0 | F40: 2148 | G40: 2049 | I40: 0 | J40: 2049
B41: Thiruttani rental charges | C41: 276 | E41: 0 | F41: 276 | G41: 293 | I41: 0 | J41: 293
B42: Max Office rental charges | C42: 4209 | E42: 0 | F42: 4209 | G42: 4255 | I42: 0 | J42: 4255
B43: Rent Expense | C43: 263 | D43: 3125 | E43: 0 | F43: 3388 | G43: 266 | H43: 0 | I43: 0 | J43: 266
...

Sheet Jun'26
B2: iMagnum US | C2: Period: June 2026 | G2: Period: May 2026
B3: FTM_CurrentYear_CV_SPL | E3: ( USD in Whole Number ) | I3: ( USD in Whole Number )
B6: particulars | C6: iMagnum India | D6: iMagnum US | E6: Elimination-iMagnum Segment | F6: Total | G6: iMagnum India | H6: iMagnum US | I6: Elimination-iMagnum Segment | J6: Total | K6: Variance
B7: Service Income
B8: Sales | C8: 163489 | D8: 225961 | E8: -157139 | F8: 232311 | G8: 158437 | H8: 209920 | I8: -158439 | J8: 209918 | K8: =F8-J8 -> 22393
B9: Sales | C9: 157186 | D9: 225667 | E9: -157139 | F9: 225714 | G9: 158439 | H9: 209920 | I9: -158439 | J9: 209920 | K9: =F9-J9 -> 15794
B10: Other Charges | C10: 0 | D10: 0 | F10: 0 | G10: 0 | H10: 0 | I10: 0 | J10: 0 | K10: =F10-J10 -> 0
B11: Buyout | I11: 0 | J11: 0
B12: General Income | C12: 0 | D12: 294 | F12: 294 | G12: 0 | H12: 0 | I12: 0 | J12: 0 | K12: =F12-J12 -> 294
B13: Interest Income | C13: -1 | F13: -1 | G13: -2 | I13: 0 | J13: -2 | K13: =F13-J13 -> 1
B14: Governments Grant Income | C14: 6304 | F14: 6304 | I14: 0 | J14: 0 | K14: =F14-J14 -> 6304
B15: Total Revenue | C15: 163489 | D15: 225961 | E15: -157139 | F15: 232311 | G15: 158437 | H15: 209920 | I15: -158439 | J15: 209918 | K15: =F15-J15 -> 22393
B16: Overall Operational cost
B17: Manpower | C17: 94790 | D17: 157139 | E17: -157139 | F17: 94790 | G17: 92642 | H17: 158280 | I17: -158439 | J17: 92483 | K17: =F17-J17 -> 2307
B18: India Cost | I18: 0 | J18: 0
B19: Consultancy fee | D19: 0 | F19: 0 | H19: 0 | I19: 0 | J19: 0 | K19: =F19-J19 -> 0
B20: Operation salaries | C20: 60587 | F20: 60587 | G20: 57391 | I20: 0 | J20: 57391 | K20: =F20-J20 -> 3196
B21: Ops Support Salaries | C21: 33990 | F21: 33990 | G21: 35040 | I21: 0 | J21: 35040 | K21: =F21-J21 -> -1050
B22: Contract employee salaries | C22: 213 | D22: 157139 | E22: -157139 | F22: 213 | G22: 212 | H22: 158280 | I22: -158439 | J22: 53 | K22: =F22-J22 -> 160
B23: Coding charges | C23: 0 | F23: 0 | G23: -1 | I23: 0 | J23: -1 | K23: =F23-J23 -> 1
B24: Employee statutory expenses | C24: 11261 | F24: 11261 | G24: 10954 | I24: 0 | J24: 10954 | K24: =F24-J24 -> 307
B25: Employee ESI | I25: 0 | J25: 0
B26: EPF Admin Charges | C26: 396 | F26: 396 | G26: 369 | I26: 0 | J26: 369 | K26: =F26-J26 -> 27
B27: Employee PF | C27: 9833 | F27: 9833 | G27: 9488 | I27: 0 | J27: 9488 | K27: =F27-J27 -> 345
B28: Employer ESI | C28: 381 | F28: 381 | G28: 365 | I28: 0 | J28: 365 | K28: =F28-J28 -> 16
B29: Employer PF | I29: 0 | J29: 0
B30: Professional tax | C30: 651 | F30: 651 | G30: 597 | I30: 0 | J30: 597 | K30: =F30-J30 -> 54
B31: Interest on TDS | C31: 0 | F31: 0 | G31: 8 | I31: 0 | J31: 8 | K31: =F31-J31 -> -8
B32: Interest on employee statutory dues | I32: 0 | J32: 0
B33: Interest on Advance Tax | C33: 0 | F33: 0 | G33: 127 | I33: 0 | J33: 127 | K33: =F33-J33 -> -127
B34: Facility Cost | C34: 15275 | D34: 0 | F34: 15275 | G34: 14229 | H34: 3000 | I34: 0 | J34: 17229 | K34: =F34-J34 -> -1954
B35: Electricity | I35: 0 | J35: 0
B36: Electricity Expense | C36: 3476 | F36: 3476 | G36: 2663 | I36: 0 | J36: 2663 | K36: =F36-J36 -> 813
B37: Computer maintenance | I37: 0 | J37: 0
B38: Janani Property Maintenance Charges | C38: 727 | F38: 727 | G38: 719 | I38: 0 | J38: 719 | K38: =F38-J38 -> 8
B39: Janani Property Rental Charges | C39: 4210 | F39: 4210 | G39: 4162 | I39: 0 | J39: 4162 | K39: =F39-J39 -> 48
B40: Laptop Rental Charges | C40: 2049 | F40: 2049 | G40: 1924 | I40: 0 | J40: 1924 | K40: =F40-J40 -> 125
B41: Thiruttani rental charges | C41: 293 | F41: 293 | G41: 290 | I41: 0 | J41: 290 | K41: =F41-J41 -> 3
B42: Max Office rental charges | C42: 4255 | F42: 4255 | G42: 4207 | I42: 0 | J42: 4207 | K42: =F42-J42 -> 48
B43: Rent Expense | C43: 266 | D43: 0 | F43: 266 | G43: 263 | H43: 3000 | I43: 0 | J43: 3263 | K43: =F43-J43 -> -2997
...

Sheet May-April
B2: iMagnum US | C2: Period: May 2026 | G2: Period: April 2026
B3: FTM_CurrentYear_CV_SPL | E3: ( USD in Whole Number ) | I3: ( USD in Whole Number )
B6: particulars | C6: iMagnum India | D6: iMagnum US | E6: Elimination-iMagnum Segment | F6: Total | G6: iMagnum India | H6: iMagnum US | I6: Elimination-iMagnum Segment | J6: Total | K6: Variance
B7: Service Income
B8: Sales | C8: 158437 | D8: 209920 | E8: -158439 | F8: 209918 | G8: 176206 | H8: 194902 | I8: -175901 | J8: 195207 | K8: =F8-J8 -> 14711
B9: Sales | C9: 158439 | D9: 209920 | E9: -158439 | F9: 209920 | G9: 175901 | H9: 194902 | I9: -175901 | J9: 194902 | K9: =F9-J9 -> 15018
B10: Other Charges | C10: 0 | D10: 0 | F10: 0 | G10: 0 | H10: 0 | J10: 0 | K10: =F10-J10 -> 0
B11: Buyout
B12: General Income | C12: 0 | D12: 0 | F12: 0 | G12: 16 | H12: 0 | J12: 16 | K12: =F12-J12 -> -16
B13: Interest Income | C13: -2 | F13: -2 | G13: 289 | J13: 289 | K13: =F13-J13 -> -291
B14: Total Revenue | C14: 158437 | D14: 209920 | E14: -158439 | F14: 209918 | G14: 176206 | H14: 194902 | I14: -175901 | J14: 195207 | K14: =F14-J14 -> 14711
B15: Overall Operational cost
B16: Manpower | C16: 92642 | D16: 158280 | E16: -158439 | F16: 92483 | G16: 101010 | H16: 175901 | I16: -175901 | J16: 101010 | K16: =F16-J16 -> -8527
B17: India Cost
B18: Consultancy fee | D18: 0 | F18: 0 | H18: 0 | J18: 0 | K18: =F18-J18 -> 0
B19: Operation salaries | C19: 57391 | F19: 57391 | G19: 62706 | J19: 62706 | K19: =F19-J19 -> -5315
B20: Ops Support Salaries | C20: 35040 | F20: 35040 | G20: 38087 | J20: 38087 | K20: =F20-J20 -> -3047
B21: Contract employee salaries | C21: 212 | D21: 158280 | E21: -158439 | F21: 53 | G21: 217 | H21: 175901 | I21: -175901 | J21: 217 | K21: =F21-J21 -> -164
B22: Coding charges | C22: -1 | F22: -1 | G22: 0 | J22: 0 | K22: =F22-J22 -> -1
B23: Employee statutory expenses | C23: 10965 | F23: 10965 | G23: 11375 | J23: 11375 | K23: =F23-J23 -> -410
B24: Employee ESI
B25: EPF Admin Charges | C25: 381 | F25: 381 | G25: 415 | J25: 415 | K25: =F25-J25 -> -34
B26: Employee PF | C26: 9488 | F26: 9488 | G26: 9958 | J26: 9958 | K26: =F26-J26 -> -470
B27: Employer ESI | C27: 365 | F27: 365 | G27: 391 | J27: 391 | K27: =F27-J27 -> -26
B28: Employer PF
B29: Professional tax | C29: 597 | F29: 597 | G29: 610 | J29: 610 | K29: =F29-J29 -> -13
B30: Interest on TDS | C30: 8 | F30: 8
B31: Interest on employee statutory dues
B32: Interest on Advance Tax | C32: 127 | F32: 127
B33: Facility Cost | C33: 14229 | D33: 3000 | F33: 17229 | G33: 14894 | H33: 0 | J33: 14894 | K33: =F33-J33 -> 2335
B34: Electricity
B35: Electricity Expense | C35: 2663 | F35: 2663 | G35: 2980 | J35: 2980 | K35: =F35-J35 -> -317
B36: Computer maintenance
B37: Janani Property Maintenance Charges | C37: 719 | F37: 719 | G37: 743 | J37: 743 | K37: =F37-J37 -> -24
B38: Janani Property Rental Charges | C38: 4162 | F38: 4162 | G38: 4302 | J38: 4302 | K38: =F38-J38 -> -140
B39: Laptop Rental Charges | C39: 1924 | F39: 1924 | G39: 1964 | J39: 1964 | K39: =F39-J39 -> -40
B40: Thiruttani rental charges | C40: 290 | F40: 290 | G40: 285 | J40: 285 | K40: =F40-J40 -> 5
B41: Max Office rental charges | C41: 4207 | F41: 4207 | G41: 4348 | J41: 4348 | K41: =F41-J41 -> -141
B42: Rent Expense | C42: 263 | D42: 3000 | F42: 3263 | G42: 272 | H42: 0 | J42: 272 | K42: =F42-J42 -> 2991
B43: Trichy rental charges
...

Sheet April-March
B2: iMagnum US | C2: Period: April 2026 | G2: Period: March 2026
B3: FTM_CurrentYear_CV_SPL | E3: ( USD in Whole Number ) | I3: ( USD in Whole Number )
B6: particulars | C6: iMagnum India | D6: iMagnum US | E6: Elimination-iMagnum Segment | F6: Total | G6: iMagnum India | H6: iMagnum US | I6: Elimination-iMagnum Segment | J6: Total | K6: Variance
B7: Service Income
B8: Sales | C8: 176206 | D8: 194902 | E8: -175901 | F8: 195207 | G8: 75319 | H8: 237839 | I8: -75319 | J8: 237839 | K8: =F8-J8 -> -42632
B9: Sales | C9: 175901 | D9: 194902 | E9: -175901 | F9: 194902 | G9: 75319 | H9: 237839 | I9: -75319 | J9: 237839 | K9: =F9-J9 -> -42937
B10: Other Charges | C10: 0 | D10: 0 | F10: 0 | G10: 0 | H10: 0 | J10: 0 | K10: =F10-J10 -> 0
B11: Buyout
B12: General Income | C12: 16 | D12: 0 | F12: 16 | H12: 0 | J12: 0 | K12: =F12-J12 -> 16
B13: Interest Income | C13: 289 | F13: 289
B14: Total Revenue | C14: 176206 | D14: 194902 | E14: -175901 | F14: 195207 | G14: 75319 | H14: 237839 | I14: -75319 | J14: 237839 | K14: =F14-J14 -> -42632
B15: Overall Operational cost
B16: Manpower | C16: 100793 | D16: 175901 | E16: -175901 | F16: 100793 | G16: 104521 | H16: 75394 | I16: -75319 | J16: 104596 | K16: =F16-J16 -> -3803
B17: India Cost
B18: Consultancy fee | D18: 0 | F18: 0 | H18: 75 | J18: 75 | K18: =F18-J18 -> -75
B19: Operation salaries | C19: 62706 | F19: 62706 | G19: 65666 | J19: 65666 | K19: =F19-J19 -> -2960
B20: Ops Support Salaries | C20: 38087 | F20: 38087 | G20: 38517 | J20: 38517 | K20: =F20-J20 -> -430
B21: Contract employee salaries | C21: 0 | D21: 175901 | E21: -175901 | F21: 0 | G21: 217 | H21: 75319 | I21: -75319 | J21: 217 | K21: =F21-J21 -> -217
B22: Coding charges | C22: 0 | F22: 0 | G22: 121 | J22: 121 | K22: =F22-J22 -> -121
B23: Employee statutory expenses | C23: 11371 | F23: 11371 | G23: 10999 | J23: 10999 | K23: =F23-J23 -> 372
B24: Employee ESI
B25: EPF Admin Charges | C25: 411 | F25: 411 | G25: 383 | J25: 383 | K25: =F25-J25 -> 28
B26: Employee PF | C26: 9958 | F26: 9958 | G26: 9573 | J26: 9573 | K26: =F26-J26 -> 385
B27: Employer ESI | C27: 391 | F27: 391 | G27: 404 | J27: 404 | K27: =F27-J27 -> -13
B28: Employer PF
B29: Professional tax | C29: 610 | F29: 610 | G29: 639 | J29: 639 | K29: =F29-J29 -> -29
B30: Interest on TDS
B31: Interest on employee statutory dues
B32: Facility Cost | C32: 14894 | D32: 0 | F32: 14894 | G32: 14533 | H32: 1000 | J32: 15533 | K32: =F32-J32 -> -639
B33: Electricity
B34: Electricity Expense | C34: 2980 | F34: 2980 | G34: 2676 | J34: 2676 | K34: =F34-J34 -> 304
B35: Computer maintenance
B36: Janani Property Maintenance Charges | C36: 743 | F36: 743 | G36: 743 | J36: 743 | K36: =F36-J36 -> 0
B37: Janani Property Rental Charges | C37: 4302 | F37: 4302 | G37: 4302 | J37: 4302 | K37: =F37-J37 -> 0
B38: Laptop Rental Charges | C38: 1964 | F38: 1964 | G38: 1907 | J38: 1907 | K38: =F38-J38 -> 57
B39: Thiruttani rental charges | C39: 285 | F39: 285 | G39: 285 | J39: 285 | K39: =F39-J39 -> 0
B40: Max Office rental charges | C40: 4348 | F40: 4348 | G40: 4348 | J40: 4348 | K40: =F40-J40 -> 0
B41: Rent Expense | C41: 272 | D41: 0 | F41: 272 | G41: 272 | H41: 1000 | J41: 1272 | K41: =F41-J41 -> -1000
B42: Trichy rental charges
B43: Telcom/Data & others | C43: 1475 | D43: 506 | F43: 1981 | G43: 1603 | H43: 1255 | J43: 2858 | K43: =F43-J43 -> -877
...

Sheet March-Feb
B2: iMagnum US | C2: Period: March 2026 | G2: Period: February 2026
B3: FTM_CurrentYear_CV_SPL | F3: ( USD in Whole Number ) | J3: ( USD in Whole Number )
B6: particulars | C6: iMagnum India | D6: iMagnum US | E6: Total | F6: Elimination-iMagnum Segment | G6: iMagnum India | H6: iMagnum US | I6: Total | J6: Elimination-iMagnum Segment | K6: Variance
B7: Service Income
B8: Sales | C8: 123319 | D8: 221215 | E8: 221215 | F8: -123319 | G8: 184916 | H8: 227771 | I8: 227771 | J8: -184916 | K8: =E8-I8 -> -6556
B9: Sales | C9: 123319 | D9: 221215 | E9: 221215 | F9: -123319 | G9: 184916 | H9: 227770 | I9: 227770 | J9: -184916
B10: Other Charges | C10: 0 | D10: 0 | E10: 0 | G10: 0 | H10: 1 | I10: 1
B11: Buyout
B12: General Income | D12: 0 | E12: 0 | H12: 0 | I12: 0
B13: Interest Income
B14: Total Revenue | C14: 123319 | D14: 221215 | E14: 221215 | F14: -123319 | G14: 184916 | H14: 227771 | I14: 227771 | J14: -184916
B15: Overall Operational cost
B16: Manpower | C16: 112934 | D16: 130894 | E16: 120509 | F16: -123319 | G16: 102920 | H16: 190830 | I16: 108834 | J16: -184916 | K16: =I16-E16 -> -11675
B17: India Cost
B18: Consultancy fee | D18: 7575 | E18: 7575 | H18: 5914 | I18: 5914
B19: Operation salaries | C19: 71381 | E19: 71381 | G19: 66470 | I19: 66470
B20: Ops Support Salaries | C20: 41215 | E20: 41215 | G20: 36233 | I20: 36233
B21: Contract employee salaries | C21: 217 | D21: 123319 | E21: 217 | F21: -123319 | G21: 217 | H21: 184916 | I21: 217 | J21: -184916
B22: Coding charges | C22: 121 | E22: 121
B23: Employee statutory expenses | C23: 11400 | E23: 11400 | G23: 10714 | I23: 10714 | K23: =I23-E23 -> -686
B24: Employee ESI
B25: EPF Admin Charges | C25: 392 | E25: 392 | G25: 370 | I25: 370
B26: Employee PF | C26: 9964 | E26: 9964 | G26: 9273 | I26: 9273
B27: Employer ESI | C27: 404 | E27: 404 | G27: 428 | I27: 428
B28: Employer PF
B29: Professional tax | C29: 639 | E29: 639 | G29: 644 | I29: 644
B30: Interest on TDS
B31: Interest on employee statutory dues
B32: Facility Cost | C32: 14533 | D32: 1000 | E32: 15533 | G32: 15082 | H32: 0 | I32: 15082 | K32: =I32-E32 -> -451
B33: Electricity
B34: Electricity Expense | C34: 2676 | E34: 2676 | G34: 3064 | I34: 3064
B35: Computer maintenance
B36: Janani Property Maintenance Charges | C36: 743 | E36: 743 | G36: 743 | I36: 743
B37: Janani Property Rental Charges | C37: 4302 | E37: 4302 | G37: 4302 | I37: 4302
B38: Laptop Rental Charges | C38: 1907 | E38: 1907 | G38: 2068 | I38: 2068
B39: Thiruttani rental charges | C39: 285 | E39: 285 | G39: 285 | I39: 285
B40: Max Office rental charges | C40: 4348 | E40: 4348 | G40: 4348 | I40: 4348
B41: Rent Expense | C41: 272 | D41: 1000 | E41: 1272 | G41: 272 | H41: 0 | I41: 272
B42: Trichy rental charges
B43: Telcom/Data & others | C43: 1546 | D43: 25406 | E43: 26953 | G43: 1464 | H43: 18105 | I43: 19569 | K43: =I43-E43 -> -7384
...

Sheet Jan
B1: IMAGNUM HEALTHCARE SOLUTION PRIVATE LIMITED
B2: =MID(CELL("filename",B1),FIND("]",CELL("filename",B1))+1,250) -> Jan
B4: Particulars | C4: Jan-US | D4: Jan-India | E4: Jan Consolidation | F4: Budget Remarks
B5: Service Income
B6: Sales | C6: =C77 -> 226814 | D6: =D77 -> 0 | E6: =C6+D6 -> 226814
B7: Total Revenue | C7: =SUM(C6) -> 226814 | D7: =SUM(D6) -> 0 | E7: =C7+D7 -> 226814
B9: Overall Operational cost
B10: Manpower | C10: =C99 -> 0 | D10: =D99 -> 114851.43 | E10: =E99 -> 114851.43 | F10: Budgeted HC for operations & ops support is 208 whereas Actual HC is 270
B11: Facility Cost | C11: =C112 -> 2000 | D11: =D112 -> 13975.718 | E11: =C11+D11 -> 15975.718
B12: Telcom/Data & others | C12: =C123 -> 3270.23 | D12: =D123 -> 1668.7611 | E12: =C12+D12 -> 4938.9911
B13: Transport | C13: =C127 -> 0 | D13: =D127 -> 4438.587 | E13: =C13+D13 -> 4438.587 | F13: Transport cost budgeted in proportion with HC
B14: Other COGS | C14: =C142 -> 14832.9 | D14: =D142 -> 5397.5486 | E14: =C14+D14 -> 20230.449 | F14: Software Expense budgeted for $9,393 whereas actual it is $20,656
B15: Total COGS | C15: =SUM(C10:C14) -> 20103.13 | D15: =SUM(D10:D14) -> 140332.05 | E15: =SUM(E10:E14) -> 160435.18
B16: GP | C16: =C7-C15 -> 206710.87 | D16: =D7-D15 -> -140332.05 | E16: =E7-E15 -> 66378.82
B17: GM% | E17: =E16/E7 -> 0.29265751
B20: SG&A
B21: Selling Expenses | C21: =C159 -> 3440.69 | D21: =D159 -> 1759.788 | E21: =C21+D21 -> 5200.478
B22: G&A Expenses
B23: Salaries-Management & Others | C23: =C210 -> 37269.02 | D23: =D210 -> 9892.1087 | E23: =C23+D23 -> 47161.129
B24: Legal & Professional Fees | C24: =C205 -> 7940.38 | D24: =D205 -> 1413.0435 | E24: =C24+D24 -> 9353.4235
B25: G&A salaries | C25: =C198 -> 11722.56 | D25: =D198 -> 2606.087 | E25: =C25+D25 -> 14328.647
B26: Gen & Admin. Expenses | C26: =C190 -> 15020.47 | D26: =D190 -> 1528.303 | E26: =C26+D26 -> 16548.773 | F26: Insurance expense budgeted for $1,400 whereas actual it is $6,487 Consultancy fees not budgeted whereas actual it $3,750
B27: Total | C27: =SUM(C23:C26) -> 71952.43 | D27: =SUM(D23:D26) -> 15439.542 | E27: =C27+D27 -> 87391.972
B29: Overall SG&A | C29: =+C21+C27 -> 75393.12 | D29: =+D21+D27 -> 17199.33 | E29: =C29+D29 -> 92592.45
B31: EBITDA | C31: =C16-C29 -> 131317.75 | D31: =D16-D29 -> -157531.38 | E31: =E16-E29 -> -26213.63
B32: EBITDA% | E32: =E31/E7 -> -0.11557325
B34: Finance Cost | C34: =C219 -> 4889.52 | D34: =D219 -> -6231.8296 | E34: =C34+D34 -> -1342.3096
B35: Rates & Taxes | C35: =C221 -> 0 | D35: =D221 -> 0 | E35: =C35+D35 -> 0
B36: Depreciation | C36: =C222 -> 0 | D36: =D222 -> 0 | E36: =C36+D36 -> 0
B37: Total | C37: =SUM(C34:C36) -> 4889.52 | D37: =SUM(D34:D36) -> -6231.8296 | E37: =C37+D37 -> -1342.3096
B39: PBT | C39: =C31-C37 -> 126428.23 | D39: =D31-D37 -> -151299.55 | E39: =E31-E37 -> -24871.321
E40: =E39/E7 -> -0.10965514
B41: Check point
B42: Revenue | E42: =C72 -> 226527
B43: India cost | E43: 151604.88
B44: US cost | E44: =C7-C39 -> 100385.77
B45: Profit | E45: =E42-E43-E44 -> -25463.647
E46: =E45-E39 -> -592.32609
B49: Total Revenue | E49: =E7 -> 226814
B50: Directs | E50: 197
...

Sheet Holding Detailed Exp summary
A2: IMAGNUM HEALTHCARE SOLUTION PRIVATE LIMITED
B3: Sum of Amount | C3: Column Labels
B4: Row Labels | C4: 45688 | D4: 45716 | E4: 45747 | F4: 45777 | G4: 45808 | H4: 45838 | I4: 45869 | J4: 45900 | K4: 45930 | L4: 45961 | M4: 45991 | N4: 46022 | O4: 46053 | P4: 46081 | Q4: 46112 | R4: 46142 | S4: 46173 | T4: 46203 | U4: Jun Vs May
B5: Operational Cost | C5: 140372.38 | D5: 156066.25 | E5: 163126.01 | F5: 182521.71 | G5: 172967.17 | H5: 217751.89 | I5: 187196.35 | J5: 211746.73 | K5: 209436.87 | L5: 208717.45 | M5: 216280.72 | N5: 209450.3 | O5: 211311.47 | P5: 203313.12 | Q5: 106950.86 | R5: 193910.08 | S5: 179687.53 | T5: 163379.68 | U5: =S5-T5 -> 16307.85
B6: India Cost | C6: 137139 | D6: 141484 | E6: 140018 | F6: 164649 | G6: 151760 | H6: 200674 | I6: 158956 | J6: 173054 | K6: 187101 | L6: 183412 | M6: 190966 | N6: 187035 | O6: 184697 | P6: 184916 | Q6: 75319 | R6: 175901 | S6: 158280 | T6: 157139 | U6: =S6-T6 -> 1141
B7: Contractors | C7: 137139 | D7: 141484 | E7: 140018 | F7: 164649 | G7: 151760 | H7: 200674 | I7: 158956 | J7: 173054 | K7: 187101 | L7: 183412 | M7: 190966 | N7: 187035 | O7: 184697 | P7: 184916 | Q7: 75319 | R7: 175901 | S7: 158280 | T7: 157139 | U7: =S7-T7 -> 1141
B8: iMagnum Healthcare Solutions Pvt Ltd | C8: 137139 | D8: 141484 | E8: 140018 | F8: 164649 | G8: 151760 | H8: 200674 | I8: 158956 | J8: 173054 | K8: 187101 | L8: 183412 | M8: 190966 | N8: 187035 | O8: 184697 | P8: 184916 | Q8: 75319 | R8: 175901 | S8: 158280 | T8: 157139 | U8: =S8-T8 -> 1141
B9: Facility Cost | F9: 1050 | H9: 2000 | K9: 2000 | M9: 2000 | O9: 2000 | Q9: 1000 | S9: 3000 | U9: =S9-T9 -> 3000
