Workbook
Name \: #REF!
Name \: #REF!
Name \: #REF!
Name \: #REF!
Name \: #REF!
Name \: #REF!
Name \0: #REF!
Name \0: #REF!
Name \0: #REF!
Name \0: #REF!
Name \0: #REF!
Name \0: #REF!
Name \A: #REF!
Name \A: #REF!
Name \A: #REF!
Name \A: #REF!
Name \A: #REF!
Name \A: #REF!
Name \B: #REF!
Name \B: #REF!
Name \B: #REF!
Name \B: #REF!
Name \B: #REF!
Name \B: #REF!
Name \E: #REF!
Name \E: #REF!
Name \E: #REF!
Name \E: #REF!
Name \E: #REF!
Name \E: #REF!
Name \G: #REF!
Name \G: #REF!
Name \G: #REF!
Name \G: #REF!
Name \G: #REF!
Name \G: #REF!
Name \L: #REF!
Name \L: #REF!
Name \L: #REF!
Name \L: #REF!
Name \L: #REF!
Name \L: #REF!
Name \q: #REF!
Name \q: #REF!
Name \q: #REF!
Name \q: #REF!
Name \q: #REF!
Name \q: #REF!
Name \S: #REF!
Name \S: #REF!
Name \S: #REF!
Name \S: #REF!
Name \S: #REF!
Name \S: #REF!
Name \T: #REF!
Name \T: #REF!
Name \T: #REF!
Name \T: #REF!
Name \T: #REF!
Name \T: #REF!

Sheet Sheet1
A1: Consolidated P&L — Jan to May 2026
A2: (USD in Whole Numbers)
A4: Particulars | B4: Jan-26 | C4: Feb-26 | D4: Mar-26 | E4: Apr-26 | F4: May-26
A5: Service Income
A6: Sales | B6: 226527 | C6: 227771 | D6: 221215 | E6: 195207 | F6: 209918
A7: Sales | B7: 226814 | C7: 227770 | D7: 221215 | E7: 194902 | F7: 209920
A8: Other Charges | B8: 0 | C8: 1 | D8: 0 | E8: 0 | F8: 0
A9: Buyout | B9: 0
A10: General Income | B10: 287 | C10: 0 | D10: 0 | E10: 16 | F10: 0
A11: Interest Income | B11: 0 | E11: 289 | F11: -2
A12: Total Revenue | B12: 226814 | C12: 227771 | D12: 221215 | E12: 195207 | F12: 209918
A13: Overall Operational cost
A14: Manpower | B14: 114851 | C14: 108834 | D14: 120509 | E14: 100793 | F14: 92483
A15: India Cost
A16: Consultancy fee | B16: 0 | C16: 5914 | D16: 7575 | E16: 0 | F16: 0
A17: Operation salaries | B17: 65899 | C17: 66470 | D17: 71381 | E17: 62706 | F17: 57391
A18: Ops Support Salaries | B18: 37201 | C18: 36233 | D18: 41215 | E18: 38087 | F18: 35040
A19: Contract employee salaries | B19: 0 | C19: 217 | D19: 217 | E19: 0 | F19: 53
A20: Coding charges | B20: 0 | D20: 121 | E20: 0 | F20: -1
A21: Employee statutory expenses | C21: 10714 | D21: 11400 | E21: 11371 | F21: 10965
A22: Employee ESI | B22: 83
A23: EPF Admin Charges | B23: 407 | C23: 370 | D23: 392 | E23: 411 | F23: 381
A24: Employee PF | B24: 5079 | C24: 9273 | D24: 9964 | E24: 9958 | F24: 9488
A25: Employer ESI | B25: 357 | C25: 428 | D25: 404 | E25: 391 | F25: 365
A26: Employer PF | B26: 5079
A27: Professional tax | B27: 748 | C27: 644 | D27: 639 | E27: 610 | F27: 597
A28: Interest on TDS | B28: 0 | F28: 8
A29: Interest on employee statutory dues | B29: 0
A30: Interest on Advance Tax | F30: 127
A31: Facility Cost | B31: 15976 | C31: 15082 | D31: 15533 | E31: 14894 | F31: 17229
A32: Electricity | B32: 0
A33: Electricity Expense | B33: 1968 | C33: 3064 | D33: 2676 | E33: 2980 | F33: 2663
A34: Computer maintenance | B34: 0
A35: Janani Property Maintenance Charges | B35: 743 | C35: 743 | D35: 743 | E35: 743 | F35: 719
A36: Janani Property Rental Charges | B36: 4302 | C36: 4302 | D36: 4302 | E36: 4302 | F36: 4162
A37: Laptop Rental Charges | B37: 2058 | C37: 2068 | D37: 1907 | E37: 1964 | F37: 1924
A38: Thiruttani rental charges | B38: 285 | C38: 285 | D38: 285 | E38: 285 | F38: 290
A39: Max Office rental charges | B39: 4348 | C39: 4348 | D39: 4348 | E39: 4348 | F39: 4207
A40: Rent Expense | B40: 2000 | C40: 272 | D40: 1272 | E40: 272 | F40: 3263
A41: Trichy rental charges | B41: 272
...

Sheet Consolidated PnL-Jan
B1: IMAGNUM HEALTHCARE SOLUTION PRIVATE LIMITED
B2: =MID(CELL("filename",B1),FIND("]",CELL("filename",B1))+1,250) -> Consolidated PnL-Jan
B4: Particulars | C4: Jan-US | D4: Jan-India | E4: Jan Consolidation | F4: Budget Remarks
B5: Service Income
B6: Sales | C6: =C77 -> 226814 | D6: =D77 -> 0 | E6: =C6+D6 -> 226814
B7: Total Revenue | C7: =SUM(C6) -> 226814 | D7: =SUM(D6) -> 0 | E7: =C7+D7 -> 226814
B9: Overall Operational cost
B10: Manpower | C10: =C99 -> 0 | D10: =D99 -> 114851.43 | E10: =E99 -> 114851.43 | F10: Budgeted HC for operations & ops support is 208 whereas Actual HC is 270
B11: Facility Cost | C11: =C112 -> 2000 | D11: =D112 -> 13975.718 | E11: =C11+D11 -> 15975.718
B12: Telcom/Data & others | C12: =C123 -> 3270.23 | D12: =D123 -> 1668.7611 | E12: =C12+D12 -> 4938.9911
B13: Transport | C13: =C127 -> 0 | D13: =D127 -> 4438.587 | E13: =C13+D13 -> 4438.587 | F13: Transport cost budgeted in proportion with HC
B14: Other COGS | C14: =C142 -> 14832.9 | D14: =D142 -> 5397.5486 | E14: =C14+D14 -> 20230.449 | F14: Software Expense budgeted for $9,393 whereas actual it is $20,656
B15: Total COGS | C15: =SUM(C10:C14) -> 20103.13 | D15: =SUM(D10:D14) -> 140332.05 | E15: =SUM(E10:E14) -> 160435.18
B16: GP | C16: =C7-C15 -> 206710.87 | D16: =D7-D15 -> -140332.05 | E16: =E7-E15 -> 66378.82
B17: GM% | E17: =E16/E7 -> 0.29265751
B20: SG&A
B21: Selling Expenses | C21: =C159 -> 3440.69 | D21: =D159 -> 1759.788 | E21: =C21+D21 -> 5200.478
B22: G&A Expenses
B23: Salaries-Management & Others | C23: =C210 -> 37269.02 | D23: =D210 -> 9892.1087 | E23: =C23+D23 -> 47161.129
B24: Legal & Professional Fees | C24: =C205 -> 7940.38 | D24: =D205 -> 1413.0435 | E24: =C24+D24 -> 9353.4235
B25: G&A salaries | C25: =C198 -> 11722.56 | D25: =D198 -> 2606.087 | E25: =C25+D25 -> 14328.647
B26: Gen & Admin. Expenses | C26: =C190 -> 15020.47 | D26: =D190 -> 1528.303 | E26: =C26+D26 -> 16548.773 | F26: Insurance expense budgeted for $1,400 whereas actual it is $6,487 Consultancy fees not budgeted whereas actual it $3,750
B27: Total | C27: =SUM(C23:C26) -> 71952.43 | D27: =SUM(D23:D26) -> 15439.542 | E27: =C27+D27 -> 87391.972
B29: Overall SG&A | C29: =+C21+C27 -> 75393.12 | D29: =+D21+D27 -> 17199.33 | E29: =C29+D29 -> 92592.45
B31: EBITDA | C31: =C16-C29 -> 131317.75 | D31: =D16-D29 -> -157531.38 | E31: =E16-E29 -> -26213.63
B32: EBITDA% | E32: =E31/E7 -> -0.11557325
B34: Finance Cost | C34: =C219 -> 4889.52 | D34: =D219 -> -6231.8296 | E34: =C34+D34 -> -1342.3096
B35: Rates & Taxes | C35: =C221 -> 0 | D35: =D221 -> 0 | E35: =C35+D35 -> 0
B36: Depreciation | C36: =C222 -> 0 | D36: =D222 -> 0 | E36: =C36+D36 -> 0
B37: Total | C37: =SUM(C34:C36) -> 4889.52 | D37: =SUM(D34:D36) -> -6231.8296 | E37: =C37+D37 -> -1342.3096
B39: PBT | C39: =C31-C37 -> 126428.23 | D39: =D31-D37 -> -151299.55 | E39: =E31-E37 -> -24871.321
E40: =E39/E7 -> -0.10965514
B41: Check point
B42: Revenue | E42: =C72 -> 226527
B43: India cost | E43: ='[1]Subs MoM PnL'!T7-'[1]Subs MoM PnL'!T37 -> 151604.88
B44: US cost | E44: =C7-C39 -> 100385.77
B45: Profit | E45: =E42-E43-E44 -> -25463.647
E46: =E45-E39 -> -592.32609
B49: Total Revenue | E49: =E7 -> 226814
B50: Directs | E50: ='[1]Payroll Dashboard'!BA5 -> 197
...

Sheet Consolidated- Mar&Feb
B2: iMagnum US | C2: Period: March 2026 | G2: Period: February 2026
B3: FTM_CurrentYear_CV_SPL | F3: ( USD in Whole Number ) | J3: ( USD in Whole Number )
B6: particulars | C6: iMagnum India | D6: iMagnum US | E6: Total | F6: Elimination-iMagnum Segment | G6: iMagnum India | H6: iMagnum US | I6: Total | J6: Elimination-iMagnum Segment | K6: Variance
B7: Service Income
B8: Sales | C8: 123319 | D8: 221215 | E8: 221215 | F8: -123319 | G8: 184916 | H8: 227771 | I8: 227771 | J8: -184916 | K8: =E8-I8 -> -6556
B9: Sales | C9: 123319 | D9: 221215 | E9: 221215 | F9: -123319 | G9: 184916 | H9: 227770 | I9: 227770 | J9: -184916
B10: Other Charges | C10: 0 | D10: 0 | E10: 0 | G10: 0 | H10: 1 | I10: 1
B11: Buyout
B12: General Income | D12: 0 | E12: 0 | H12: 0 | I12: 0
B13: Interest Income
B14: Total Revenue | C14: 123319 | D14: 221215 | E14: 221215 | F14: -123319 | G14: 184916 | H14: 227771 | I14: 227771 | J14: -184916
B15: Overall Operational cost
B16: Manpower | C16: 112934 | D16: 130894 | E16: 120509 | F16: -123319 | G16: 102920 | H16: 190830 | I16: 108834 | J16: -184916 | K16: =I16-E16 -> -11675
B17: India Cost
B18: Consultancy fee | D18: 7575 | E18: 7575 | H18: 5914 | I18: 5914
B19: Operation salaries | C19: 71381 | E19: 71381 | G19: 66470 | I19: 66470
B20: Ops Support Salaries | C20: 41215 | E20: 41215 | G20: 36233 | I20: 36233
B21: Contract employee salaries | C21: 217 | D21: 123319 | E21: 217 | F21: -123319 | G21: 217 | H21: 184916 | I21: 217 | J21: -184916
B22: Coding charges | C22: 121 | E22: 121
B23: Employee statutory expenses | C23: 11400 | E23: 11400 | G23: 10714 | I23: 10714 | K23: =I23-E23 -> -686
B24: Employee ESI
B25: EPF Admin Charges | C25: 392 | E25: 392 | G25: 370 | I25: 370
B26: Employee PF | C26: 9964 | E26: 9964 | G26: 9273 | I26: 9273
B27: Employer ESI | C27: 404 | E27: 404 | G27: 428 | I27: 428
B28: Employer PF
B29: Professional tax | C29: 639 | E29: 639 | G29: 644 | I29: 644
B30: Interest on TDS
B31: Interest on employee statutory dues
B32: Facility Cost | C32: 14533 | D32: 1000 | E32: 15533 | G32: 15082 | H32: 0 | I32: 15082 | K32: =I32-E32 -> -451
B33: Electricity
B34: Electricity Expense | C34: 2676 | E34: 2676 | G34: 3064 | I34: 3064
B35: Computer maintenance
B36: Janani Property Maintenance Charges | C36: 743 | E36: 743 | G36: 743 | I36: 743
B37: Janani Property Rental Charges | C37: 4302 | E37: 4302 | G37: 4302 | I37: 4302
B38: Laptop Rental Charges | C38: 1907 | E38: 1907 | G38: 2068 | I38: 2068
B39: Thiruttani rental charges | C39: 285 | E39: 285 | G39: 285 | I39: 285
B40: Max Office rental charges | C40: 4348 | E40: 4348 | G40: 4348 | I40: 4348
B41: Rent Expense | C41: 272 | D41: 1000 | E41: 1272 | G41: 272 | H41: 0 | I41: 272
B42: Trichy rental charges
B43: Telcom/Data & others | C43: 1546 | D43: 25406 | E43: 26953 | G43: 1464 | H43: 18105 | I43: 19569 | K43: =I43-E43 -> -7384
...

Sheet Consolidted PnL-April
B2: iMagnum US | C2: Period: April 2026 | G2: Period: March 2026
B3: FTM_CurrentYear_CV_SPL | E3: ( USD in Whole Number ) | I3: ( USD in Whole Number )
B6: particulars | C6: iMagnum India | D6: iMagnum US | E6: Elimination-iMagnum Segment | F6: Total | G6: iMagnum India | H6: iMagnum US | I6: Elimination-iMagnum Segment | J6: Total | K6: Variance
B7: Service Income
B8: Sales | C8: 176206 | D8: 194902 | E8: -175901 | F8: 195207 | G8: 75319 | H8: 237839 | I8: -75319 | J8: 237839 | K8: =F8-J8 -> -42632
B9: Sales | C9: 175901 | D9: 194902 | E9: -175901 | F9: 194902 | G9: 75319 | H9: 237839 | I9: -75319 | J9: 237839 | K9: =F9-J9 -> -42937
B10: Other Charges | C10: 0 | D10: 0 | F10: 0 | G10: 0 | H10: 0 | J10: 0 | K10: =F10-J10 -> 0
B11: Buyout
B12: General Income | C12: 16 | D12: 0 | F12: 16 | H12: 0 | J12: 0 | K12: =F12-J12 -> 16
B13: Interest Income | C13: 289 | F13: 289
B14: Total Revenue | C14: 176206 | D14: 194902 | E14: -175901 | F14: 195207 | G14: 75319 | H14: 237839 | I14: -75319 | J14: 237839 | K14: =F14-J14 -> -42632
B15: Overall Operational cost
B16: Manpower | C16: 100793 | D16: 175901 | E16: -175901 | F16: 100793 | G16: 104521 | H16: 75394 | I16: -75319 | J16: 104596 | K16: =F16-J16 -> -3803
B17: India Cost
B18: Consultancy fee | D18: 0 | F18: 0 | H18: 75 | J18: 75 | K18: =F18-J18 -> -75
B19: Operation salaries | C19: 62706 | F19: 62706 | G19: 65666 | J19: 65666 | K19: =F19-J19 -> -2960
B20: Ops Support Salaries | C20: 38087 | F20: 38087 | G20: 38517 | J20: 38517 | K20: =F20-J20 -> -430
B21: Contract employee salaries | C21: 0 | D21: 175901 | E21: -175901 | F21: 0 | G21: 217 | H21: 75319 | I21: -75319 | J21: 217 | K21: =F21-J21 -> -217
B22: Coding charges | C22: 0 | F22: 0 | G22: 121 | J22: 121 | K22: =F22-J22 -> -121
B23: Employee statutory expenses | C23: 11371 | F23: 11371 | G23: 10999 | J23: 10999 | K23: =F23-J23 -> 372
B24: Employee ESI
B25: EPF Admin Charges | C25: 411 | F25: 411 | G25: 383 | J25: 383 | K25: =F25-J25 -> 28
B26: Employee PF | C26: 9958 | F26: 9958 | G26: 9573 | J26: 9573 | K26: =F26-J26 -> 385
B27: Employer ESI | C27: 391 | F27: 391 | G27: 404 | J27: 404 | K27: =F27-J27 -> -13
B28: Employer PF
B29: Professional tax | C29: 610 | F29: 610 | G29: 639 | J29: 639 | K29: =F29-J29 -> -29
B30: Interest on TDS
B31: Interest on employee statutory dues
B32: Facility Cost | C32: 14894 | D32: 0 | F32: 14894 | G32: 14533 | H32: 1000 | J32: 15533 | K32: =F32-J32 -> -639
B33: Electricity
B34: Electricity Expense | C34: 2980 | F34: 2980 | G34: 2676 | J34: 2676 | K34: =F34-J34 -> 304
B35: Computer maintenance
B36: Janani Property Maintenance Charges | C36: 743 | F36: 743 | G36: 743 | J36: 743 | K36: =F36-J36 -> 0
B37: Janani Property Rental Charges | C37: 4302 | F37: 4302 | G37: 4302 | J37: 4302 | K37: =F37-J37 -> 0
B38: Laptop Rental Charges | C38: 1964 | F38: 1964 | G38: 1907 | J38: 1907 | K38: =F38-J38 -> 57
B39: Thiruttani rental charges | C39: 285 | F39: 285 | G39: 285 | J39: 285 | K39: =F39-J39 -> 0
B40: Max Office rental charges | C40: 4348 | F40: 4348 | G40: 4348 | J40: 4348 | K40: =F40-J40 -> 0
B41: Rent Expense | C41: 272 | D41: 0 | F41: 272 | G41: 272 | H41: 1000 | J41: 1272 | K41: =F41-J41 -> -1000
B42: Trichy rental charges
B43: Telcom/Data & others | C43: 1475 | D43: 506 | F43: 1981 | G43: 1603 | H43: 1255 | J43: 2858 | K43: =F43-J43 -> -877
...

Sheet Consolidted PnL-May
B2: iMagnum US | C2: Period: May 2026 | G2: Period: April 2026
B3: FTM_CurrentYear_CV_SPL | E3: ( USD in Whole Number ) | I3: ( USD in Whole Number )
B6: particulars | C6: iMagnum India | D6: iMagnum US | E6: Elimination-iMagnum Segment | F6: Total | G6: iMagnum India | H6: iMagnum US | I6: Elimination-iMagnum Segment | J6: Total | K6: Variance
B7: Service Income
B8: Sales | C8: 158437 | D8: 209920 | E8: -158439 | F8: 209918 | G8: 176206 | H8: 194902 | I8: -175901 | J8: 195207 | K8: =F8-J8 -> 14711
B9: Sales | C9: 158439 | D9: 209920 | E9: -158439 | F9: 209920 | G9: 175901 | H9: 194902 | I9: -175901 | J9: 194902 | K9: =F9-J9 -> 15018
B10: Other Charges | C10: 0 | D10: 0 | F10: 0 | G10: 0 | H10: 0 | J10: 0 | K10: =F10-J10 -> 0
B11: Buyout
B12: General Income | C12: 0 | D12: 0 | F12: 0 | G12: 16 | H12: 0 | J12: 16 | K12: =F12-J12 -> -16
B13: Interest Income | C13: -2 | F13: -2 | G13: 289 | J13: 289 | K13: =F13-J13 -> -291
B14: Total Revenue | C14: 158437 | D14: 209920 | E14: -158439 | F14: 209918 | G14: 176206 | H14: 194902 | I14: -175901 | J14: 195207 | K14: =F14-J14 -> 14711
B15: Overall Operational cost
B16: Manpower | C16: 92642 | D16: 158280 | E16: -158439 | F16: 92483 | G16: 101010 | H16: 175901 | I16: -175901 | J16: 101010 | K16: =F16-J16 -> -8527
B17: India Cost
B18: Consultancy fee | D18: 0 | F18: 0 | H18: 0 | J18: 0 | K18: =F18-J18 -> 0
B19: Operation salaries | C19: 57391 | F19: 57391 | G19: 62706 | J19: 62706 | K19: =F19-J19 -> -5315
B20: Ops Support Salaries | C20: 35040 | F20: 35040 | G20: 38087 | J20: 38087 | K20: =F20-J20 -> -3047
B21: Contract employee salaries | C21: 212 | D21: 158280 | E21: -158439 | F21: 53 | G21: 217 | H21: 175901 | I21: -175901 | J21: 217 | K21: =F21-J21 -> -164
B22: Coding charges | C22: -1 | F22: -1 | G22: 0 | J22: 0 | K22: =F22-J22 -> -1
B23: Employee statutory expenses | C23: 10965 | F23: 10965 | G23: 11375 | J23: 11375 | K23: =F23-J23 -> -410
B24: Employee ESI
B25: EPF Admin Charges | C25: 381 | F25: 381 | G25: 415 | J25: 415 | K25: =F25-J25 -> -34
B26: Employee PF | C26: 9488 | F26: 9488 | G26: 9958 | J26: 9958 | K26: =F26-J26 -> -470
B27: Employer ESI | C27: 365 | F27: 365 | G27: 391 | J27: 391 | K27: =F27-J27 -> -26
B28: Employer PF
B29: Professional tax | C29: 597 | F29: 597 | G29: 610 | J29: 610 | K29: =F29-J29 -> -13
B30: Interest on TDS | C30: 8 | F30: 8
B31: Interest on employee statutory dues
B32: Interest on Advance Tax | C32: 127 | F32: 127
B33: Facility Cost | C33: 14229 | D33: 3000 | F33: 17229 | G33: 14894 | H33: 0 | J33: 14894 | K33: =F33-J33 -> 2335
B34: Electricity
B35: Electricity Expense | C35: 2663 | F35: 2663 | G35: 2980 | J35: 2980 | K35: =F35-J35 -> -317
B36: Computer maintenance
B37: Janani Property Maintenance Charges | C37: 719 | F37: 719 | G37: 743 | J37: 743 | K37: =F37-J37 -> -24
B38: Janani Property Rental Charges | C38: 4162 | F38: 4162 | G38: 4302 | J38: 4302 | K38: =F38-J38 -> -140
B39: Laptop Rental Charges | C39: 1924 | F39: 1924 | G39: 1964 | J39: 1964 | K39: =F39-J39 -> -40
B40: Thiruttani rental charges | C40: 290 | F40: 290 | G40: 285 | J40: 285 | K40: =F40-J40 -> 5
B41: Max Office rental charges | C41: 4207 | F41: 4207 | G41: 4348 | J41: 4348 | K41: =F41-J41 -> -141
B42: Rent Expense | C42: 263 | D42: 3000 | F42: 3263 | G42: 272 | H42: 0 | J42: 272 | K42: =F42-J42 -> 2991
B43: Trichy rental charges
...

Sheet Holding Detailed Exp summary
A2: IMAGNUM HEALTHCARE SOLUTION PRIVATE LIMITED
B3: Sum of Amount | C3: Column Labels
B4: Row Labels | C4: 45688 | D4: 45716 | E4: 45747 | F4: 45777 | G4: 45808 | H4: 45838 | I4: 45869 | J4: 45900 | K4: 45930 | L4: 45961 | M4: 45991 | N4: 46022 | O4: 46053 | P4: 46081 | Q4: 46112 | R4: 46142 | S4: 46173 | T4: May Vs Apr
B5: Operational Cost | C5: 140372.38 | D5: 156066.25 | E5: 163126.01 | F5: 182521.71 | G5: 172967.17 | H5: 217751.89 | I5: 187196.35 | J5: 211746.73 | K5: 209436.87 | L5: 208717.45 | M5: 216280.72 | N5: 209450.3 | O5: 211311.47 | P5: 203313.12 | Q5: 106950.86 | R5: 193588.31 | S5: 174317.96 | T5: =R5-S5 -> 19270.35
B6: India Cost | C6: 137139 | D6: 141484 | E6: 140018 | F6: 164649 | G6: 151760 | H6: 200674 | I6: 158956 | J6: 173054 | K6: 187101 | L6: 183412 | M6: 190966 | N6: 187035 | O6: 184697 | P6: 184916 | Q6: 75319 | R6: 175901 | S6: 158280 | T6: =R6-S6 -> 17621
B7: Contractors | C7: 137139 | D7: 141484 | E7: 140018 | F7: 164649 | G7: 151760 | H7: 200674 | I7: 158956 | J7: 173054 | K7: 187101 | L7: 183412 | M7: 190966 | N7: 187035 | O7: 184697 | P7: 184916 | Q7: 75319 | R7: 175901 | S7: 158280 | T7: =R7-S7 -> 17621
B8: iMagnum Healthcare Solutions Pvt Ltd | C8: 137139 | D8: 141484 | E8: 140018 | F8: 164649 | G8: 151760 | H8: 200674 | I8: 158956 | J8: 173054 | K8: 187101 | L8: 183412 | M8: 190966 | N8: 187035 | O8: 184697 | P8: 184916 | Q8: 75319 | R8: 175901 | S8: 158280 | T8: =R8-S8 -> 17621
B9: Facility Cost | F9: 1050 | H9: 2000 | K9: 2000 | M9: 2000 | O9: 2000 | Q9: 1000 | S9: 3000 | T9: =R9-S9 -> -3000
B10: Rent Expense | F10: 1050 | H10: 2000 | K10: 2000 | M10: 2000 | O10: 2000 | Q10: 1000 | S10: 3000 | T10: =R10-S10 -> -3000
B11: Lynx Realty | F11: 1050 | H11: 2000 | K11: 2000 | M11: 2000 | O11: 2000 | Q11: 1000 | S11: 3000 | T11: =R11-S11 -> -3000
B12: Telecom Data & Others | C12: 1990.87 | D12: 613.96 | E12: 673.09 | F12: 924.82 | G12: 1687.9 | H12: 1193.92 | I12: 2480.76 | J12: 1380.49 | K12: 1568.84 | L12: 1388.64 | M12: 1260.19 | N12: 967.9 | O12: 3270.23 | P12: 1439.74 | Q12: 1254.75 | R12: 637.73 | S12: 505.1 | T12: =R12-S12 -> 132.63
B13: Dues and Subscriptions | C13: 314.84 | D13: 321.81 | E13: 431.18 | F13: 309.74 | G13: 1155.59 | H13: 447.56 | I13: 375.97 | J13: 492.04 | K13: 610.89 | L13: 494.47 | M13: 426.89 | N13: 403.23 | O13: 435.09 | P13: 392.63 | Q13: 459.2 | R13: 352.46 | S13: 220.25 | T13: =R13-S13 -> 132.21
B14: A2Webhost | K14: 212.26 | T14: =R14-S14 -> 0
B15: Adobe Systems | C15: 13.8 | D15: 13.8 | E15: 13.8 | F15: 13.8 | G15: 13.8 | H15: 13.8 | I15: 13.8 | J15: 13.8 | K15: 13.8 | L15: 13.8 | M15: 13.8 | N15: 13.8 | O15: 45.66 | P15: 13.8 | Q15: 13.8 | R15: 13.8 | S15: 13.8 | T15: =R15-S15 -> 0
B16: Availity | G16: 26.65 | T16: =R16-S16 -> 0
B17: Calendly | C17: 25.3 | D17: 25.3 | E17: 25.3 | F17: 25.3 | G17: 25.3 | H17: 25.3 | I17: 25.3 | J17: 25.54 | K17: 25.54 | L17: 25.54 | M17: 25.54 | N17: 25.54 | O17: 25.54 | P17: 25.54 | Q17: 25.54 | R17: 25.54 | S17: 25.54 | T17: =R17-S17 -> 0
B18: Chatgpt | C18: 180.88 | D18: 180.88 | E18: 180.88 | F18: 180.88 | G18: 180.88 | H18: 180.88 | I18: 186.2 | J18: 159.6 | K18: 159.6 | L18: 203.77 | M18: 191.52 | N18: 191.52 | O18: 191.52 | P18: 159.6 | Q18: 159.6 | R18: 119.43 | T18: =R18-S18 -> 119.43
B19: DROPBOX | C19: 12.78 | E19: 25.56 | F19: 12.78 | G19: 12.78 | H19: 12.78 | I19: 12.78 | J19: 12.78 | K19: 12.78 | L19: 12.78 | M19: 12.78 | N19: 12.78 | O19: 12.78 | P19: 12.78 | Q19: 12.78 | R19: 12.78 | T19: =R19-S19 -> 12.78
B20: MICROSOFT | J20: 137.79 | T20: =R20-S20 -> 0
B21: MongoDB | G21: 814.4 | T21: =R21-S21 -> 0
B22: Zoho Corp | C22: 82.08 | D22: 82.08 | E22: 82.08 | P22: 21.32 | Q22: 21.32 | R22: 21.32 | S22: 21.32 | T22: =R22-S22 -> 0
B23: READ - MEETING | D23: 19.75 | E23: 21.01 | F23: 21.01 | G23: 21.01 | H23: 21.01 | I23: 21.01 | J23: 21.01 | K23: 21.01 | L23: 21.01 | M23: 21.01 | N23: 21.01 | O23: 21.01 | P23: 21.01 | Q23: 21.01 | R23: 21.01 | S23: 21.01 | T23: =R23-S23 -> 0
B24: Bluefin | E24: 56.57 | T24: =R24-S24 -> 0
B25: GoDaddy | E25: 25.98 | H25: 133.02 | K25: 44.38 | Q25: 66.57 | T25: =R25-S25 -> 0
B26: QuickBooks Payments | F26: 55.97 | G26: 60.77 | H26: 60.77 | I26: 116.88 | J26: 121.52 | K26: 121.52 | L26: 138.58 | M26: 138.58 | N26: 138.58 | O26: 138.58 | P26: 138.58 | Q26: 138.58 | R26: 138.58 | S26: 138.58 | T26: =R26-S26 -> 0
B27: McAfee | L27: 49.99 | T27: =R27-S27 -> 0
B28: Awaz | L28: 29 | T28: =R28-S28 -> 0
B29: Tailwind | M29: 23.66 | T29: =R29-S29 -> 0
B30: IT and Internet Expenses | C30: 31.92 | D30: 31.92 | F30: 227.68 | G30: 274.94 | H30: 509.84 | I30: 1726.01 | J30: 511.61 | K30: 586.55 | L30: 582.65 | M30: 540.68 | N30: 255.71 | O30: 499.3 | P30: 506.14 | Q30: 500.65 | T30: =R30-S30 -> 0
B31: Digital Ocean | F31: 227.68 | G31: 274.94 | H31: 275.53 | I31: 303.7 | J31: 277.3 | K31: 283.79 | L31: 284.38 | M31: 284.97 | O31: 286.15 | P31: 292.99 | Q31: 287.5 | T31: =R31-S31 -> 0
B32: Figma | C32: 31.92 | D32: 31.92 | H32: 85.12 | I32: 85.12 | J32: 85.12 | K32: 85.12 | L32: 85.12 | M32: 42.56 | N32: 42.56 | T32: =R32-S32 -> 0
B33: Scalela | I33: 1188 | T33: =R33-S33 -> 0
B34: Semrush | H34: 149.19 | I34: 149.19 | J34: 149.19 | K34: 217.64 | L34: 213.15 | M34: 213.15 | N34: 213.15 | O34: 213.15 | P34: 213.15 | Q34: 213.15 | T34: =R34-S34 -> 0
B35: Telephone Expense | C35: 1644.11 | D35: 260.23 | E35: 241.91 | F35: 387.4 | G35: 257.37 | H35: 236.52 | I35: 378.78 | J35: 376.84 | K35: 371.4 | L35: 311.52 | M35: 292.62 | N35: 308.96 | O35: 2335.84 | P35: 540.97 | Q35: 294.9 | R35: 285.27 | S35: 284.85 | T35: =R35-S35 -> 0.42
B36: RINGCENTRAL INC | C36: 1427.47 | N36: 32.25 | O36: 2036.8 | T36: =R36-S36 -> 0
B37: Verizon | C37: 216.64 | D37: 260.23 | E37: 241.91 | F37: 387.4 | G37: 257.37 | H37: 236.52 | I37: 378.78 | J37: 376.84 | K37: 371.4 | L37: 311.52 | M37: 292.62 | N37: 276.71 | O37: 299.04 | P37: 540.97 | Q37: 294.9 | R37: 285.27 | S37: 284.85 | T37: =R37-S37 -> 0.42
B38: Other COGS | C38: 1007.56 | D38: 13069.29 | E38: 14339.92 | F38: 15297.89 | G38: 17266.72 | H38: 13768.54 | I38: 18080.94 | J38: 37312.24 | K38: 15322.03 | L38: 20416.81 | M38: 20804.53 | N38: 17697.4 | O38: 14960.82 | P38: 16793.61 | Q38: 29302.11 | R38: 17049.58 | S38: 12532.86 | T38: =R38-S38 -> 4516.72
B39: Software Expenses | C39: 1007.56 | D39: 13069.29 | E39: 14339.92 | F39: 15297.89 | G39: 17266.72 | H39: 13768.54 | I39: 18080.94 | J39: 37312.24 | K39: 15322.03 | L39: 20416.81 | M39: 20804.53 | N39: 17697.4 | O39: 14960.82 | P39: 16793.61 | Q39: 29302.11 | R39: 17049.58 | S39: 12532.86 | T39: =R39-S39 -> 4516.72
B40: AdvancedMD | C40: 310.67 | D40: 7171.4 | E40: 6399.9 | F40: 9071.33 | G40: 9087.09 | H40: 9063.53 | I40: 9078.5 | J40: 21415.87 | K40: 9163.02 | L40: 17541.85 | M40: 13980.76 | N40: 13265.71 | O40: 9421.8 | P40: 13419.37 | Q40: 18963.63 | R40: 7046.68 | S40: 7046.68 | T40: =R40-S40 -> 0
B41: Availity | C41: 31.64 | D41: 26.65 | E41: 26.65 | F41: 26.65 | H41: 26.65 | I41: 26.65 | J41: 26.65 | K41: 28.09 | L41: 41.05 | M41: 70.69 | N41: 2734.34 | O41: 2215.06 | P41: 62.63 | Q41: 2196.77 | R41: 1398.06 | S41: 1066 | T41: =R41-S41 -> 332.06
...

Sheet Subs Detailed Exp Summary
A1: IMAGNUM HEALTHCARE SOLUTION PRIVATE LIMITED
B4: Sum of Amount | E4: Month
B5: Cost Category | C5: Ledger Name | D5: Supplier Name | E5: 45688 | F5: 45716 | G5: 45747 | H5: 45777 | I5: 45808 | J5: 45838 | K5: 45869 | L5: 45900 | M5: 45930 | N5: 45961 | O5: 45991 | P5: 46022 | Q5: 46053 | R5: 46081 | S5: 46112 | T5: 46142 | U5: 46173 | V5: May Vs Apr | W5: in $ | Y5: 95
B6: 1.Manpower | C6: Operation Salaries | D6: Operation Salaries | E6: 3762414 | F6: 4457855 | G6: 4579463 | H6: 4473906 | I6: 4728640 | J6: 5065520 | K6: 5158862 | L6: 5788065 | M6: 5991910 | N6: 6270781 | O6: 6229342 | P6: 6323574 | Q6: 6062679 | R6: 6115267 | S6: 6041252 | T6: 5768982 | U6: 5470829 | V6: =T6-U6 -> 298153 | W6: =V6/95 -> 3138.4526 | Y6: =U6/$Y$5 -> 57587.674
C7: Ops Support Salaries | D7: Ops Support Salaries | E7: 1911823 | F7: 2198354 | G7: 2043456 | H7: 2108487 | I7: 2151697 | J7: 2220435 | K7: 2498763 | L7: 2762127 | M7: 2796629 | N7: 3187170 | O7: 3255082 | P7: 3428387 | Q7: 3422489 | R7: 3333406 | S7: 3516012 | T7: 3503973 | U7: 3335558 | V7: =T7-U7 -> 168415 | W7: =V7/95 -> 1772.7895 | Y7: =U7/$Y$5 -> 35111.137
C8: Bonus and Incentives | D8: HDFC Bank | E8: 758750 | Q8: 15000 | V8: =T8-U8 -> 0 | W8: =V8/95 -> 0 | Y8: =U8/$Y$5 -> 0
C9: Contract Employee Salaries | D9: Contract Employee Salaries | E9: 47000 | F9: 47000 | G9: 47000 | H9: 47000 | I9: 28667 | J9: 12000 | K9: 12000 | L9: 12000 | M9: 12000 | N9: 12000 | O9: 12000 | P9: 12000 | R9: 20000 | S9: 20000 | U9: 20000 | V9: =T9-U9 -> -20000 | W9: =V9/95 -> -210.52632 | Y9: =U9/$Y$5 -> 210.52632
B10: 1.Manpower Total | E10: 6479987 | F10: 6703209 | G10: 6669919 | H10: 6629393 | I10: 6909004 | J10: 7297955 | K10: 7669625 | L10: 8562192 | M10: 8800539 | N10: 9469951 | O10: 9496424 | P10: 9763961 | Q10: 9500168 | R10: 9468673 | S10: 9577264 | T10: 9272955 | U10: 8826387 | V10: =T10-U10 -> 446568 | W10: =V10/95 -> 4700.7158 | Y10: =U10/$Y$5 -> 92909.337
B11: 2.Facility cost | C11: Janani Property Rental Charges | D11: JANANI PROPERTY & ESTATES PVT LTD | E11: 376923 | F11: 376923 | G11: 376923 | H11: 376923 | I11: 376923 | J11: 376923 | K11: 376923 | L11: 376923 | M11: 376923 | N11: 395769 | O11: 395769 | P11: 395769 | Q11: 395769 | R11: 395769 | S11: 395769 | T11: 395769 | U11: 395769 | V11: =T11-U11 -> 0 | W11: =V11/95 -> 0 | Y11: =U11/$Y$5 -> 4165.9895
C12: Max Office rental charges | D12: Max Office | K12: 400000 | L12: 400000 | M12: 400000 | N12: 400000 | O12: 400000 | P12: 400000 | Q12: 400000 | R12: 400000 | S12: 400000 | T12: 400000 | U12: 400000 | V12: =T12-U12 -> 0 | W12: =V12/95 -> 0 | Y12: =U12/$Y$5 -> 4210.5263
C13: Electricity Expense | D13: HDFC Bank | R13: 373 | V13: =T13-U13 -> 0 | W13: =V13/95 -> 0 | Y13: =U13/$Y$5 -> 0
D14: TAMILNADU GENERATION AND DISTRIBUTION CORPORATION LIMITED | E14: 180904.38 | F14: 217106.48 | G14: 182837.26 | H14: 237374.54 | I14: 205380.36 | J14: 275963.02 | K14: 222710.11 | L14: 282109.83 | M14: 219561 | N14: 278072 | O14: 200679 | P14: 246415 | Q14: 180086 | R14: 212225 | S14: 213905.73 | T14: 224144 | U14: 205772 | V14: =T14-U14 -> 18372 | W14: =V14/95 -> 193.38947 | Y14: =U14/$Y$5 -> 2166.0211
D15: Max Office | L15: 15396 | M15: 33468 | O15: 47724 | P15: 19848 | R15: 69324 | S15: 32304 | T15: 50052 | U15: 42360 | V15: =T15-U15 -> 7692 | W15: =V15/95 -> 80.968421 | Y15: =U15/$Y$5 -> 445.89474
D16: Amutha Trichy Rental House | Q16: 974 | U16: 4907 | V16: =T16-U16 -> -4907 | W16: =V16/95 -> -51.652632 | Y16: =U16/$Y$5 -> 51.652632
C17: Laptop Rental Charges | D17: M.R. INFOTECH | E17: 119245 | F17: 119485 | G17: 119470 | H17: 120435 | I17: 136370 | J17: 140575 | K17: 151460 | L17: 150740 | M17: 152855.09 | N17: 159250.09 | O17: 168956.09 | P17: 181117.09 | Q17: 189327.1 | R17: 190241.09 | S17: 175436.09 | T17: 180696.09 | U17: 182988.09 | V17: =T17-U17 -> -2292 | W17: =V17/95 -> -24.126316 | Y17: =U17/$Y$5 -> 1926.1904
C18: Janani Property Maintenance Charges | D18: JANANI PROPERTY & ESTATES PVT LTD | E18: 65105 | F18: 65105 | G18: 65105 | H18: 65105 | I18: 65105 | J18: 65105 | K18: 65105 | L18: 65105 | M18: 65105 | N18: 68360 | O18: 68360 | P18: 68360 | Q18: 68360 | R18: 68360 | S18: 68360 | T18: 68360 | U18: 68360 | V18: =T18-U18 -> 0 | W18: =V18/95 -> 0 | Y18: =U18/$Y$5 -> 719.57895
C19: Thiruttani rental charges | D19: Balaji Towers | E19: 25000 | F19: 25000 | G19: 25000 | H19: 25000 | I19: 26250 | J19: 26250 | K19: 26250 | L19: 26250 | M19: 26250 | N19: 26250 | O19: 26250 | P19: 26250 | Q19: 26250 | R19: 26250 | S19: 26250 | T19: 26250 | U19: 27562 | V19: =T19-U19 -> -1312 | W19: =V19/95 -> -13.810526 | Y19: =U19/$Y$5 -> 290.12632
C20: Trichy rental charges | D20: Amutha Trichy Rental House | O20: 25000 | P20: 25000 | Q20: 25000 | R20: 25000 | S20: 25000 | T20: 25000 | U20: 25000 | V20: =T20-U20 -> 0 | W20: =V20/95 -> 0 | Y20: =U20/$Y$5 -> 263.15789
C21: Computer maintenance | D21: Xtreme Infotech | J21: 7000 | V21: =T21-U21 -> 0 | W21: =V21/95 -> 0 | Y21: =U21/$Y$5 -> 0
B22: 2.Facility cost Total | E22: 767177.38 | F22: 803619.48 | G22: 769335.26 | H22: 824837.54 | I22: 810028.36 | J22: 891816.02 | K22: 1242448.1 | L22: 1316523.8 | M22: 1274162.1 | N22: 1327701.1 | O22: 1332738.1 | P22: 1362759.1 | Q22: 1285766.1 | R22: 1387542.1 | S22: 1337024.8 | T22: 1370271.1 | U22: 1352718.1 | V22: =T22-U22 -> 17553 | W22: =V22/95 -> 184.76842 | Y22: =U22/$Y$5 -> 14239.138
B23: 3.Telecom Data & others | C23: License/Subscription/Certification Charges | D23: Adobe Systems Software Ireland Ltd | E23: 5160.06 | F23: 5160.06 | G23: 6659.06 | H23: 6659.06 | I23: 6659.06 | J23: 6659.06 | K23: 6659.06 | L23: 10243.06 | M23: 10041.06 | N23: 10041.06 | O23: 10041.06 | P23: 10041.06 | Q23: 10041.06 | R23: 10041.06 | S23: 11256.06 | T23: 11256.06 | U23: 2367 | V23: =T23-U23 -> 8889.06 | W23: =V23/95 -> 93.569053 | Y23: =U23/$Y$5 -> 24.915789
D24: E2E Networks Limited | E24: 45000 | F24: 50000 | G24: 50000 | H24: 50000 | I24: 49999 | J24: 50000 | K24: 50000 | L24: 50000 | M24: 56153 | O24: 50000 | P24: 50000 | Q24: 32000 | R24: 7950 | V24: =T24-U24 -> 0 | W24: =V24/95 -> 0 | Y24: =U24/$Y$5 -> 0
D25: Esoftsol Infocom Pvt Ltd | E25: 147510 | F25: 18378 | V25: =T25-U25 -> 0 | W25: =V25/95 -> 0 | Y25: =U25/$Y$5 -> 0
D26: HDFC credit card (Kasi) | O26: 5990 | V26: =T26-U26 -> 0 | W26: =V26/95 -> 0 | Y26: =U26/$Y$5 -> 0
D27: LinkedIn | E27: 6299.14 | F27: 6299.14 | G27: 9446.74 | H27: 6299.14 | I27: 6299.14 | J27: 6299.14 | K27: 6299.14 | L27: 6299.14 | M27: 6299.14 | N27: 6299.14 | O27: 6299.14 | P27: 6299.14 | Q27: 6299.14 | S27: 21899.87 | T27: 9536.2 | V27: =T27-U27 -> 9536.2 | W27: =V27/95 -> 100.38105 | Y27: =U27/$Y$5 -> 0
D28: Udemy India LLP | F28: 1068 | V28: =T28-U28 -> 0 | W28: =V28/95 -> 0 | Y28: =U28/$Y$5 -> 0
D29: License/Subscription/Certification Charges | E29: 18468 | F29: 18468 | G29: 18468 | H29: 18468 | I29: 18468 | J29: 21097 | K29: 24486 | L29: 28554 | M29: 37971 | N29: 38106 | O29: 41354 | P29: 41354 | Q29: 42647 | R29: 42870 | S29: 43953 | T29: 48603 | U29: 48603 | V29: =T29-U29 -> 0 | W29: =V29/95 -> 0 | Y29: =U29/$Y$5 -> 511.61053
D30: AAPC | O30: 19820.54 | V30: =T30-U30 -> 0 | W30: =V30/95 -> 0 | Y30: =U30/$Y$5 -> 0
D31: ClaudeAI | U31: 1916.04 | V31: =T31-U31 -> -1916.04 | W31: =V31/95 -> -20.168842 | Y31: =U31/$Y$5 -> 20.168842
C32: IT and Internet Expenses | D32: IT and Internet Expenses | E32: 20000 | F32: 27416 | G32: 27416 | H32: 33750 | I32: 33750 | J32: 33750 | K32: 33750 | L32: 42917 | M32: 42917 | N32: 52084 | O32: 42917 | P32: 42917 | Q32: 42917 | R32: 42917 | S32: 42917 | T32: 42917 | U32: 42917 | V32: =T32-U32 -> 0 | W32: =V32/95 -> 0 | Y32: =U32/$Y$5 -> 451.75789
D33: SYSVEL TECHNOLOGY | I33: 3000 | V33: =T33-U33 -> 0 | W33: =V33/95 -> 0 | Y33: =U33/$Y$5 -> 0
D34: TATA TELESERVICES LIMITED | L34: 5000 | V34: =T34-U34 -> 0 | W34: =V34/95 -> 0 | Y34: =U34/$Y$5 -> 0
D35: Slack | S35: 1673.76 | T35: 1179 | U35: 1149.52 | V35: =T35-U35 -> 29.48 | W35: =V35/95 -> 0.31031579 | Y35: =U35/$Y$5 -> 12.100211
D36: Reliance Jio Infocomm Limited | U36: 20750 | V36: =T36-U36 -> -20750 | W36: =V36/95 -> -218.42105 | Y36: =U36/$Y$5 -> 218.42105
C37: Software development and Hosting charges | D37: Futurecalls Technology | L37: 1936 | M37: 15000 | N37: 15000 | O37: 15000 | P37: 23241.77 | Q37: 32542.65 | R37: 33095.87 | S37: 64203.88 | T37: 15000 | U37: 39529.52 | V37: =T37-U37 -> -24529.52 | W37: =V37/95 -> -258.20547 | Y37: =U37/$Y$5 -> 416.10021
D38: HDFC Bank | N38: 20997 | V38: =T38-U38 -> 0 | W38: =V38/95 -> 0 | Y38: =U38/$Y$5 -> 0
D39: Info Edge (India) Ltd | G39: 55800 | S39: 55800 | V39: =T39-U39 -> 0 | W39: =V39/95 -> 0 | Y39: =U39/$Y$5 -> 0
D40: Claritus Management Consulting Pvt. Ltd. | Q40: 967.34 | V40: =T40-U40 -> 0 | W40: =V40/95 -> 0 | Y40: =U40/$Y$5 -> 0
D41: Software development and Hosting charges | E41: 1000 | F41: 1000 | G41: 1000 | H41: 1000 | I41: 1000 | J41: 1000 | K41: 1000 | L41: 1000 | M41: 1000 | N41: 1000 | O41: 1000 | P41: 1000 | V41: =T41-U41 -> 0 | W41: =V41/95 -> 0 | Y41: =U41/$Y$5 -> 0
D42: GAMMA.APP | N42: 22787.23 | V42: =T42-U42 -> 0 | W42: =V42/95 -> 0 | Y42: =U42/$Y$5 -> 0
...
